2025-06-18 21:35:29,653 [INFO] [31m[1mWARNING: This is a development server. Do not use it in a production deployment. Use a production WSGI server instead.[0m
 * Running on all addresses (0.0.0.0)
 * Running on http://127.0.0.1:5000
 * Running on http://192.168.0.7:5000
2025-06-18 21:35:29,653 [INFO] [33mPress CTRL+C to quit[0m
2025-06-18 21:48:06,366 [INFO] [31m[1mWARNING: This is a development server. Do not use it in a production deployment. Use a production WSGI server instead.[0m
 * Running on all addresses (0.0.0.0)
 * Running on http://127.0.0.1:5000
 * Running on http://192.168.0.7:5000
2025-06-18 21:48:06,367 [INFO] [33mPress CTRL+C to quit[0m
2025-06-18 21:48:31,669 [INFO] Error while receiving.
Traceback (most recent call last):
  File "C:\Users\jaehy\anaconda3\Lib\site-packages\py4j\clientserver.py", line 511, in send_command
    answer = smart_decode(self.stream.readline()[:-1])
                          ^^^^^^^^^^^^^^^^^^^^^^
  File "C:\Users\jaehy\anaconda3\Lib\socket.py", line 706, in readinto
    return self._sock.recv_into(b)
           ^^^^^^^^^^^^^^^^^^^^^^^
ConnectionResetError: [WinError 10054] 현재 연결은 원격 호스트에 의해 강제로 끊겼습니다
2025-06-18 21:48:31,674 [INFO] Closing down clientserver connection
2025-06-18 21:48:31,674 [ERROR] Exception while sending command.
Traceback (most recent call last):
  File "C:\Users\jaehy\anaconda3\Lib\site-packages\py4j\clientserver.py", line 511, in send_command
    answer = smart_decode(self.stream.readline()[:-1])
                          ^^^^^^^^^^^^^^^^^^^^^^
  File "C:\Users\jaehy\anaconda3\Lib\socket.py", line 706, in readinto
    return self._sock.recv_into(b)
           ^^^^^^^^^^^^^^^^^^^^^^^
ConnectionResetError: [WinError 10054] 현재 연결은 원격 호스트에 의해 강제로 끊겼습니다

During handling of the above exception, another exception occurred:

Traceback (most recent call last):
  File "C:\Users\jaehy\anaconda3\Lib\site-packages\py4j\java_gateway.py", line 1038, in send_command
    response = connection.send_command(command)
               ^^^^^^^^^^^^^^^^^^^^^^^^^^^^^^^^
  File "C:\Users\jaehy\anaconda3\Lib\site-packages\py4j\clientserver.py", line 539, in send_command
    raise Py4JNetworkError(
py4j.protocol.Py4JNetworkError: Error while sending or receiving
2025-06-18 21:48:31,677 [INFO] Closing down clientserver connection
2025-06-18 21:48:31,715 [INFO] Closing down clientserver connection
2025-06-18 21:48:41,967 [INFO] [31m[1mWARNING: This is a development server. Do not use it in a production deployment. Use a production WSGI server instead.[0m
 * Running on all addresses (0.0.0.0)
 * Running on http://127.0.0.1:5000
 * Running on http://192.168.0.7:5000
2025-06-18 21:48:41,967 [INFO] [33mPress CTRL+C to quit[0m
2025-06-18 21:48:56,856 [INFO] Error while receiving.
Traceback (most recent call last):
  File "C:\Users\jaehy\anaconda3\Lib\site-packages\py4j\clientserver.py", line 511, in send_command
    answer = smart_decode(self.stream.readline()[:-1])
                          ^^^^^^^^^^^^^^^^^^^^^^
  File "C:\Users\jaehy\anaconda3\Lib\socket.py", line 706, in readinto
    return self._sock.recv_into(b)
           ^^^^^^^^^^^^^^^^^^^^^^^
ConnectionResetError: [WinError 10054] 현재 연결은 원격 호스트에 의해 강제로 끊겼습니다
2025-06-18 21:48:56,858 [INFO] Closing down clientserver connection
2025-06-18 21:48:56,858 [ERROR] Exception while sending command.
Traceback (most recent call last):
  File "C:\Users\jaehy\anaconda3\Lib\site-packages\py4j\clientserver.py", line 511, in send_command
    answer = smart_decode(self.stream.readline()[:-1])
                          ^^^^^^^^^^^^^^^^^^^^^^
  File "C:\Users\jaehy\anaconda3\Lib\socket.py", line 706, in readinto
    return self._sock.recv_into(b)
           ^^^^^^^^^^^^^^^^^^^^^^^
ConnectionResetError: [WinError 10054] 현재 연결은 원격 호스트에 의해 강제로 끊겼습니다

During handling of the above exception, another exception occurred:

Traceback (most recent call last):
  File "C:\Users\jaehy\anaconda3\Lib\site-packages\py4j\java_gateway.py", line 1038, in send_command
    response = connection.send_command(command)
               ^^^^^^^^^^^^^^^^^^^^^^^^^^^^^^^^
  File "C:\Users\jaehy\anaconda3\Lib\site-packages\py4j\clientserver.py", line 539, in send_command
    raise Py4JNetworkError(
py4j.protocol.Py4JNetworkError: Error while sending or receiving
2025-06-18 21:48:56,860 [INFO] Closing down clientserver connection
2025-06-18 21:48:56,887 [INFO] Closing down clientserver connection
2025-06-19 19:39:54,244 [INFO] [31m[1mWARNING: This is a development server. Do not use it in a production deployment. Use a production WSGI server instead.[0m
 * Running on all addresses (0.0.0.0)
 * Running on http://127.0.0.1:5000
 * Running on http://192.168.0.7:5000
2025-06-19 19:39:54,245 [INFO] [33mPress CTRL+C to quit[0m
2025-06-19 19:39:59,166 [INFO] [요청] IP: 127.0.0.1, OPTIONS /stock_news
2025-06-19 19:39:59,167 [INFO] 127.0.0.1 - - [19/Jun/2025 19:39:59] "OPTIONS /stock_news HTTP/1.1" 200 -
2025-06-19 19:39:59,408 [INFO] [요청] IP: 127.0.0.1, GET /stock_news
2025-06-19 19:40:07,075 [INFO] 127.0.0.1 - - [19/Jun/2025 19:40:07] "GET /stock_news HTTP/1.1" 200 -
2025-06-19 19:40:13,887 [INFO] [요청] IP: 127.0.0.1, OPTIONS /stock_news
2025-06-19 19:40:13,888 [INFO] 127.0.0.1 - - [19/Jun/2025 19:40:13] "OPTIONS /stock_news HTTP/1.1" 200 -
2025-06-19 19:40:14,193 [INFO] [요청] IP: 127.0.0.1, GET /stock_news
2025-06-19 19:40:21,114 [INFO] 127.0.0.1 - - [19/Jun/2025 19:40:21] "GET /stock_news HTTP/1.1" 200 -
2025-06-19 19:40:31,247 [INFO] [요청] IP: 127.0.0.1, OPTIONS /stock_news
2025-06-19 19:40:31,248 [INFO] 127.0.0.1 - - [19/Jun/2025 19:40:31] "OPTIONS /stock_news HTTP/1.1" 200 -
2025-06-19 19:40:31,563 [INFO] [요청] IP: 127.0.0.1, GET /stock_news
2025-06-19 19:40:38,936 [INFO] 127.0.0.1 - - [19/Jun/2025 19:40:38] "GET /stock_news HTTP/1.1" 200 -
2025-06-19 19:40:50,877 [INFO] [요청] IP: 127.0.0.1, OPTIONS /stock_news
2025-06-19 19:40:50,879 [INFO] 127.0.0.1 - - [19/Jun/2025 19:40:50] "OPTIONS /stock_news HTTP/1.1" 200 -
2025-06-19 19:40:51,137 [INFO] [요청] IP: 127.0.0.1, GET /stock_news
2025-06-19 19:40:58,601 [INFO] 127.0.0.1 - - [19/Jun/2025 19:40:58] "GET /stock_news HTTP/1.1" 200 -
2025-06-19 19:41:02,738 [INFO] [요청] IP: 127.0.0.1, OPTIONS /login
2025-06-19 19:41:02,739 [INFO] 127.0.0.1 - - [19/Jun/2025 19:41:02] "OPTIONS /login HTTP/1.1" 200 -
2025-06-19 19:41:03,049 [INFO] [요청] IP: 127.0.0.1, POST /login
2025-06-19 19:41:04,627 [INFO] 127.0.0.1 - - [19/Jun/2025 19:41:04] "POST /login HTTP/1.1" 200 -
2025-06-19 19:41:04,627 [INFO] Closing down clientserver connection
2025-06-19 19:41:04,746 [INFO] [요청] IP: 127.0.0.1, OPTIONS /stock_news
2025-06-19 19:41:04,747 [INFO] 127.0.0.1 - - [19/Jun/2025 19:41:04] "OPTIONS /stock_news HTTP/1.1" 200 -
2025-06-19 19:41:05,050 [INFO] [요청] IP: 127.0.0.1, OPTIONS /check-auth
2025-06-19 19:41:05,050 [INFO] [요청] IP: 127.0.0.1, OPTIONS /check-auth
2025-06-19 19:41:05,051 [INFO] 127.0.0.1 - - [19/Jun/2025 19:41:05] "OPTIONS /check-auth HTTP/1.1" 200 -
2025-06-19 19:41:05,051 [INFO] [요청] IP: 127.0.0.1, GET /stock_news
2025-06-19 19:41:05,053 [INFO] 127.0.0.1 - - [19/Jun/2025 19:41:05] "OPTIONS /check-auth HTTP/1.1" 200 -
2025-06-19 19:41:05,357 [INFO] [요청] IP: 127.0.0.1, GET /check-auth
2025-06-19 19:41:05,358 [INFO] 127.0.0.1 - - [19/Jun/2025 19:41:05] "GET /check-auth HTTP/1.1" 200 -
2025-06-19 19:41:05,618 [INFO] [요청] IP: 127.0.0.1, GET /check-auth
2025-06-19 19:41:05,619 [INFO] 127.0.0.1 - - [19/Jun/2025 19:41:05] "GET /check-auth HTTP/1.1" 200 -
2025-06-19 19:41:12,787 [INFO] 127.0.0.1 - - [19/Jun/2025 19:41:12] "GET /stock_news HTTP/1.1" 200 -
2025-06-19 19:41:30,171 [INFO] [요청] IP: 127.0.0.1, OPTIONS /stock_news
2025-06-19 19:41:30,172 [INFO] 127.0.0.1 - - [19/Jun/2025 19:41:30] "OPTIONS /stock_news HTTP/1.1" 200 -
2025-06-19 19:41:30,431 [INFO] [요청] IP: 127.0.0.1, GET /stock_news
2025-06-19 19:41:38,638 [INFO] [요청] IP: 127.0.0.1, OPTIONS /DB_stock_search
2025-06-19 19:41:38,638 [INFO] 127.0.0.1 - - [19/Jun/2025 19:41:38] "OPTIONS /DB_stock_search HTTP/1.1" 200 -
2025-06-19 19:41:38,946 [INFO] [요청] IP: 127.0.0.1, POST /DB_stock_search
2025-06-19 19:41:39,030 [INFO] 127.0.0.1 - - [19/Jun/2025 19:41:39] "GET /stock_news HTTP/1.1" 200 -
2025-06-19 19:41:44,481 [INFO] 127.0.0.1 - - [19/Jun/2025 19:41:44] "POST /DB_stock_search HTTP/1.1" 200 -
2025-06-19 19:41:44,486 [INFO] Closing down clientserver connection
2025-06-19 19:41:46,758 [INFO] [요청] IP: 127.0.0.1, OPTIONS /stock_news
2025-06-19 19:41:46,759 [INFO] 127.0.0.1 - - [19/Jun/2025 19:41:46] "OPTIONS /stock_news HTTP/1.1" 200 -
2025-06-19 19:41:47,017 [INFO] [요청] IP: 127.0.0.1, GET /stock_news
2025-06-19 19:41:54,719 [INFO] 127.0.0.1 - - [19/Jun/2025 19:41:54] "GET /stock_news HTTP/1.1" 200 -
2025-06-19 19:42:17,643 [INFO] [요청] IP: 127.0.0.1, OPTIONS /stock_news
2025-06-19 19:42:17,644 [INFO] 127.0.0.1 - - [19/Jun/2025 19:42:17] "OPTIONS /stock_news HTTP/1.1" 200 -
2025-06-19 19:42:17,960 [INFO] [요청] IP: 127.0.0.1, OPTIONS /DB_stock_search
2025-06-19 19:42:17,960 [INFO] [요청] IP: 127.0.0.1, GET /stock_news
2025-06-19 19:42:17,961 [INFO] 127.0.0.1 - - [19/Jun/2025 19:42:17] "OPTIONS /DB_stock_search HTTP/1.1" 200 -
2025-06-19 19:42:18,269 [INFO] [요청] IP: 127.0.0.1, POST /DB_stock_search
2025-06-19 19:42:19,791 [INFO] 127.0.0.1 - - [19/Jun/2025 19:42:19] "POST /DB_stock_search HTTP/1.1" 200 -
2025-06-19 19:42:19,795 [INFO] Closing down clientserver connection
2025-06-19 19:42:27,091 [INFO] 127.0.0.1 - - [19/Jun/2025 19:42:27] "GET /stock_news HTTP/1.1" 200 -
2025-06-19 19:42:31,475 [INFO] [요청] IP: 127.0.0.1, OPTIONS /stock_news
2025-06-19 19:42:31,476 [INFO] [요청] IP: 127.0.0.1, OPTIONS /DB_stock_search
2025-06-19 19:42:31,478 [INFO] 127.0.0.1 - - [19/Jun/2025 19:42:31] "OPTIONS /stock_news HTTP/1.1" 200 -
2025-06-19 19:42:31,478 [INFO] 127.0.0.1 - - [19/Jun/2025 19:42:31] "OPTIONS /DB_stock_search HTTP/1.1" 200 -
2025-06-19 19:42:31,735 [INFO] [요청] IP: 127.0.0.1, POST /DB_stock_search
2025-06-19 19:42:31,797 [INFO] [요청] IP: 127.0.0.1, GET /stock_news
2025-06-19 19:42:33,018 [INFO] 127.0.0.1 - - [19/Jun/2025 19:42:33] "POST /DB_stock_search HTTP/1.1" 200 -
2025-06-19 19:42:33,020 [INFO] Closing down clientserver connection
2025-06-19 19:42:39,750 [INFO] 127.0.0.1 - - [19/Jun/2025 19:42:39] "GET /stock_news HTTP/1.1" 200 -
2025-06-19 19:43:03,107 [INFO] [요청] IP: 127.0.0.1, OPTIONS /stock_news
2025-06-19 19:43:03,108 [INFO] 127.0.0.1 - - [19/Jun/2025 19:43:03] "OPTIONS /stock_news HTTP/1.1" 200 -
2025-06-19 19:43:03,409 [INFO] [요청] IP: 127.0.0.1, OPTIONS /DB_stock_search
2025-06-19 19:43:03,409 [INFO] 127.0.0.1 - - [19/Jun/2025 19:43:03] "OPTIONS /DB_stock_search HTTP/1.1" 200 -
2025-06-19 19:43:03,411 [INFO] [요청] IP: 127.0.0.1, GET /stock_news
2025-06-19 19:43:03,718 [INFO] [요청] IP: 127.0.0.1, POST /DB_stock_search
2025-06-19 19:43:05,125 [INFO] 127.0.0.1 - - [19/Jun/2025 19:43:05] "POST /DB_stock_search HTTP/1.1" 200 -
2025-06-19 19:43:05,136 [INFO] Closing down clientserver connection
2025-06-19 19:43:12,087 [INFO] 127.0.0.1 - - [19/Jun/2025 19:43:12] "GET /stock_news HTTP/1.1" 200 -
2025-06-19 19:43:18,663 [INFO] [요청] IP: 127.0.0.1, OPTIONS /chat
2025-06-19 19:43:18,664 [INFO] 127.0.0.1 - - [19/Jun/2025 19:43:18] "OPTIONS /chat HTTP/1.1" 200 -
2025-06-19 19:43:18,923 [INFO] [요청] IP: 127.0.0.1, POST /chat
2025-06-19 19:43:54,985 [INFO] 127.0.0.1 - - [19/Jun/2025 19:43:54] "POST /chat HTTP/1.1" 200 -
2025-06-19 19:43:54,986 [INFO] Closing down clientserver connection
2025-06-19 19:44:23,663 [INFO] [요청] IP: 127.0.0.1, OPTIONS /stock_news
2025-06-19 19:44:23,663 [INFO] 127.0.0.1 - - [19/Jun/2025 19:44:23] "OPTIONS /stock_news HTTP/1.1" 200 -
2025-06-19 19:44:23,663 [INFO] [요청] IP: 127.0.0.1, OPTIONS /DB_stock_search
2025-06-19 19:44:23,665 [INFO] 127.0.0.1 - - [19/Jun/2025 19:44:23] "OPTIONS /DB_stock_search HTTP/1.1" 200 -
2025-06-19 19:44:23,921 [INFO] [요청] IP: 127.0.0.1, GET /stock_news
2025-06-19 19:44:23,971 [INFO] [요청] IP: 127.0.0.1, POST /DB_stock_search
2025-06-19 19:44:25,147 [INFO] 127.0.0.1 - - [19/Jun/2025 19:44:25] "POST /DB_stock_search HTTP/1.1" 200 -
2025-06-19 19:44:25,149 [INFO] Closing down clientserver connection
2025-06-19 19:44:31,670 [INFO] 127.0.0.1 - - [19/Jun/2025 19:44:31] "GET /stock_news HTTP/1.1" 200 -
2025-06-19 19:44:42,096 [INFO] [요청] IP: 127.0.0.1, OPTIONS /DB_stock_search
2025-06-19 19:44:42,096 [INFO] 127.0.0.1 - - [19/Jun/2025 19:44:42] "OPTIONS /DB_stock_search HTTP/1.1" 200 -
2025-06-19 19:44:42,415 [INFO] [요청] IP: 127.0.0.1, POST /DB_stock_search
2025-06-19 19:44:45,311 [INFO] 127.0.0.1 - - [19/Jun/2025 19:44:45] "POST /DB_stock_search HTTP/1.1" 200 -
2025-06-19 19:44:45,313 [INFO] Closing down clientserver connection
2025-06-19 19:46:07,734 [INFO] [요청] IP: 127.0.0.1, OPTIONS /stock_news
2025-06-19 19:46:07,735 [INFO] [요청] IP: 127.0.0.1, OPTIONS /DB_stock_search
2025-06-19 19:46:07,736 [INFO] 127.0.0.1 - - [19/Jun/2025 19:46:07] "OPTIONS /stock_news HTTP/1.1" 200 -
2025-06-19 19:46:07,736 [INFO] 127.0.0.1 - - [19/Jun/2025 19:46:07] "OPTIONS /DB_stock_search HTTP/1.1" 200 -
2025-06-19 19:46:07,978 [INFO] [요청] IP: 127.0.0.1, POST /DB_stock_search
2025-06-19 19:46:08,055 [INFO] [요청] IP: 127.0.0.1, GET /stock_news
2025-06-19 19:46:09,022 [INFO] 127.0.0.1 - - [19/Jun/2025 19:46:09] "POST /DB_stock_search HTTP/1.1" 200 -
2025-06-19 19:46:09,025 [INFO] Closing down clientserver connection
2025-06-19 19:46:10,883 [INFO] [요청] IP: 127.0.0.1, POST /DB_stock_search
2025-06-19 19:46:13,444 [INFO] 127.0.0.1 - - [19/Jun/2025 19:46:13] "POST /DB_stock_search HTTP/1.1" 200 -
2025-06-19 19:46:13,447 [INFO] Closing down clientserver connection
2025-06-19 19:46:15,665 [INFO] 127.0.0.1 - - [19/Jun/2025 19:46:15] "GET /stock_news HTTP/1.1" 200 -
2025-06-19 19:46:53,586 [INFO] [요청] IP: 127.0.0.1, OPTIONS /stock_news
2025-06-19 19:46:53,586 [INFO] 127.0.0.1 - - [19/Jun/2025 19:46:53] "OPTIONS /stock_news HTTP/1.1" 200 -
2025-06-19 19:46:53,588 [INFO] [요청] IP: 127.0.0.1, OPTIONS /DB_stock_search
2025-06-19 19:46:53,588 [INFO] 127.0.0.1 - - [19/Jun/2025 19:46:53] "OPTIONS /DB_stock_search HTTP/1.1" 200 -
2025-06-19 19:46:53,846 [INFO] [요청] IP: 127.0.0.1, GET /stock_news
2025-06-19 19:46:53,894 [INFO] [요청] IP: 127.0.0.1, POST /DB_stock_search
2025-06-19 19:46:55,246 [INFO] 127.0.0.1 - - [19/Jun/2025 19:46:55] "POST /DB_stock_search HTTP/1.1" 200 -
2025-06-19 19:46:55,249 [INFO] Closing down clientserver connection
2025-06-19 19:46:58,438 [INFO] [요청] IP: 127.0.0.1, OPTIONS /chat
2025-06-19 19:46:58,440 [INFO] 127.0.0.1 - - [19/Jun/2025 19:46:58] "OPTIONS /chat HTTP/1.1" 200 -
2025-06-19 19:46:58,756 [INFO] [요청] IP: 127.0.0.1, POST /chat
2025-06-19 19:47:01,577 [INFO] 127.0.0.1 - - [19/Jun/2025 19:47:01] "GET /stock_news HTTP/1.1" 200 -
2025-06-19 19:47:33,754 [INFO] 127.0.0.1 - - [19/Jun/2025 19:47:33] "POST /chat HTTP/1.1" 200 -
2025-06-19 19:47:33,754 [INFO] Closing down clientserver connection
2025-06-19 19:47:38,447 [INFO] [요청] IP: 127.0.0.1, OPTIONS /stock_news
2025-06-19 19:47:38,448 [INFO] [요청] IP: 127.0.0.1, OPTIONS /DB_stock_search
2025-06-19 19:47:38,449 [INFO] 127.0.0.1 - - [19/Jun/2025 19:47:38] "OPTIONS /stock_news HTTP/1.1" 200 -
2025-06-19 19:47:38,450 [INFO] 127.0.0.1 - - [19/Jun/2025 19:47:38] "OPTIONS /DB_stock_search HTTP/1.1" 200 -
2025-06-19 19:47:38,688 [INFO] [요청] IP: 127.0.0.1, POST /DB_stock_search
2025-06-19 19:47:38,767 [INFO] [요청] IP: 127.0.0.1, GET /stock_news
2025-06-19 19:47:40,068 [INFO] 127.0.0.1 - - [19/Jun/2025 19:47:40] "POST /DB_stock_search HTTP/1.1" 200 -
2025-06-19 19:47:40,073 [INFO] Closing down clientserver connection
2025-06-19 19:47:46,041 [INFO] [요청] IP: 127.0.0.1, OPTIONS /stock_news
2025-06-19 19:47:46,041 [INFO] 127.0.0.1 - - [19/Jun/2025 19:47:46] "OPTIONS /stock_news HTTP/1.1" 200 -
2025-06-19 19:47:46,357 [INFO] [요청] IP: 127.0.0.1, OPTIONS /check-auth
2025-06-19 19:47:46,357 [INFO] [요청] IP: 127.0.0.1, OPTIONS /check-auth
2025-06-19 19:47:46,358 [INFO] 127.0.0.1 - - [19/Jun/2025 19:47:46] "OPTIONS /check-auth HTTP/1.1" 200 -
2025-06-19 19:47:46,360 [INFO] 127.0.0.1 - - [19/Jun/2025 19:47:46] "OPTIONS /check-auth HTTP/1.1" 200 -
2025-06-19 19:47:46,680 [INFO] [요청] IP: 127.0.0.1, GET /check-auth
2025-06-19 19:47:46,681 [INFO] 127.0.0.1 - - [19/Jun/2025 19:47:46] "[31m[1mGET /check-auth HTTP/1.1[0m" 401 -
2025-06-19 19:47:46,924 [INFO] [요청] IP: 127.0.0.1, GET /check-auth
2025-06-19 19:47:46,925 [INFO] 127.0.0.1 - - [19/Jun/2025 19:47:46] "[31m[1mGET /check-auth HTTP/1.1[0m" 401 -
2025-06-19 19:47:47,335 [INFO] 127.0.0.1 - - [19/Jun/2025 19:47:47] "GET /stock_news HTTP/1.1" 200 -
2025-06-19 19:47:47,653 [INFO] [요청] IP: 127.0.0.1, GET /stock_news
2025-06-19 19:47:55,907 [INFO] 127.0.0.1 - - [19/Jun/2025 19:47:55] "GET /stock_news HTTP/1.1" 200 -
2025-06-19 19:47:57,546 [INFO] [요청] IP: 127.0.0.1, OPTIONS /sign_id_check
2025-06-19 19:47:57,546 [INFO] 127.0.0.1 - - [19/Jun/2025 19:47:57] "OPTIONS /sign_id_check HTTP/1.1" 200 -
2025-06-19 19:47:57,855 [INFO] [요청] IP: 127.0.0.1, POST /sign_id_check
2025-06-19 19:47:58,180 [INFO] 127.0.0.1 - - [19/Jun/2025 19:47:58] "POST /sign_id_check HTTP/1.1" 200 -
2025-06-19 19:47:58,181 [INFO] Closing down clientserver connection
2025-06-19 19:47:59,220 [INFO] [요청] IP: 127.0.0.1, OPTIONS /stock_news
2025-06-19 19:47:59,221 [INFO] 127.0.0.1 - - [19/Jun/2025 19:47:59] "OPTIONS /stock_news HTTP/1.1" 200 -
2025-06-19 19:47:59,536 [INFO] [요청] IP: 127.0.0.1, GET /stock_news
2025-06-19 19:48:07,128 [INFO] 127.0.0.1 - - [19/Jun/2025 19:48:07] "GET /stock_news HTTP/1.1" 200 -
2025-06-19 19:48:14,064 [INFO] [요청] IP: 127.0.0.1, OPTIONS /sign_nickname_check
2025-06-19 19:48:14,064 [INFO] 127.0.0.1 - - [19/Jun/2025 19:48:14] "OPTIONS /sign_nickname_check HTTP/1.1" 200 -
2025-06-19 19:48:14,378 [INFO] [요청] IP: 127.0.0.1, POST /sign_nickname_check
2025-06-19 19:48:15,215 [INFO] 127.0.0.1 - - [19/Jun/2025 19:48:15] "POST /sign_nickname_check HTTP/1.1" 200 -
2025-06-19 19:48:15,217 [INFO] Closing down clientserver connection
2025-06-19 19:48:16,329 [INFO] [요청] IP: 127.0.0.1, OPTIONS /stock_news
2025-06-19 19:48:16,329 [INFO] 127.0.0.1 - - [19/Jun/2025 19:48:16] "OPTIONS /stock_news HTTP/1.1" 200 -
2025-06-19 19:48:16,634 [INFO] [요청] IP: 127.0.0.1, GET /stock_news
2025-06-19 19:48:24,278 [INFO] 127.0.0.1 - - [19/Jun/2025 19:48:24] "GET /stock_news HTTP/1.1" 200 -
2025-06-19 19:48:30,829 [INFO] [요청] IP: 127.0.0.1, OPTIONS /sign_up
2025-06-19 19:48:30,830 [INFO] 127.0.0.1 - - [19/Jun/2025 19:48:30] "OPTIONS /sign_up HTTP/1.1" 200 -
2025-06-19 19:48:31,143 [INFO] [요청] IP: 127.0.0.1, POST /sign_up
2025-06-19 19:48:46,418 [INFO] 127.0.0.1 - - [19/Jun/2025 19:48:46] "POST /sign_up HTTP/1.1" 200 -
2025-06-19 19:48:46,418 [INFO] Closing down clientserver connection
2025-06-19 19:48:58,046 [INFO] [요청] IP: 127.0.0.1, OPTIONS /stock_news
2025-06-19 19:48:58,047 [INFO] 127.0.0.1 - - [19/Jun/2025 19:48:58] "OPTIONS /stock_news HTTP/1.1" 200 -
2025-06-19 19:48:58,358 [INFO] [요청] IP: 127.0.0.1, GET /stock_news
2025-06-19 19:49:03,595 [INFO] [요청] IP: 127.0.0.1, OPTIONS /sign_id_check
2025-06-19 19:49:03,595 [INFO] 127.0.0.1 - - [19/Jun/2025 19:49:03] "OPTIONS /sign_id_check HTTP/1.1" 200 -
2025-06-19 19:49:03,899 [INFO] [요청] IP: 127.0.0.1, POST /sign_id_check
2025-06-19 19:49:03,981 [INFO] 127.0.0.1 - - [19/Jun/2025 19:49:03] "POST /sign_id_check HTTP/1.1" 200 -
2025-06-19 19:49:03,981 [INFO] Closing down clientserver connection
2025-06-19 19:49:05,596 [INFO] 127.0.0.1 - - [19/Jun/2025 19:49:05] "GET /stock_news HTTP/1.1" 200 -
2025-06-19 19:49:06,550 [INFO] [요청] IP: 127.0.0.1, OPTIONS /sign_nickname_check
2025-06-19 19:49:06,551 [INFO] 127.0.0.1 - - [19/Jun/2025 19:49:06] "OPTIONS /sign_nickname_check HTTP/1.1" 200 -
2025-06-19 19:49:06,810 [INFO] [요청] IP: 127.0.0.1, POST /sign_nickname_check
2025-06-19 19:49:06,977 [INFO] 127.0.0.1 - - [19/Jun/2025 19:49:06] "POST /sign_nickname_check HTTP/1.1" 200 -
2025-06-19 19:49:06,979 [INFO] Closing down clientserver connection
2025-06-19 19:49:12,440 [INFO] [요청] IP: 127.0.0.1, OPTIONS /stock_news
2025-06-19 19:49:12,440 [INFO] 127.0.0.1 - - [19/Jun/2025 19:49:12] "OPTIONS /stock_news HTTP/1.1" 200 -
2025-06-19 19:49:12,755 [INFO] [요청] IP: 127.0.0.1, GET /stock_news
2025-06-19 19:49:14,928 [INFO] [요청] IP: 127.0.0.1, OPTIONS /sign_up
2025-06-19 19:49:14,929 [INFO] 127.0.0.1 - - [19/Jun/2025 19:49:14] "OPTIONS /sign_up HTTP/1.1" 200 -
2025-06-19 19:49:15,243 [INFO] [요청] IP: 127.0.0.1, POST /sign_up
2025-06-19 19:49:20,377 [INFO] 127.0.0.1 - - [19/Jun/2025 19:49:20] "GET /stock_news HTTP/1.1" 200 -
2025-06-19 19:49:29,945 [INFO] 127.0.0.1 - - [19/Jun/2025 19:49:29] "POST /sign_up HTTP/1.1" 200 -
2025-06-19 19:49:29,947 [INFO] Closing down clientserver connection
2025-06-19 19:49:31,423 [INFO] [요청] IP: 127.0.0.1, OPTIONS /stock_news
2025-06-19 19:49:31,423 [INFO] 127.0.0.1 - - [19/Jun/2025 19:49:31] "OPTIONS /stock_news HTTP/1.1" 200 -
2025-06-19 19:49:31,664 [INFO] [요청] IP: 127.0.0.1, GET /stock_news
2025-06-19 19:49:37,229 [INFO] Error while receiving.
Traceback (most recent call last):
  File "C:\Users\jaehy\anaconda3\Lib\site-packages\py4j\clientserver.py", line 511, in send_command
    answer = smart_decode(self.stream.readline()[:-1])
                          ^^^^^^^^^^^^^^^^^^^^^^
  File "C:\Users\jaehy\anaconda3\Lib\socket.py", line 706, in readinto
    return self._sock.recv_into(b)
           ^^^^^^^^^^^^^^^^^^^^^^^
ConnectionResetError: [WinError 10054] 현재 연결은 원격 호스트에 의해 강제로 끊겼습니다
2025-06-19 19:49:37,232 [INFO] Closing down clientserver connection
2025-06-19 19:49:37,232 [ERROR] Exception while sending command.
Traceback (most recent call last):
  File "C:\Users\jaehy\anaconda3\Lib\site-packages\py4j\clientserver.py", line 511, in send_command
    answer = smart_decode(self.stream.readline()[:-1])
                          ^^^^^^^^^^^^^^^^^^^^^^
  File "C:\Users\jaehy\anaconda3\Lib\socket.py", line 706, in readinto
    return self._sock.recv_into(b)
           ^^^^^^^^^^^^^^^^^^^^^^^
ConnectionResetError: [WinError 10054] 현재 연결은 원격 호스트에 의해 강제로 끊겼습니다

During handling of the above exception, another exception occurred:

Traceback (most recent call last):
  File "C:\Users\jaehy\anaconda3\Lib\site-packages\py4j\java_gateway.py", line 1038, in send_command
    response = connection.send_command(command)
               ^^^^^^^^^^^^^^^^^^^^^^^^^^^^^^^^
  File "C:\Users\jaehy\anaconda3\Lib\site-packages\py4j\clientserver.py", line 539, in send_command
    raise Py4JNetworkError(
py4j.protocol.Py4JNetworkError: Error while sending or receiving
2025-06-19 19:49:37,234 [INFO] Closing down clientserver connection
2025-06-19 19:49:37,284 [INFO] Closing down clientserver connection
2025-06-19 21:05:58,891 [INFO] [31m[1mWARNING: This is a development server. Do not use it in a production deployment. Use a production WSGI server instead.[0m
 * Running on all addresses (0.0.0.0)
 * Running on http://127.0.0.1:5000
 * Running on http://192.168.0.7:5000
2025-06-19 21:05:58,891 [INFO] [33mPress CTRL+C to quit[0m
2025-06-19 21:06:02,090 [INFO] [요청] IP: 127.0.0.1, POST /realtime_search
2025-06-19 21:06:02,405 [ERROR] Exception on /realtime_search [POST]
Traceback (most recent call last):
  File "C:\Users\jaehy\anaconda3\Lib\site-packages\flask\app.py", line 2529, in wsgi_app
    response = self.full_dispatch_request()
               ^^^^^^^^^^^^^^^^^^^^^^^^^^^^
  File "C:\Users\jaehy\anaconda3\Lib\site-packages\flask\app.py", line 1825, in full_dispatch_request
    rv = self.handle_user_exception(e)
         ^^^^^^^^^^^^^^^^^^^^^^^^^^^^^
  File "C:\Users\jaehy\anaconda3\Lib\site-packages\flask_cors\extension.py", line 176, in wrapped_function
    return cors_after_request(app.make_response(f(*args, **kwargs)))
                                                ^^^^^^^^^^^^^^^^^^
  File "C:\Users\jaehy\anaconda3\Lib\site-packages\flask\app.py", line 1823, in full_dispatch_request
    rv = self.dispatch_request()
         ^^^^^^^^^^^^^^^^^^^^^^^
  File "C:\Users\jaehy\anaconda3\Lib\site-packages\flask\app.py", line 1799, in dispatch_request
    return self.ensure_sync(self.view_functions[rule.endpoint])(**view_args)
           ^^^^^^^^^^^^^^^^^^^^^^^^^^^^^^^^^^^^^^^^^^^^^^^^^^^^^^^^^^^^^^^^^
  File "c:\JaeHyeok\TickerNow\TickerNow-backend\main.py", line 343, in run_realtime_search
    re = spark.sql(query)
         ^^^^^^^^^^^^^^^^
  File "C:\Users\jaehy\anaconda3\Lib\site-packages\pyspark\sql\session.py", line 1631, in sql
    return DataFrame(self._jsparkSession.sql(sqlQuery, litArgs), self)
                     ^^^^^^^^^^^^^^^^^^^^^^^^^^^^^^^^^^^^^^^^^^
  File "C:\Users\jaehy\anaconda3\Lib\site-packages\py4j\java_gateway.py", line 1322, in __call__
    return_value = get_return_value(
                   ^^^^^^^^^^^^^^^^^
  File "C:\Users\jaehy\anaconda3\Lib\site-packages\pyspark\errors\exceptions\captured.py", line 185, in deco
    raise converted from None
pyspark.errors.exceptions.captured.ParseException: 
[PARSE_SYNTAX_ERROR] Syntax error at or near end of input.(line 5, pos 4)

== SQL ==

    select daum_financial_stock_table
    from user_info
    where name = LIKE '삼성' %
    
----^^^

2025-06-19 21:06:02,414 [INFO] 127.0.0.1 - - [19/Jun/2025 21:06:02] "[35m[1mPOST /realtime_search HTTP/1.1[0m" 500 -
2025-06-19 21:06:02,414 [INFO] Closing down clientserver connection
2025-06-19 21:06:32,827 [INFO] Error while receiving.
Traceback (most recent call last):
  File "C:\Users\jaehy\anaconda3\Lib\site-packages\py4j\clientserver.py", line 511, in send_command
    answer = smart_decode(self.stream.readline()[:-1])
                          ^^^^^^^^^^^^^^^^^^^^^^
  File "C:\Users\jaehy\anaconda3\Lib\socket.py", line 706, in readinto
    return self._sock.recv_into(b)
           ^^^^^^^^^^^^^^^^^^^^^^^
ConnectionResetError: [WinError 10054] 현재 연결은 원격 호스트에 의해 강제로 끊겼습니다
2025-06-19 21:06:32,829 [INFO] Closing down clientserver connection
2025-06-19 21:06:32,829 [ERROR] Exception while sending command.
Traceback (most recent call last):
  File "C:\Users\jaehy\anaconda3\Lib\site-packages\py4j\clientserver.py", line 511, in send_command
    answer = smart_decode(self.stream.readline()[:-1])
                          ^^^^^^^^^^^^^^^^^^^^^^
  File "C:\Users\jaehy\anaconda3\Lib\socket.py", line 706, in readinto
    return self._sock.recv_into(b)
           ^^^^^^^^^^^^^^^^^^^^^^^
ConnectionResetError: [WinError 10054] 현재 연결은 원격 호스트에 의해 강제로 끊겼습니다

During handling of the above exception, another exception occurred:

Traceback (most recent call last):
  File "C:\Users\jaehy\anaconda3\Lib\site-packages\py4j\java_gateway.py", line 1038, in send_command
    response = connection.send_command(command)
               ^^^^^^^^^^^^^^^^^^^^^^^^^^^^^^^^
  File "C:\Users\jaehy\anaconda3\Lib\site-packages\py4j\clientserver.py", line 539, in send_command
    raise Py4JNetworkError(
py4j.protocol.Py4JNetworkError: Error while sending or receiving
2025-06-19 21:06:32,830 [INFO] Closing down clientserver connection
2025-06-19 21:06:32,869 [INFO] Closing down clientserver connection
2025-06-19 21:06:43,455 [INFO] [31m[1mWARNING: This is a development server. Do not use it in a production deployment. Use a production WSGI server instead.[0m
 * Running on all addresses (0.0.0.0)
 * Running on http://127.0.0.1:5000
 * Running on http://192.168.0.7:5000
2025-06-19 21:06:43,455 [INFO] [33mPress CTRL+C to quit[0m
2025-06-19 21:06:46,089 [INFO] [요청] IP: 127.0.0.1, POST /realtime_search
2025-06-19 21:06:46,369 [ERROR] Exception on /realtime_search [POST]
Traceback (most recent call last):
  File "C:\Users\jaehy\anaconda3\Lib\site-packages\flask\app.py", line 2529, in wsgi_app
    response = self.full_dispatch_request()
               ^^^^^^^^^^^^^^^^^^^^^^^^^^^^
  File "C:\Users\jaehy\anaconda3\Lib\site-packages\flask\app.py", line 1825, in full_dispatch_request
    rv = self.handle_user_exception(e)
         ^^^^^^^^^^^^^^^^^^^^^^^^^^^^^
  File "C:\Users\jaehy\anaconda3\Lib\site-packages\flask_cors\extension.py", line 176, in wrapped_function
    return cors_after_request(app.make_response(f(*args, **kwargs)))
                                                ^^^^^^^^^^^^^^^^^^
  File "C:\Users\jaehy\anaconda3\Lib\site-packages\flask\app.py", line 1823, in full_dispatch_request
    rv = self.dispatch_request()
         ^^^^^^^^^^^^^^^^^^^^^^^
  File "C:\Users\jaehy\anaconda3\Lib\site-packages\flask\app.py", line 1799, in dispatch_request
    return self.ensure_sync(self.view_functions[rule.endpoint])(**view_args)
           ^^^^^^^^^^^^^^^^^^^^^^^^^^^^^^^^^^^^^^^^^^^^^^^^^^^^^^^^^^^^^^^^^
  File "c:\JaeHyeok\TickerNow\TickerNow-backend\main.py", line 343, in run_realtime_search
    re = spark.sql(query)
         ^^^^^^^^^^^^^^^^
  File "C:\Users\jaehy\anaconda3\Lib\site-packages\pyspark\sql\session.py", line 1631, in sql
    return DataFrame(self._jsparkSession.sql(sqlQuery, litArgs), self)
                     ^^^^^^^^^^^^^^^^^^^^^^^^^^^^^^^^^^^^^^^^^^
  File "C:\Users\jaehy\anaconda3\Lib\site-packages\py4j\java_gateway.py", line 1322, in __call__
    return_value = get_return_value(
                   ^^^^^^^^^^^^^^^^^
  File "C:\Users\jaehy\anaconda3\Lib\site-packages\pyspark\errors\exceptions\captured.py", line 185, in deco
    raise converted from None
pyspark.errors.exceptions.captured.ParseException: 
[PARSE_SYNTAX_ERROR] Syntax error at or near end of input.(line 5, pos 4)

== SQL ==

    select daum_financial_stock_table
    from user_info
    where name LIKE '삼성' %
    
----^^^

2025-06-19 21:06:46,378 [INFO] 127.0.0.1 - - [19/Jun/2025 21:06:46] "[35m[1mPOST /realtime_search HTTP/1.1[0m" 500 -
2025-06-19 21:06:46,379 [INFO] Closing down clientserver connection
2025-06-19 21:07:53,710 [INFO] Error while receiving.
Traceback (most recent call last):
  File "C:\Users\jaehy\anaconda3\Lib\site-packages\py4j\clientserver.py", line 511, in send_command
    answer = smart_decode(self.stream.readline()[:-1])
                          ^^^^^^^^^^^^^^^^^^^^^^
  File "C:\Users\jaehy\anaconda3\Lib\socket.py", line 706, in readinto
    return self._sock.recv_into(b)
           ^^^^^^^^^^^^^^^^^^^^^^^
ConnectionResetError: [WinError 10054] 현재 연결은 원격 호스트에 의해 강제로 끊겼습니다
2025-06-19 21:07:53,712 [INFO] Closing down clientserver connection
2025-06-19 21:07:53,712 [ERROR] Exception while sending command.
Traceback (most recent call last):
  File "C:\Users\jaehy\anaconda3\Lib\site-packages\py4j\clientserver.py", line 511, in send_command
    answer = smart_decode(self.stream.readline()[:-1])
                          ^^^^^^^^^^^^^^^^^^^^^^
  File "C:\Users\jaehy\anaconda3\Lib\socket.py", line 706, in readinto
    return self._sock.recv_into(b)
           ^^^^^^^^^^^^^^^^^^^^^^^
ConnectionResetError: [WinError 10054] 현재 연결은 원격 호스트에 의해 강제로 끊겼습니다

During handling of the above exception, another exception occurred:

Traceback (most recent call last):
  File "C:\Users\jaehy\anaconda3\Lib\site-packages\py4j\java_gateway.py", line 1038, in send_command
    response = connection.send_command(command)
               ^^^^^^^^^^^^^^^^^^^^^^^^^^^^^^^^
  File "C:\Users\jaehy\anaconda3\Lib\site-packages\py4j\clientserver.py", line 539, in send_command
    raise Py4JNetworkError(
py4j.protocol.Py4JNetworkError: Error while sending or receiving
2025-06-19 21:07:53,713 [INFO] Closing down clientserver connection
2025-06-19 21:07:53,752 [INFO] Closing down clientserver connection
2025-06-19 21:08:04,802 [INFO] [31m[1mWARNING: This is a development server. Do not use it in a production deployment. Use a production WSGI server instead.[0m
 * Running on all addresses (0.0.0.0)
 * Running on http://127.0.0.1:5000
 * Running on http://192.168.0.7:5000
2025-06-19 21:08:04,802 [INFO] [33mPress CTRL+C to quit[0m
2025-06-19 21:08:09,096 [INFO] [요청] IP: 127.0.0.1, POST /realtime_search
2025-06-19 21:08:09,401 [ERROR] Exception on /realtime_search [POST]
Traceback (most recent call last):
  File "C:\Users\jaehy\anaconda3\Lib\site-packages\flask\app.py", line 2529, in wsgi_app
    response = self.full_dispatch_request()
               ^^^^^^^^^^^^^^^^^^^^^^^^^^^^
  File "C:\Users\jaehy\anaconda3\Lib\site-packages\flask\app.py", line 1825, in full_dispatch_request
    rv = self.handle_user_exception(e)
         ^^^^^^^^^^^^^^^^^^^^^^^^^^^^^
  File "C:\Users\jaehy\anaconda3\Lib\site-packages\flask_cors\extension.py", line 176, in wrapped_function
    return cors_after_request(app.make_response(f(*args, **kwargs)))
                                                ^^^^^^^^^^^^^^^^^^
  File "C:\Users\jaehy\anaconda3\Lib\site-packages\flask\app.py", line 1823, in full_dispatch_request
    rv = self.dispatch_request()
         ^^^^^^^^^^^^^^^^^^^^^^^
  File "C:\Users\jaehy\anaconda3\Lib\site-packages\flask\app.py", line 1799, in dispatch_request
    return self.ensure_sync(self.view_functions[rule.endpoint])(**view_args)
           ^^^^^^^^^^^^^^^^^^^^^^^^^^^^^^^^^^^^^^^^^^^^^^^^^^^^^^^^^^^^^^^^^
  File "c:\JaeHyeok\TickerNow\TickerNow-backend\main.py", line 343, in run_realtime_search
    re = spark.sql(query)
         ^^^^^^^^^^^^^^^^
  File "C:\Users\jaehy\anaconda3\Lib\site-packages\pyspark\sql\session.py", line 1631, in sql
    return DataFrame(self._jsparkSession.sql(sqlQuery, litArgs), self)
                     ^^^^^^^^^^^^^^^^^^^^^^^^^^^^^^^^^^^^^^^^^^
  File "C:\Users\jaehy\anaconda3\Lib\site-packages\py4j\java_gateway.py", line 1322, in __call__
    return_value = get_return_value(
                   ^^^^^^^^^^^^^^^^^
  File "C:\Users\jaehy\anaconda3\Lib\site-packages\pyspark\errors\exceptions\captured.py", line 185, in deco
    raise converted from None
pyspark.errors.exceptions.captured.ParseException: 
[PARSE_SYNTAX_ERROR] Syntax error at or near 'LIKE'.(line 4, pos 15)

== SQL ==

    select daum_financial_stock_table
    from user_info
    where name LIKE 삼성 %
---------------^^^
    

2025-06-19 21:08:09,412 [INFO] 127.0.0.1 - - [19/Jun/2025 21:08:09] "[35m[1mPOST /realtime_search HTTP/1.1[0m" 500 -
2025-06-19 21:08:09,412 [INFO] Closing down clientserver connection
2025-06-19 21:09:57,266 [INFO] Error while sending or receiving.
Traceback (most recent call last):
  File "C:\Users\jaehy\anaconda3\Lib\site-packages\pyspark\errors\exceptions\captured.py", line 179, in deco
    return f(*a, **kw)
           ^^^^^^^^^^^
  File "C:\Users\jaehy\anaconda3\Lib\site-packages\py4j\protocol.py", line 326, in get_return_value
    raise Py4JJavaError(
py4j.protocol.Py4JJavaError: <exception str() failed>

During handling of the above exception, another exception occurred:

Traceback (most recent call last):
  File "C:\Users\jaehy\anaconda3\Lib\site-packages\py4j\clientserver.py", line 511, in send_command
    answer = smart_decode(self.stream.readline()[:-1])
                          ^^^^^^^^^^^^^^^^^^^^^^
  File "C:\Users\jaehy\anaconda3\Lib\socket.py", line 706, in readinto
    return self._sock.recv_into(b)
           ^^^^^^^^^^^^^^^^^^^^^^^
ConnectionResetError: [WinError 10054] 현재 연결은 원격 호스트에 의해 강제로 끊겼습니다

During handling of the above exception, another exception occurred:

Traceback (most recent call last):
  File "C:\Users\jaehy\anaconda3\Lib\site-packages\py4j\clientserver.py", line 503, in send_command
    self.socket.sendall(command.encode("utf-8"))
ConnectionResetError: [WinError 10054] 현재 연결은 원격 호스트에 의해 강제로 끊겼습니다

During handling of the above exception, another exception occurred:

Traceback (most recent call last):
  File "C:\Users\jaehy\anaconda3\Lib\site-packages\py4j\clientserver.py", line 503, in send_command
    self.socket.sendall(command.encode("utf-8"))
ConnectionResetError: [WinError 10054] 현재 연결은 원격 호스트에 의해 강제로 끊겼습니다

During handling of the above exception, another exception occurred:

Traceback (most recent call last):
  File "C:\Users\jaehy\anaconda3\Lib\site-packages\py4j\clientserver.py", line 503, in send_command
    self.socket.sendall(command.encode("utf-8"))
ConnectionResetError: [WinError 10054] 현재 연결은 원격 호스트에 의해 강제로 끊겼습니다

During handling of the above exception, another exception occurred:

Traceback (most recent call last):
  File "C:\Users\jaehy\anaconda3\Lib\site-packages\py4j\clientserver.py", line 503, in send_command
    self.socket.sendall(command.encode("utf-8"))
ConnectionResetError: [WinError 10054] 현재 연결은 원격 호스트에 의해 강제로 끊겼습니다

During handling of the above exception, another exception occurred:

Traceback (most recent call last):
  File "C:\Users\jaehy\anaconda3\Lib\site-packages\py4j\clientserver.py", line 503, in send_command
    self.socket.sendall(command.encode("utf-8"))
ConnectionResetError: [WinError 10054] 현재 연결은 원격 호스트에 의해 강제로 끊겼습니다

During handling of the above exception, another exception occurred:

Traceback (most recent call last):
  File "C:\Users\jaehy\anaconda3\Lib\site-packages\py4j\clientserver.py", line 503, in send_command
    self.socket.sendall(command.encode("utf-8"))
ConnectionResetError: [WinError 10054] 현재 연결은 원격 호스트에 의해 강제로 끊겼습니다

During handling of the above exception, another exception occurred:

Traceback (most recent call last):
  File "C:\Users\jaehy\anaconda3\Lib\site-packages\py4j\clientserver.py", line 503, in send_command
    self.socket.sendall(command.encode("utf-8"))
ConnectionResetError: [WinError 10054] 현재 연결은 원격 호스트에 의해 강제로 끊겼습니다

During handling of the above exception, another exception occurred:

Traceback (most recent call last):
  File "C:\Users\jaehy\anaconda3\Lib\site-packages\py4j\clientserver.py", line 503, in send_command
    self.socket.sendall(command.encode("utf-8"))
ConnectionResetError: [WinError 10054] 현재 연결은 원격 호스트에 의해 강제로 끊겼습니다

During handling of the above exception, another exception occurred:

Traceback (most recent call last):
  File "C:\Users\jaehy\anaconda3\Lib\site-packages\py4j\clientserver.py", line 503, in send_command
    self.socket.sendall(command.encode("utf-8"))
ConnectionResetError: [WinError 10054] 현재 연결은 원격 호스트에 의해 강제로 끊겼습니다

During handling of the above exception, another exception occurred:

Traceback (most recent call last):
  File "C:\Users\jaehy\anaconda3\Lib\site-packages\py4j\clientserver.py", line 503, in send_command
    self.socket.sendall(command.encode("utf-8"))
ConnectionResetError: [WinError 10054] 현재 연결은 원격 호스트에 의해 강제로 끊겼습니다

During handling of the above exception, another exception occurred:

Traceback (most recent call last):
  File "C:\Users\jaehy\anaconda3\Lib\site-packages\py4j\clientserver.py", line 503, in send_command
    self.socket.sendall(command.encode("utf-8"))
ConnectionResetError: [WinError 10054] 현재 연결은 원격 호스트에 의해 강제로 끊겼습니다

During handling of the above exception, another exception occurred:

Traceback (most recent call last):
  File "C:\Users\jaehy\anaconda3\Lib\site-packages\py4j\clientserver.py", line 503, in send_command
    self.socket.sendall(command.encode("utf-8"))
ConnectionResetError: [WinError 10054] 현재 연결은 원격 호스트에 의해 강제로 끊겼습니다

During handling of the above exception, another exception occurred:

Traceback (most recent call last):
  File "C:\Users\jaehy\anaconda3\Lib\site-packages\py4j\clientserver.py", line 503, in send_command
    self.socket.sendall(command.encode("utf-8"))
ConnectionResetError: [WinError 10054] 현재 연결은 원격 호스트에 의해 강제로 끊겼습니다

During handling of the above exception, another exception occurred:

Traceback (most recent call last):
  File "C:\Users\jaehy\anaconda3\Lib\site-packages\py4j\clientserver.py", line 503, in send_command
    self.socket.sendall(command.encode("utf-8"))
ConnectionResetError: [WinError 10054] 현재 연결은 원격 호스트에 의해 강제로 끊겼습니다

During handling of the above exception, another exception occurred:

Traceback (most recent call last):
  File "C:\Users\jaehy\anaconda3\Lib\site-packages\py4j\clientserver.py", line 503, in send_command
    self.socket.sendall(command.encode("utf-8"))
ConnectionResetError: [WinError 10054] 현재 연결은 원격 호스트에 의해 강제로 끊겼습니다

During handling of the above exception, another exception occurred:

Traceback (most recent call last):
  File "C:\Users\jaehy\anaconda3\Lib\site-packages\py4j\clientserver.py", line 503, in send_command
    self.socket.sendall(command.encode("utf-8"))
ConnectionResetError: [WinError 10054] 현재 연결은 원격 호스트에 의해 강제로 끊겼습니다

During handling of the above exception, another exception occurred:

Traceback (most recent call last):
  File "C:\Users\jaehy\anaconda3\Lib\site-packages\py4j\clientserver.py", line 503, in send_command
    self.socket.sendall(command.encode("utf-8"))
ConnectionResetError: [WinError 10054] 현재 연결은 원격 호스트에 의해 강제로 끊겼습니다

During handling of the above exception, another exception occurred:

Traceback (most recent call last):
  File "C:\Users\jaehy\anaconda3\Lib\site-packages\py4j\clientserver.py", line 503, in send_command
    self.socket.sendall(command.encode("utf-8"))
ConnectionResetError: [WinError 10054] 현재 연결은 원격 호스트에 의해 강제로 끊겼습니다

During handling of the above exception, another exception occurred:

Traceback (most recent call last):
  File "C:\Users\jaehy\anaconda3\Lib\site-packages\py4j\clientserver.py", line 503, in send_command
    self.socket.sendall(command.encode("utf-8"))
ConnectionResetError: [WinError 10054] 현재 연결은 원격 호스트에 의해 강제로 끊겼습니다

During handling of the above exception, another exception occurred:

Traceback (most recent call last):
  File "C:\Users\jaehy\anaconda3\Lib\site-packages\py4j\clientserver.py", line 503, in send_command
    self.socket.sendall(command.encode("utf-8"))
ConnectionResetError: [WinError 10054] 현재 연결은 원격 호스트에 의해 강제로 끊겼습니다

During handling of the above exception, another exception occurred:

Traceback (most recent call last):
  File "C:\Users\jaehy\anaconda3\Lib\site-packages\py4j\clientserver.py", line 503, in send_command
    self.socket.sendall(command.encode("utf-8"))
ConnectionResetError: [WinError 10054] 현재 연결은 원격 호스트에 의해 강제로 끊겼습니다

During handling of the above exception, another exception occurred:

Traceback (most recent call last):
  File "C:\Users\jaehy\anaconda3\Lib\site-packages\py4j\clientserver.py", line 503, in send_command
    self.socket.sendall(command.encode("utf-8"))
ConnectionResetError: [WinError 10054] 현재 연결은 원격 호스트에 의해 강제로 끊겼습니다

During handling of the above exception, another exception occurred:

Traceback (most recent call last):
  File "C:\Users\jaehy\anaconda3\Lib\site-packages\py4j\clientserver.py", line 503, in send_command
    self.socket.sendall(command.encode("utf-8"))
ConnectionResetError: [WinError 10054] 현재 연결은 원격 호스트에 의해 강제로 끊겼습니다

During handling of the above exception, another exception occurred:

Traceback (most recent call last):
  File "C:\Users\jaehy\anaconda3\Lib\site-packages\py4j\clientserver.py", line 503, in send_command
    self.socket.sendall(command.encode("utf-8"))
ConnectionResetError: [WinError 10054] 현재 연결은 원격 호스트에 의해 강제로 끊겼습니다

During handling of the above exception, another exception occurred:

Traceback (most recent call last):
  File "C:\Users\jaehy\anaconda3\Lib\site-packages\py4j\clientserver.py", line 503, in send_command
    self.socket.sendall(command.encode("utf-8"))
ConnectionResetError: [WinError 10054] 현재 연결은 원격 호스트에 의해 강제로 끊겼습니다

During handling of the above exception, another exception occurred:

Traceback (most recent call last):
  File "C:\Users\jaehy\anaconda3\Lib\site-packages\py4j\clientserver.py", line 503, in send_command
    self.socket.sendall(command.encode("utf-8"))
ConnectionResetError: [WinError 10054] 현재 연결은 원격 호스트에 의해 강제로 끊겼습니다

During handling of the above exception, another exception occurred:

Traceback (most recent call last):
  File "C:\Users\jaehy\anaconda3\Lib\site-packages\py4j\clientserver.py", line 503, in send_command
    self.socket.sendall(command.encode("utf-8"))
ConnectionResetError: [WinError 10054] 현재 연결은 원격 호스트에 의해 강제로 끊겼습니다

During handling of the above exception, another exception occurred:

Traceback (most recent call last):
  File "C:\Users\jaehy\anaconda3\Lib\site-packages\py4j\clientserver.py", line 503, in send_command
    self.socket.sendall(command.encode("utf-8"))
ConnectionResetError: [WinError 10054] 현재 연결은 원격 호스트에 의해 강제로 끊겼습니다

During handling of the above exception, another exception occurred:

Traceback (most recent call last):
  File "C:\Users\jaehy\anaconda3\Lib\site-packages\py4j\clientserver.py", line 503, in send_command
    self.socket.sendall(command.encode("utf-8"))
ConnectionResetError: [WinError 10054] 현재 연결은 원격 호스트에 의해 강제로 끊겼습니다

During handling of the above exception, another exception occurred:

Traceback (most recent call last):
  File "C:\Users\jaehy\anaconda3\Lib\site-packages\py4j\clientserver.py", line 503, in send_command
    self.socket.sendall(command.encode("utf-8"))
ConnectionResetError: [WinError 10054] 현재 연결은 원격 호스트에 의해 강제로 끊겼습니다

During handling of the above exception, another exception occurred:

Traceback (most recent call last):
  File "C:\Users\jaehy\anaconda3\Lib\site-packages\py4j\clientserver.py", line 503, in send_command
    self.socket.sendall(command.encode("utf-8"))
ConnectionResetError: [WinError 10054] 현재 연결은 원격 호스트에 의해 강제로 끊겼습니다

During handling of the above exception, another exception occurred:

Traceback (most recent call last):
  File "C:\Users\jaehy\anaconda3\Lib\site-packages\py4j\clientserver.py", line 503, in send_command
    self.socket.sendall(command.encode("utf-8"))
ConnectionResetError: [WinError 10054] 현재 연결은 원격 호스트에 의해 강제로 끊겼습니다

During handling of the above exception, another exception occurred:

Traceback (most recent call last):
  File "C:\Users\jaehy\anaconda3\Lib\site-packages\py4j\clientserver.py", line 503, in send_command
    self.socket.sendall(command.encode("utf-8"))
ConnectionResetError: [WinError 10054] 현재 연결은 원격 호스트에 의해 강제로 끊겼습니다

During handling of the above exception, another exception occurred:

Traceback (most recent call last):
  File "C:\Users\jaehy\anaconda3\Lib\site-packages\py4j\clientserver.py", line 503, in send_command
    self.socket.sendall(command.encode("utf-8"))
ConnectionResetError: [WinError 10054] 현재 연결은 원격 호스트에 의해 강제로 끊겼습니다

During handling of the above exception, another exception occurred:

Traceback (most recent call last):
  File "C:\Users\jaehy\anaconda3\Lib\site-packages\py4j\clientserver.py", line 503, in send_command
    self.socket.sendall(command.encode("utf-8"))
ConnectionResetError: [WinError 10054] 현재 연결은 원격 호스트에 의해 강제로 끊겼습니다

During handling of the above exception, another exception occurred:

Traceback (most recent call last):
  File "C:\Users\jaehy\anaconda3\Lib\site-packages\py4j\clientserver.py", line 503, in send_command
    self.socket.sendall(command.encode("utf-8"))
ConnectionResetError: [WinError 10054] 현재 연결은 원격 호스트에 의해 강제로 끊겼습니다

During handling of the above exception, another exception occurred:

Traceback (most recent call last):
  File "C:\Users\jaehy\anaconda3\Lib\site-packages\py4j\clientserver.py", line 503, in send_command
    self.socket.sendall(command.encode("utf-8"))
ConnectionResetError: [WinError 10054] 현재 연결은 원격 호스트에 의해 강제로 끊겼습니다

During handling of the above exception, another exception occurred:

Traceback (most recent call last):
  File "C:\Users\jaehy\anaconda3\Lib\site-packages\py4j\clientserver.py", line 503, in send_command
    self.socket.sendall(command.encode("utf-8"))
ConnectionResetError: [WinError 10054] 현재 연결은 원격 호스트에 의해 강제로 끊겼습니다

During handling of the above exception, another exception occurred:

Traceback (most recent call last):
  File "C:\Users\jaehy\anaconda3\Lib\site-packages\py4j\clientserver.py", line 503, in send_command
    self.socket.sendall(command.encode("utf-8"))
ConnectionResetError: [WinError 10054] 현재 연결은 원격 호스트에 의해 강제로 끊겼습니다

During handling of the above exception, another exception occurred:

Traceback (most recent call last):
  File "C:\Users\jaehy\anaconda3\Lib\site-packages\py4j\clientserver.py", line 503, in send_command
    self.socket.sendall(command.encode("utf-8"))
ConnectionResetError: [WinError 10054] 현재 연결은 원격 호스트에 의해 강제로 끊겼습니다

During handling of the above exception, another exception occurred:

Traceback (most recent call last):
  File "C:\Users\jaehy\anaconda3\Lib\site-packages\py4j\clientserver.py", line 503, in send_command
    self.socket.sendall(command.encode("utf-8"))
ConnectionResetError: [WinError 10054] 현재 연결은 원격 호스트에 의해 강제로 끊겼습니다

During handling of the above exception, another exception occurred:

Traceback (most recent call last):
  File "C:\Users\jaehy\anaconda3\Lib\site-packages\py4j\clientserver.py", line 503, in send_command
    self.socket.sendall(command.encode("utf-8"))
ConnectionResetError: [WinError 10054] 현재 연결은 원격 호스트에 의해 강제로 끊겼습니다

During handling of the above exception, another exception occurred:

Traceback (most recent call last):
  File "C:\Users\jaehy\anaconda3\Lib\site-packages\py4j\clientserver.py", line 503, in send_command
    self.socket.sendall(command.encode("utf-8"))
ConnectionResetError: [WinError 10054] 현재 연결은 원격 호스트에 의해 강제로 끊겼습니다

During handling of the above exception, another exception occurred:

Traceback (most recent call last):
  File "C:\Users\jaehy\anaconda3\Lib\site-packages\py4j\clientserver.py", line 503, in send_command
    self.socket.sendall(command.encode("utf-8"))
ConnectionResetError: [WinError 10054] 현재 연결은 원격 호스트에 의해 강제로 끊겼습니다

During handling of the above exception, another exception occurred:

Traceback (most recent call last):
  File "C:\Users\jaehy\anaconda3\Lib\site-packages\py4j\clientserver.py", line 503, in send_command
    self.socket.sendall(command.encode("utf-8"))
ConnectionResetError: [WinError 10054] 현재 연결은 원격 호스트에 의해 강제로 끊겼습니다

During handling of the above exception, another exception occurred:

Traceback (most recent call last):
  File "C:\Users\jaehy\anaconda3\Lib\site-packages\py4j\clientserver.py", line 503, in send_command
    self.socket.sendall(command.encode("utf-8"))
ConnectionResetError: [WinError 10054] 현재 연결은 원격 호스트에 의해 강제로 끊겼습니다

During handling of the above exception, another exception occurred:

Traceback (most recent call last):
  File "C:\Users\jaehy\anaconda3\Lib\site-packages\py4j\clientserver.py", line 503, in send_command
    self.socket.sendall(command.encode("utf-8"))
ConnectionResetError: [WinError 10054] 현재 연결은 원격 호스트에 의해 강제로 끊겼습니다

During handling of the above exception, another exception occurred:

Traceback (most recent call last):
  File "C:\Users\jaehy\anaconda3\Lib\site-packages\py4j\clientserver.py", line 503, in send_command
    self.socket.sendall(command.encode("utf-8"))
ConnectionResetError: [WinError 10054] 현재 연결은 원격 호스트에 의해 강제로 끊겼습니다
2025-06-19 21:09:57,273 [INFO] Closing down clientserver connection
2025-06-19 21:09:57,273 [INFO] Exception while sending command.
Traceback (most recent call last):
  File "C:\Users\jaehy\anaconda3\Lib\site-packages\pyspark\errors\exceptions\captured.py", line 179, in deco
    return f(*a, **kw)
           ^^^^^^^^^^^
  File "C:\Users\jaehy\anaconda3\Lib\site-packages\py4j\protocol.py", line 326, in get_return_value
    raise Py4JJavaError(
py4j.protocol.Py4JJavaError: <exception str() failed>

During handling of the above exception, another exception occurred:

Traceback (most recent call last):
  File "C:\Users\jaehy\anaconda3\Lib\site-packages\py4j\clientserver.py", line 511, in send_command
    answer = smart_decode(self.stream.readline()[:-1])
                          ^^^^^^^^^^^^^^^^^^^^^^
  File "C:\Users\jaehy\anaconda3\Lib\socket.py", line 706, in readinto
    return self._sock.recv_into(b)
           ^^^^^^^^^^^^^^^^^^^^^^^
ConnectionResetError: [WinError 10054] 현재 연결은 원격 호스트에 의해 강제로 끊겼습니다

During handling of the above exception, another exception occurred:

Traceback (most recent call last):
  File "C:\Users\jaehy\anaconda3\Lib\site-packages\py4j\clientserver.py", line 503, in send_command
    self.socket.sendall(command.encode("utf-8"))
ConnectionResetError: [WinError 10054] 현재 연결은 원격 호스트에 의해 강제로 끊겼습니다

During handling of the above exception, another exception occurred:

Traceback (most recent call last):
  File "C:\Users\jaehy\anaconda3\Lib\site-packages\py4j\clientserver.py", line 503, in send_command
    self.socket.sendall(command.encode("utf-8"))
ConnectionResetError: [WinError 10054] 현재 연결은 원격 호스트에 의해 강제로 끊겼습니다

During handling of the above exception, another exception occurred:

Traceback (most recent call last):
  File "C:\Users\jaehy\anaconda3\Lib\site-packages\py4j\clientserver.py", line 503, in send_command
    self.socket.sendall(command.encode("utf-8"))
ConnectionResetError: [WinError 10054] 현재 연결은 원격 호스트에 의해 강제로 끊겼습니다

During handling of the above exception, another exception occurred:

Traceback (most recent call last):
  File "C:\Users\jaehy\anaconda3\Lib\site-packages\py4j\clientserver.py", line 503, in send_command
    self.socket.sendall(command.encode("utf-8"))
ConnectionResetError: [WinError 10054] 현재 연결은 원격 호스트에 의해 강제로 끊겼습니다

During handling of the above exception, another exception occurred:

Traceback (most recent call last):
  File "C:\Users\jaehy\anaconda3\Lib\site-packages\py4j\clientserver.py", line 503, in send_command
    self.socket.sendall(command.encode("utf-8"))
ConnectionResetError: [WinError 10054] 현재 연결은 원격 호스트에 의해 강제로 끊겼습니다

During handling of the above exception, another exception occurred:

Traceback (most recent call last):
  File "C:\Users\jaehy\anaconda3\Lib\site-packages\py4j\clientserver.py", line 503, in send_command
    self.socket.sendall(command.encode("utf-8"))
ConnectionResetError: [WinError 10054] 현재 연결은 원격 호스트에 의해 강제로 끊겼습니다

During handling of the above exception, another exception occurred:

Traceback (most recent call last):
  File "C:\Users\jaehy\anaconda3\Lib\site-packages\py4j\clientserver.py", line 503, in send_command
    self.socket.sendall(command.encode("utf-8"))
ConnectionResetError: [WinError 10054] 현재 연결은 원격 호스트에 의해 강제로 끊겼습니다

During handling of the above exception, another exception occurred:

Traceback (most recent call last):
  File "C:\Users\jaehy\anaconda3\Lib\site-packages\py4j\clientserver.py", line 503, in send_command
    self.socket.sendall(command.encode("utf-8"))
ConnectionResetError: [WinError 10054] 현재 연결은 원격 호스트에 의해 강제로 끊겼습니다

During handling of the above exception, another exception occurred:

Traceback (most recent call last):
  File "C:\Users\jaehy\anaconda3\Lib\site-packages\py4j\clientserver.py", line 503, in send_command
    self.socket.sendall(command.encode("utf-8"))
ConnectionResetError: [WinError 10054] 현재 연결은 원격 호스트에 의해 강제로 끊겼습니다

During handling of the above exception, another exception occurred:

Traceback (most recent call last):
  File "C:\Users\jaehy\anaconda3\Lib\site-packages\py4j\clientserver.py", line 503, in send_command
    self.socket.sendall(command.encode("utf-8"))
ConnectionResetError: [WinError 10054] 현재 연결은 원격 호스트에 의해 강제로 끊겼습니다

During handling of the above exception, another exception occurred:

Traceback (most recent call last):
  File "C:\Users\jaehy\anaconda3\Lib\site-packages\py4j\clientserver.py", line 503, in send_command
    self.socket.sendall(command.encode("utf-8"))
ConnectionResetError: [WinError 10054] 현재 연결은 원격 호스트에 의해 강제로 끊겼습니다

During handling of the above exception, another exception occurred:

Traceback (most recent call last):
  File "C:\Users\jaehy\anaconda3\Lib\site-packages\py4j\clientserver.py", line 503, in send_command
    self.socket.sendall(command.encode("utf-8"))
ConnectionResetError: [WinError 10054] 현재 연결은 원격 호스트에 의해 강제로 끊겼습니다

During handling of the above exception, another exception occurred:

Traceback (most recent call last):
  File "C:\Users\jaehy\anaconda3\Lib\site-packages\py4j\clientserver.py", line 503, in send_command
    self.socket.sendall(command.encode("utf-8"))
ConnectionResetError: [WinError 10054] 현재 연결은 원격 호스트에 의해 강제로 끊겼습니다

During handling of the above exception, another exception occurred:

Traceback (most recent call last):
  File "C:\Users\jaehy\anaconda3\Lib\site-packages\py4j\clientserver.py", line 503, in send_command
    self.socket.sendall(command.encode("utf-8"))
ConnectionResetError: [WinError 10054] 현재 연결은 원격 호스트에 의해 강제로 끊겼습니다

During handling of the above exception, another exception occurred:

Traceback (most recent call last):
  File "C:\Users\jaehy\anaconda3\Lib\site-packages\py4j\clientserver.py", line 503, in send_command
    self.socket.sendall(command.encode("utf-8"))
ConnectionResetError: [WinError 10054] 현재 연결은 원격 호스트에 의해 강제로 끊겼습니다

During handling of the above exception, another exception occurred:

Traceback (most recent call last):
  File "C:\Users\jaehy\anaconda3\Lib\site-packages\py4j\clientserver.py", line 503, in send_command
    self.socket.sendall(command.encode("utf-8"))
ConnectionResetError: [WinError 10054] 현재 연결은 원격 호스트에 의해 강제로 끊겼습니다

During handling of the above exception, another exception occurred:

Traceback (most recent call last):
  File "C:\Users\jaehy\anaconda3\Lib\site-packages\py4j\clientserver.py", line 503, in send_command
    self.socket.sendall(command.encode("utf-8"))
ConnectionResetError: [WinError 10054] 현재 연결은 원격 호스트에 의해 강제로 끊겼습니다

During handling of the above exception, another exception occurred:

Traceback (most recent call last):
  File "C:\Users\jaehy\anaconda3\Lib\site-packages\py4j\clientserver.py", line 503, in send_command
    self.socket.sendall(command.encode("utf-8"))
ConnectionResetError: [WinError 10054] 현재 연결은 원격 호스트에 의해 강제로 끊겼습니다

During handling of the above exception, another exception occurred:

Traceback (most recent call last):
  File "C:\Users\jaehy\anaconda3\Lib\site-packages\py4j\clientserver.py", line 503, in send_command
    self.socket.sendall(command.encode("utf-8"))
ConnectionResetError: [WinError 10054] 현재 연결은 원격 호스트에 의해 강제로 끊겼습니다

During handling of the above exception, another exception occurred:

Traceback (most recent call last):
  File "C:\Users\jaehy\anaconda3\Lib\site-packages\py4j\clientserver.py", line 503, in send_command
    self.socket.sendall(command.encode("utf-8"))
ConnectionResetError: [WinError 10054] 현재 연결은 원격 호스트에 의해 강제로 끊겼습니다

During handling of the above exception, another exception occurred:

Traceback (most recent call last):
  File "C:\Users\jaehy\anaconda3\Lib\site-packages\py4j\clientserver.py", line 503, in send_command
    self.socket.sendall(command.encode("utf-8"))
ConnectionResetError: [WinError 10054] 현재 연결은 원격 호스트에 의해 강제로 끊겼습니다

During handling of the above exception, another exception occurred:

Traceback (most recent call last):
  File "C:\Users\jaehy\anaconda3\Lib\site-packages\py4j\clientserver.py", line 503, in send_command
    self.socket.sendall(command.encode("utf-8"))
ConnectionResetError: [WinError 10054] 현재 연결은 원격 호스트에 의해 강제로 끊겼습니다

During handling of the above exception, another exception occurred:

Traceback (most recent call last):
  File "C:\Users\jaehy\anaconda3\Lib\site-packages\py4j\clientserver.py", line 503, in send_command
    self.socket.sendall(command.encode("utf-8"))
ConnectionResetError: [WinError 10054] 현재 연결은 원격 호스트에 의해 강제로 끊겼습니다

During handling of the above exception, another exception occurred:

Traceback (most recent call last):
  File "C:\Users\jaehy\anaconda3\Lib\site-packages\py4j\clientserver.py", line 503, in send_command
    self.socket.sendall(command.encode("utf-8"))
ConnectionResetError: [WinError 10054] 현재 연결은 원격 호스트에 의해 강제로 끊겼습니다

During handling of the above exception, another exception occurred:

Traceback (most recent call last):
  File "C:\Users\jaehy\anaconda3\Lib\site-packages\py4j\clientserver.py", line 503, in send_command
    self.socket.sendall(command.encode("utf-8"))
ConnectionResetError: [WinError 10054] 현재 연결은 원격 호스트에 의해 강제로 끊겼습니다

During handling of the above exception, another exception occurred:

Traceback (most recent call last):
  File "C:\Users\jaehy\anaconda3\Lib\site-packages\py4j\clientserver.py", line 503, in send_command
    self.socket.sendall(command.encode("utf-8"))
ConnectionResetError: [WinError 10054] 현재 연결은 원격 호스트에 의해 강제로 끊겼습니다

During handling of the above exception, another exception occurred:

Traceback (most recent call last):
  File "C:\Users\jaehy\anaconda3\Lib\site-packages\py4j\clientserver.py", line 503, in send_command
    self.socket.sendall(command.encode("utf-8"))
ConnectionResetError: [WinError 10054] 현재 연결은 원격 호스트에 의해 강제로 끊겼습니다

During handling of the above exception, another exception occurred:

Traceback (most recent call last):
  File "C:\Users\jaehy\anaconda3\Lib\site-packages\py4j\clientserver.py", line 503, in send_command
    self.socket.sendall(command.encode("utf-8"))
ConnectionResetError: [WinError 10054] 현재 연결은 원격 호스트에 의해 강제로 끊겼습니다

During handling of the above exception, another exception occurred:

Traceback (most recent call last):
  File "C:\Users\jaehy\anaconda3\Lib\site-packages\py4j\clientserver.py", line 503, in send_command
    self.socket.sendall(command.encode("utf-8"))
ConnectionResetError: [WinError 10054] 현재 연결은 원격 호스트에 의해 강제로 끊겼습니다

During handling of the above exception, another exception occurred:

Traceback (most recent call last):
  File "C:\Users\jaehy\anaconda3\Lib\site-packages\py4j\clientserver.py", line 503, in send_command
    self.socket.sendall(command.encode("utf-8"))
ConnectionResetError: [WinError 10054] 현재 연결은 원격 호스트에 의해 강제로 끊겼습니다

During handling of the above exception, another exception occurred:

Traceback (most recent call last):
  File "C:\Users\jaehy\anaconda3\Lib\site-packages\py4j\clientserver.py", line 503, in send_command
    self.socket.sendall(command.encode("utf-8"))
ConnectionResetError: [WinError 10054] 현재 연결은 원격 호스트에 의해 강제로 끊겼습니다

During handling of the above exception, another exception occurred:

Traceback (most recent call last):
  File "C:\Users\jaehy\anaconda3\Lib\site-packages\py4j\clientserver.py", line 503, in send_command
    self.socket.sendall(command.encode("utf-8"))
ConnectionResetError: [WinError 10054] 현재 연결은 원격 호스트에 의해 강제로 끊겼습니다

During handling of the above exception, another exception occurred:

Traceback (most recent call last):
  File "C:\Users\jaehy\anaconda3\Lib\site-packages\py4j\clientserver.py", line 503, in send_command
    self.socket.sendall(command.encode("utf-8"))
ConnectionResetError: [WinError 10054] 현재 연결은 원격 호스트에 의해 강제로 끊겼습니다

During handling of the above exception, another exception occurred:

Traceback (most recent call last):
  File "C:\Users\jaehy\anaconda3\Lib\site-packages\py4j\clientserver.py", line 503, in send_command
    self.socket.sendall(command.encode("utf-8"))
ConnectionResetError: [WinError 10054] 현재 연결은 원격 호스트에 의해 강제로 끊겼습니다

During handling of the above exception, another exception occurred:

Traceback (most recent call last):
  File "C:\Users\jaehy\anaconda3\Lib\site-packages\py4j\clientserver.py", line 503, in send_command
    self.socket.sendall(command.encode("utf-8"))
ConnectionResetError: [WinError 10054] 현재 연결은 원격 호스트에 의해 강제로 끊겼습니다

During handling of the above exception, another exception occurred:

Traceback (most recent call last):
  File "C:\Users\jaehy\anaconda3\Lib\site-packages\py4j\clientserver.py", line 503, in send_command
    self.socket.sendall(command.encode("utf-8"))
ConnectionResetError: [WinError 10054] 현재 연결은 원격 호스트에 의해 강제로 끊겼습니다

During handling of the above exception, another exception occurred:

Traceback (most recent call last):
  File "C:\Users\jaehy\anaconda3\Lib\site-packages\py4j\clientserver.py", line 503, in send_command
    self.socket.sendall(command.encode("utf-8"))
ConnectionResetError: [WinError 10054] 현재 연결은 원격 호스트에 의해 강제로 끊겼습니다

During handling of the above exception, another exception occurred:

Traceback (most recent call last):
  File "C:\Users\jaehy\anaconda3\Lib\site-packages\py4j\clientserver.py", line 503, in send_command
    self.socket.sendall(command.encode("utf-8"))
ConnectionResetError: [WinError 10054] 현재 연결은 원격 호스트에 의해 강제로 끊겼습니다

During handling of the above exception, another exception occurred:

Traceback (most recent call last):
  File "C:\Users\jaehy\anaconda3\Lib\site-packages\py4j\clientserver.py", line 503, in send_command
    self.socket.sendall(command.encode("utf-8"))
ConnectionResetError: [WinError 10054] 현재 연결은 원격 호스트에 의해 강제로 끊겼습니다

During handling of the above exception, another exception occurred:

Traceback (most recent call last):
  File "C:\Users\jaehy\anaconda3\Lib\site-packages\py4j\clientserver.py", line 503, in send_command
    self.socket.sendall(command.encode("utf-8"))
ConnectionResetError: [WinError 10054] 현재 연결은 원격 호스트에 의해 강제로 끊겼습니다

During handling of the above exception, another exception occurred:

Traceback (most recent call last):
  File "C:\Users\jaehy\anaconda3\Lib\site-packages\py4j\clientserver.py", line 503, in send_command
    self.socket.sendall(command.encode("utf-8"))
ConnectionResetError: [WinError 10054] 현재 연결은 원격 호스트에 의해 강제로 끊겼습니다

During handling of the above exception, another exception occurred:

Traceback (most recent call last):
  File "C:\Users\jaehy\anaconda3\Lib\site-packages\py4j\clientserver.py", line 503, in send_command
    self.socket.sendall(command.encode("utf-8"))
ConnectionResetError: [WinError 10054] 현재 연결은 원격 호스트에 의해 강제로 끊겼습니다

During handling of the above exception, another exception occurred:

Traceback (most recent call last):
  File "C:\Users\jaehy\anaconda3\Lib\site-packages\py4j\clientserver.py", line 503, in send_command
    self.socket.sendall(command.encode("utf-8"))
ConnectionResetError: [WinError 10054] 현재 연결은 원격 호스트에 의해 강제로 끊겼습니다

During handling of the above exception, another exception occurred:

Traceback (most recent call last):
  File "C:\Users\jaehy\anaconda3\Lib\site-packages\py4j\clientserver.py", line 503, in send_command
    self.socket.sendall(command.encode("utf-8"))
ConnectionResetError: [WinError 10054] 현재 연결은 원격 호스트에 의해 강제로 끊겼습니다

During handling of the above exception, another exception occurred:

Traceback (most recent call last):
  File "C:\Users\jaehy\anaconda3\Lib\site-packages\py4j\clientserver.py", line 503, in send_command
    self.socket.sendall(command.encode("utf-8"))
ConnectionResetError: [WinError 10054] 현재 연결은 원격 호스트에 의해 강제로 끊겼습니다

During handling of the above exception, another exception occurred:

Traceback (most recent call last):
  File "C:\Users\jaehy\anaconda3\Lib\site-packages\py4j\clientserver.py", line 503, in send_command
    self.socket.sendall(command.encode("utf-8"))
ConnectionResetError: [WinError 10054] 현재 연결은 원격 호스트에 의해 강제로 끊겼습니다

During handling of the above exception, another exception occurred:

Traceback (most recent call last):
  File "C:\Users\jaehy\anaconda3\Lib\site-packages\py4j\clientserver.py", line 503, in send_command
    self.socket.sendall(command.encode("utf-8"))
ConnectionResetError: [WinError 10054] 현재 연결은 원격 호스트에 의해 강제로 끊겼습니다

During handling of the above exception, another exception occurred:

Traceback (most recent call last):
  File "C:\Users\jaehy\anaconda3\Lib\site-packages\py4j\clientserver.py", line 503, in send_command
    self.socket.sendall(command.encode("utf-8"))
ConnectionResetError: [WinError 10054] 현재 연결은 원격 호스트에 의해 강제로 끊겼습니다

During handling of the above exception, another exception occurred:

Traceback (most recent call last):
  File "C:\Users\jaehy\anaconda3\Lib\site-packages\py4j\java_gateway.py", line 1038, in send_command
    response = connection.send_command(command)
               ^^^^^^^^^^^^^^^^^^^^^^^^^^^^^^^^
  File "C:\Users\jaehy\anaconda3\Lib\site-packages\py4j\clientserver.py", line 506, in send_command
    raise Py4JNetworkError(
py4j.protocol.Py4JNetworkError: Error while sending
2025-06-19 21:09:59,295 [INFO] Closing down clientserver connection
2025-06-19 21:09:59,295 [INFO] Closing down clientserver connection
2025-06-19 21:09:57,263 [INFO] Error while sending or receiving.
Traceback (most recent call last):
  File "C:\Users\jaehy\anaconda3\Lib\site-packages\pyspark\errors\exceptions\captured.py", line 179, in deco
    return f(*a, **kw)
           ^^^^^^^^^^^
  File "C:\Users\jaehy\anaconda3\Lib\site-packages\py4j\protocol.py", line 326, in get_return_value
    raise Py4JJavaError(
py4j.protocol.Py4JJavaError: <exception str() failed>

During handling of the above exception, another exception occurred:

Traceback (most recent call last):
  File "C:\Users\jaehy\anaconda3\Lib\site-packages\py4j\clientserver.py", line 511, in send_command
    answer = smart_decode(self.stream.readline()[:-1])
                          ^^^^^^^^^^^^^^^^^^^^^^
  File "C:\Users\jaehy\anaconda3\Lib\socket.py", line 706, in readinto
    return self._sock.recv_into(b)
           ^^^^^^^^^^^^^^^^^^^^^^^
ConnectionResetError: [WinError 10054] 현재 연결은 원격 호스트에 의해 강제로 끊겼습니다

During handling of the above exception, another exception occurred:

Traceback (most recent call last):
  File "C:\Users\jaehy\anaconda3\Lib\site-packages\py4j\clientserver.py", line 503, in send_command
    self.socket.sendall(command.encode("utf-8"))
ConnectionResetError: [WinError 10054] 현재 연결은 원격 호스트에 의해 강제로 끊겼습니다

During handling of the above exception, another exception occurred:

Traceback (most recent call last):
  File "C:\Users\jaehy\anaconda3\Lib\site-packages\py4j\clientserver.py", line 503, in send_command
    self.socket.sendall(command.encode("utf-8"))
ConnectionResetError: [WinError 10054] 현재 연결은 원격 호스트에 의해 강제로 끊겼습니다

During handling of the above exception, another exception occurred:

Traceback (most recent call last):
  File "C:\Users\jaehy\anaconda3\Lib\site-packages\py4j\clientserver.py", line 503, in send_command
    self.socket.sendall(command.encode("utf-8"))
ConnectionResetError: [WinError 10054] 현재 연결은 원격 호스트에 의해 강제로 끊겼습니다

During handling of the above exception, another exception occurred:

Traceback (most recent call last):
  File "C:\Users\jaehy\anaconda3\Lib\site-packages\py4j\clientserver.py", line 503, in send_command
    self.socket.sendall(command.encode("utf-8"))
ConnectionResetError: [WinError 10054] 현재 연결은 원격 호스트에 의해 강제로 끊겼습니다

During handling of the above exception, another exception occurred:

Traceback (most recent call last):
  File "C:\Users\jaehy\anaconda3\Lib\site-packages\py4j\clientserver.py", line 503, in send_command
    self.socket.sendall(command.encode("utf-8"))
ConnectionResetError: [WinError 10054] 현재 연결은 원격 호스트에 의해 강제로 끊겼습니다

During handling of the above exception, another exception occurred:

Traceback (most recent call last):
  File "C:\Users\jaehy\anaconda3\Lib\site-packages\py4j\clientserver.py", line 503, in send_command
    self.socket.sendall(command.encode("utf-8"))
ConnectionResetError: [WinError 10054] 현재 연결은 원격 호스트에 의해 강제로 끊겼습니다

During handling of the above exception, another exception occurred:

Traceback (most recent call last):
  File "C:\Users\jaehy\anaconda3\Lib\site-packages\py4j\clientserver.py", line 503, in send_command
    self.socket.sendall(command.encode("utf-8"))
ConnectionResetError: [WinError 10054] 현재 연결은 원격 호스트에 의해 강제로 끊겼습니다

During handling of the above exception, another exception occurred:

Traceback (most recent call last):
  File "C:\Users\jaehy\anaconda3\Lib\site-packages\py4j\clientserver.py", line 503, in send_command
    self.socket.sendall(command.encode("utf-8"))
ConnectionResetError: [WinError 10054] 현재 연결은 원격 호스트에 의해 강제로 끊겼습니다

During handling of the above exception, another exception occurred:

Traceback (most recent call last):
  File "C:\Users\jaehy\anaconda3\Lib\site-packages\py4j\clientserver.py", line 503, in send_command
    self.socket.sendall(command.encode("utf-8"))
ConnectionResetError: [WinError 10054] 현재 연결은 원격 호스트에 의해 강제로 끊겼습니다

During handling of the above exception, another exception occurred:

Traceback (most recent call last):
  File "C:\Users\jaehy\anaconda3\Lib\site-packages\py4j\clientserver.py", line 503, in send_command
    self.socket.sendall(command.encode("utf-8"))
ConnectionResetError: [WinError 10054] 현재 연결은 원격 호스트에 의해 강제로 끊겼습니다

During handling of the above exception, another exception occurred:

Traceback (most recent call last):
  File "C:\Users\jaehy\anaconda3\Lib\site-packages\py4j\clientserver.py", line 503, in send_command
    self.socket.sendall(command.encode("utf-8"))
ConnectionResetError: [WinError 10054] 현재 연결은 원격 호스트에 의해 강제로 끊겼습니다

During handling of the above exception, another exception occurred:

Traceback (most recent call last):
  File "C:\Users\jaehy\anaconda3\Lib\site-packages\py4j\clientserver.py", line 503, in send_command
    self.socket.sendall(command.encode("utf-8"))
ConnectionResetError: [WinError 10054] 현재 연결은 원격 호스트에 의해 강제로 끊겼습니다

During handling of the above exception, another exception occurred:

Traceback (most recent call last):
  File "C:\Users\jaehy\anaconda3\Lib\site-packages\py4j\clientserver.py", line 503, in send_command
    self.socket.sendall(command.encode("utf-8"))
ConnectionResetError: [WinError 10054] 현재 연결은 원격 호스트에 의해 강제로 끊겼습니다

During handling of the above exception, another exception occurred:

Traceback (most recent call last):
  File "C:\Users\jaehy\anaconda3\Lib\site-packages\py4j\clientserver.py", line 503, in send_command
    self.socket.sendall(command.encode("utf-8"))
ConnectionResetError: [WinError 10054] 현재 연결은 원격 호스트에 의해 강제로 끊겼습니다

During handling of the above exception, another exception occurred:

Traceback (most recent call last):
  File "C:\Users\jaehy\anaconda3\Lib\site-packages\py4j\clientserver.py", line 503, in send_command
    self.socket.sendall(command.encode("utf-8"))
ConnectionResetError: [WinError 10054] 현재 연결은 원격 호스트에 의해 강제로 끊겼습니다

During handling of the above exception, another exception occurred:

Traceback (most recent call last):
  File "C:\Users\jaehy\anaconda3\Lib\site-packages\py4j\clientserver.py", line 503, in send_command
    self.socket.sendall(command.encode("utf-8"))
ConnectionResetError: [WinError 10054] 현재 연결은 원격 호스트에 의해 강제로 끊겼습니다

During handling of the above exception, another exception occurred:

Traceback (most recent call last):
  File "C:\Users\jaehy\anaconda3\Lib\site-packages\py4j\clientserver.py", line 503, in send_command
    self.socket.sendall(command.encode("utf-8"))
ConnectionResetError: [WinError 10054] 현재 연결은 원격 호스트에 의해 강제로 끊겼습니다

During handling of the above exception, another exception occurred:

Traceback (most recent call last):
  File "C:\Users\jaehy\anaconda3\Lib\site-packages\py4j\clientserver.py", line 503, in send_command
    self.socket.sendall(command.encode("utf-8"))
ConnectionResetError: [WinError 10054] 현재 연결은 원격 호스트에 의해 강제로 끊겼습니다

During handling of the above exception, another exception occurred:

Traceback (most recent call last):
  File "C:\Users\jaehy\anaconda3\Lib\site-packages\py4j\clientserver.py", line 503, in send_command
    self.socket.sendall(command.encode("utf-8"))
ConnectionResetError: [WinError 10054] 현재 연결은 원격 호스트에 의해 강제로 끊겼습니다

During handling of the above exception, another exception occurred:

Traceback (most recent call last):
  File "C:\Users\jaehy\anaconda3\Lib\site-packages\py4j\clientserver.py", line 503, in send_command
    self.socket.sendall(command.encode("utf-8"))
ConnectionResetError: [WinError 10054] 현재 연결은 원격 호스트에 의해 강제로 끊겼습니다

During handling of the above exception, another exception occurred:

Traceback (most recent call last):
  File "C:\Users\jaehy\anaconda3\Lib\site-packages\py4j\clientserver.py", line 503, in send_command
    self.socket.sendall(command.encode("utf-8"))
ConnectionResetError: [WinError 10054] 현재 연결은 원격 호스트에 의해 강제로 끊겼습니다

During handling of the above exception, another exception occurred:

Traceback (most recent call last):
  File "C:\Users\jaehy\anaconda3\Lib\site-packages\py4j\clientserver.py", line 503, in send_command
    self.socket.sendall(command.encode("utf-8"))
ConnectionResetError: [WinError 10054] 현재 연결은 원격 호스트에 의해 강제로 끊겼습니다

During handling of the above exception, another exception occurred:

Traceback (most recent call last):
  File "C:\Users\jaehy\anaconda3\Lib\site-packages\py4j\clientserver.py", line 503, in send_command
    self.socket.sendall(command.encode("utf-8"))
ConnectionResetError: [WinError 10054] 현재 연결은 원격 호스트에 의해 강제로 끊겼습니다

During handling of the above exception, another exception occurred:

Traceback (most recent call last):
  File "C:\Users\jaehy\anaconda3\Lib\site-packages\py4j\clientserver.py", line 503, in send_command
    self.socket.sendall(command.encode("utf-8"))
ConnectionResetError: [WinError 10054] 현재 연결은 원격 호스트에 의해 강제로 끊겼습니다

During handling of the above exception, another exception occurred:

Traceback (most recent call last):
  File "C:\Users\jaehy\anaconda3\Lib\site-packages\py4j\clientserver.py", line 503, in send_command
    self.socket.sendall(command.encode("utf-8"))
ConnectionResetError: [WinError 10054] 현재 연결은 원격 호스트에 의해 강제로 끊겼습니다

During handling of the above exception, another exception occurred:

Traceback (most recent call last):
  File "C:\Users\jaehy\anaconda3\Lib\site-packages\py4j\clientserver.py", line 503, in send_command
    self.socket.sendall(command.encode("utf-8"))
ConnectionResetError: [WinError 10054] 현재 연결은 원격 호스트에 의해 강제로 끊겼습니다

During handling of the above exception, another exception occurred:

Traceback (most recent call last):
  File "C:\Users\jaehy\anaconda3\Lib\site-packages\py4j\clientserver.py", line 503, in send_command
    self.socket.sendall(command.encode("utf-8"))
ConnectionResetError: [WinError 10054] 현재 연결은 원격 호스트에 의해 강제로 끊겼습니다

During handling of the above exception, another exception occurred:

Traceback (most recent call last):
  File "C:\Users\jaehy\anaconda3\Lib\site-packages\py4j\clientserver.py", line 503, in send_command
    self.socket.sendall(command.encode("utf-8"))
ConnectionResetError: [WinError 10054] 현재 연결은 원격 호스트에 의해 강제로 끊겼습니다

During handling of the above exception, another exception occurred:

Traceback (most recent call last):
  File "C:\Users\jaehy\anaconda3\Lib\site-packages\py4j\clientserver.py", line 503, in send_command
    self.socket.sendall(command.encode("utf-8"))
ConnectionResetError: [WinError 10054] 현재 연결은 원격 호스트에 의해 강제로 끊겼습니다

During handling of the above exception, another exception occurred:

Traceback (most recent call last):
  File "C:\Users\jaehy\anaconda3\Lib\site-packages\py4j\clientserver.py", line 503, in send_command
    self.socket.sendall(command.encode("utf-8"))
ConnectionResetError: [WinError 10054] 현재 연결은 원격 호스트에 의해 강제로 끊겼습니다

During handling of the above exception, another exception occurred:

Traceback (most recent call last):
  File "C:\Users\jaehy\anaconda3\Lib\site-packages\py4j\clientserver.py", line 503, in send_command
    self.socket.sendall(command.encode("utf-8"))
ConnectionResetError: [WinError 10054] 현재 연결은 원격 호스트에 의해 강제로 끊겼습니다

During handling of the above exception, another exception occurred:

Traceback (most recent call last):
  File "C:\Users\jaehy\anaconda3\Lib\site-packages\py4j\clientserver.py", line 503, in send_command
    self.socket.sendall(command.encode("utf-8"))
ConnectionResetError: [WinError 10054] 현재 연결은 원격 호스트에 의해 강제로 끊겼습니다

During handling of the above exception, another exception occurred:

Traceback (most recent call last):
  File "C:\Users\jaehy\anaconda3\Lib\site-packages\py4j\clientserver.py", line 503, in send_command
    self.socket.sendall(command.encode("utf-8"))
ConnectionResetError: [WinError 10054] 현재 연결은 원격 호스트에 의해 강제로 끊겼습니다

During handling of the above exception, another exception occurred:

Traceback (most recent call last):
  File "C:\Users\jaehy\anaconda3\Lib\site-packages\py4j\clientserver.py", line 503, in send_command
    self.socket.sendall(command.encode("utf-8"))
ConnectionResetError: [WinError 10054] 현재 연결은 원격 호스트에 의해 강제로 끊겼습니다

During handling of the above exception, another exception occurred:

Traceback (most recent call last):
  File "C:\Users\jaehy\anaconda3\Lib\site-packages\py4j\clientserver.py", line 503, in send_command
    self.socket.sendall(command.encode("utf-8"))
ConnectionResetError: [WinError 10054] 현재 연결은 원격 호스트에 의해 강제로 끊겼습니다

During handling of the above exception, another exception occurred:

Traceback (most recent call last):
  File "C:\Users\jaehy\anaconda3\Lib\site-packages\py4j\clientserver.py", line 503, in send_command
    self.socket.sendall(command.encode("utf-8"))
ConnectionResetError: [WinError 10054] 현재 연결은 원격 호스트에 의해 강제로 끊겼습니다

During handling of the above exception, another exception occurred:

Traceback (most recent call last):
  File "C:\Users\jaehy\anaconda3\Lib\site-packages\py4j\clientserver.py", line 503, in send_command
    self.socket.sendall(command.encode("utf-8"))
ConnectionResetError: [WinError 10054] 현재 연결은 원격 호스트에 의해 강제로 끊겼습니다

During handling of the above exception, another exception occurred:

Traceback (most recent call last):
  File "C:\Users\jaehy\anaconda3\Lib\site-packages\py4j\clientserver.py", line 503, in send_command
    self.socket.sendall(command.encode("utf-8"))
ConnectionResetError: [WinError 10054] 현재 연결은 원격 호스트에 의해 강제로 끊겼습니다

During handling of the above exception, another exception occurred:

Traceback (most recent call last):
  File "C:\Users\jaehy\anaconda3\Lib\site-packages\py4j\clientserver.py", line 503, in send_command
    self.socket.sendall(command.encode("utf-8"))
ConnectionResetError: [WinError 10054] 현재 연결은 원격 호스트에 의해 강제로 끊겼습니다

During handling of the above exception, another exception occurred:

Traceback (most recent call last):
  File "C:\Users\jaehy\anaconda3\Lib\site-packages\py4j\clientserver.py", line 503, in send_command
    self.socket.sendall(command.encode("utf-8"))
ConnectionResetError: [WinError 10054] 현재 연결은 원격 호스트에 의해 강제로 끊겼습니다

During handling of the above exception, another exception occurred:

Traceback (most recent call last):
  File "C:\Users\jaehy\anaconda3\Lib\site-packages\py4j\clientserver.py", line 503, in send_command
    self.socket.sendall(command.encode("utf-8"))
ConnectionResetError: [WinError 10054] 현재 연결은 원격 호스트에 의해 강제로 끊겼습니다

During handling of the above exception, another exception occurred:

Traceback (most recent call last):
  File "C:\Users\jaehy\anaconda3\Lib\site-packages\py4j\clientserver.py", line 503, in send_command
    self.socket.sendall(command.encode("utf-8"))
ConnectionResetError: [WinError 10054] 현재 연결은 원격 호스트에 의해 강제로 끊겼습니다

During handling of the above exception, another exception occurred:

Traceback (most recent call last):
  File "C:\Users\jaehy\anaconda3\Lib\site-packages\py4j\clientserver.py", line 503, in send_command
    self.socket.sendall(command.encode("utf-8"))
ConnectionResetError: [WinError 10054] 현재 연결은 원격 호스트에 의해 강제로 끊겼습니다

During handling of the above exception, another exception occurred:

Traceback (most recent call last):
  File "C:\Users\jaehy\anaconda3\Lib\site-packages\py4j\clientserver.py", line 503, in send_command
    self.socket.sendall(command.encode("utf-8"))
ConnectionResetError: [WinError 10054] 현재 연결은 원격 호스트에 의해 강제로 끊겼습니다

During handling of the above exception, another exception occurred:

Traceback (most recent call last):
  File "C:\Users\jaehy\anaconda3\Lib\site-packages\py4j\clientserver.py", line 503, in send_command
    self.socket.sendall(command.encode("utf-8"))
ConnectionResetError: [WinError 10054] 현재 연결은 원격 호스트에 의해 강제로 끊겼습니다

During handling of the above exception, another exception occurred:

Traceback (most recent call last):
  File "C:\Users\jaehy\anaconda3\Lib\site-packages\py4j\clientserver.py", line 503, in send_command
    self.socket.sendall(command.encode("utf-8"))
ConnectionResetError: [WinError 10054] 현재 연결은 원격 호스트에 의해 강제로 끊겼습니다

During handling of the above exception, another exception occurred:

Traceback (most recent call last):
  File "C:\Users\jaehy\anaconda3\Lib\site-packages\py4j\clientserver.py", line 503, in send_command
    self.socket.sendall(command.encode("utf-8"))
ConnectionResetError: [WinError 10054] 현재 연결은 원격 호스트에 의해 강제로 끊겼습니다
2025-06-19 21:09:59,300 [INFO] Closing down clientserver connection
2025-06-19 21:10:01,330 [INFO] Closing down clientserver connection
2025-06-19 21:10:01,330 [INFO] Closing down clientserver connection
2025-06-19 21:09:59,300 [INFO] Exception while sending command.
Traceback (most recent call last):
  File "C:\Users\jaehy\anaconda3\Lib\site-packages\pyspark\errors\exceptions\captured.py", line 179, in deco
    return f(*a, **kw)
           ^^^^^^^^^^^
  File "C:\Users\jaehy\anaconda3\Lib\site-packages\py4j\protocol.py", line 326, in get_return_value
    raise Py4JJavaError(
py4j.protocol.Py4JJavaError: <exception str() failed>

During handling of the above exception, another exception occurred:

Traceback (most recent call last):
  File "C:\Users\jaehy\anaconda3\Lib\site-packages\py4j\clientserver.py", line 511, in send_command
    answer = smart_decode(self.stream.readline()[:-1])
                          ^^^^^^^^^^^^^^^^^^^^^^
  File "C:\Users\jaehy\anaconda3\Lib\socket.py", line 706, in readinto
    return self._sock.recv_into(b)
           ^^^^^^^^^^^^^^^^^^^^^^^
ConnectionResetError: [WinError 10054] 현재 연결은 원격 호스트에 의해 강제로 끊겼습니다

During handling of the above exception, another exception occurred:

Traceback (most recent call last):
  File "C:\Users\jaehy\anaconda3\Lib\site-packages\py4j\clientserver.py", line 503, in send_command
    self.socket.sendall(command.encode("utf-8"))
ConnectionResetError: [WinError 10054] 현재 연결은 원격 호스트에 의해 강제로 끊겼습니다

During handling of the above exception, another exception occurred:

Traceback (most recent call last):
  File "C:\Users\jaehy\anaconda3\Lib\site-packages\py4j\clientserver.py", line 503, in send_command
    self.socket.sendall(command.encode("utf-8"))
ConnectionResetError: [WinError 10054] 현재 연결은 원격 호스트에 의해 강제로 끊겼습니다

During handling of the above exception, another exception occurred:

Traceback (most recent call last):
  File "C:\Users\jaehy\anaconda3\Lib\site-packages\py4j\clientserver.py", line 503, in send_command
    self.socket.sendall(command.encode("utf-8"))
ConnectionResetError: [WinError 10054] 현재 연결은 원격 호스트에 의해 강제로 끊겼습니다

During handling of the above exception, another exception occurred:

Traceback (most recent call last):
  File "C:\Users\jaehy\anaconda3\Lib\site-packages\py4j\clientserver.py", line 503, in send_command
    self.socket.sendall(command.encode("utf-8"))
ConnectionResetError: [WinError 10054] 현재 연결은 원격 호스트에 의해 강제로 끊겼습니다

During handling of the above exception, another exception occurred:

Traceback (most recent call last):
  File "C:\Users\jaehy\anaconda3\Lib\site-packages\py4j\clientserver.py", line 503, in send_command
    self.socket.sendall(command.encode("utf-8"))
ConnectionResetError: [WinError 10054] 현재 연결은 원격 호스트에 의해 강제로 끊겼습니다

During handling of the above exception, another exception occurred:

Traceback (most recent call last):
  File "C:\Users\jaehy\anaconda3\Lib\site-packages\py4j\clientserver.py", line 503, in send_command
    self.socket.sendall(command.encode("utf-8"))
ConnectionResetError: [WinError 10054] 현재 연결은 원격 호스트에 의해 강제로 끊겼습니다

During handling of the above exception, another exception occurred:

Traceback (most recent call last):
  File "C:\Users\jaehy\anaconda3\Lib\site-packages\py4j\clientserver.py", line 503, in send_command
    self.socket.sendall(command.encode("utf-8"))
ConnectionResetError: [WinError 10054] 현재 연결은 원격 호스트에 의해 강제로 끊겼습니다

During handling of the above exception, another exception occurred:

Traceback (most recent call last):
  File "C:\Users\jaehy\anaconda3\Lib\site-packages\py4j\clientserver.py", line 503, in send_command
    self.socket.sendall(command.encode("utf-8"))
ConnectionResetError: [WinError 10054] 현재 연결은 원격 호스트에 의해 강제로 끊겼습니다

During handling of the above exception, another exception occurred:

Traceback (most recent call last):
  File "C:\Users\jaehy\anaconda3\Lib\site-packages\py4j\clientserver.py", line 503, in send_command
    self.socket.sendall(command.encode("utf-8"))
ConnectionResetError: [WinError 10054] 현재 연결은 원격 호스트에 의해 강제로 끊겼습니다

During handling of the above exception, another exception occurred:

Traceback (most recent call last):
  File "C:\Users\jaehy\anaconda3\Lib\site-packages\py4j\clientserver.py", line 503, in send_command
    self.socket.sendall(command.encode("utf-8"))
ConnectionResetError: [WinError 10054] 현재 연결은 원격 호스트에 의해 강제로 끊겼습니다

During handling of the above exception, another exception occurred:

Traceback (most recent call last):
  File "C:\Users\jaehy\anaconda3\Lib\site-packages\py4j\clientserver.py", line 503, in send_command
    self.socket.sendall(command.encode("utf-8"))
ConnectionResetError: [WinError 10054] 현재 연결은 원격 호스트에 의해 강제로 끊겼습니다

During handling of the above exception, another exception occurred:

Traceback (most recent call last):
  File "C:\Users\jaehy\anaconda3\Lib\site-packages\py4j\clientserver.py", line 503, in send_command
    self.socket.sendall(command.encode("utf-8"))
ConnectionResetError: [WinError 10054] 현재 연결은 원격 호스트에 의해 강제로 끊겼습니다

During handling of the above exception, another exception occurred:

Traceback (most recent call last):
  File "C:\Users\jaehy\anaconda3\Lib\site-packages\py4j\clientserver.py", line 503, in send_command
    self.socket.sendall(command.encode("utf-8"))
ConnectionResetError: [WinError 10054] 현재 연결은 원격 호스트에 의해 강제로 끊겼습니다

During handling of the above exception, another exception occurred:

Traceback (most recent call last):
  File "C:\Users\jaehy\anaconda3\Lib\site-packages\py4j\clientserver.py", line 503, in send_command
    self.socket.sendall(command.encode("utf-8"))
ConnectionResetError: [WinError 10054] 현재 연결은 원격 호스트에 의해 강제로 끊겼습니다

During handling of the above exception, another exception occurred:

Traceback (most recent call last):
  File "C:\Users\jaehy\anaconda3\Lib\site-packages\py4j\clientserver.py", line 503, in send_command
    self.socket.sendall(command.encode("utf-8"))
ConnectionResetError: [WinError 10054] 현재 연결은 원격 호스트에 의해 강제로 끊겼습니다

During handling of the above exception, another exception occurred:

Traceback (most recent call last):
  File "C:\Users\jaehy\anaconda3\Lib\site-packages\py4j\clientserver.py", line 503, in send_command
    self.socket.sendall(command.encode("utf-8"))
ConnectionResetError: [WinError 10054] 현재 연결은 원격 호스트에 의해 강제로 끊겼습니다

During handling of the above exception, another exception occurred:

Traceback (most recent call last):
  File "C:\Users\jaehy\anaconda3\Lib\site-packages\py4j\clientserver.py", line 503, in send_command
    self.socket.sendall(command.encode("utf-8"))
ConnectionResetError: [WinError 10054] 현재 연결은 원격 호스트에 의해 강제로 끊겼습니다

During handling of the above exception, another exception occurred:

Traceback (most recent call last):
  File "C:\Users\jaehy\anaconda3\Lib\site-packages\py4j\clientserver.py", line 503, in send_command
    self.socket.sendall(command.encode("utf-8"))
ConnectionResetError: [WinError 10054] 현재 연결은 원격 호스트에 의해 강제로 끊겼습니다

During handling of the above exception, another exception occurred:

Traceback (most recent call last):
  File "C:\Users\jaehy\anaconda3\Lib\site-packages\py4j\clientserver.py", line 503, in send_command
    self.socket.sendall(command.encode("utf-8"))
ConnectionResetError: [WinError 10054] 현재 연결은 원격 호스트에 의해 강제로 끊겼습니다

During handling of the above exception, another exception occurred:

Traceback (most recent call last):
  File "C:\Users\jaehy\anaconda3\Lib\site-packages\py4j\clientserver.py", line 503, in send_command
    self.socket.sendall(command.encode("utf-8"))
ConnectionResetError: [WinError 10054] 현재 연결은 원격 호스트에 의해 강제로 끊겼습니다

During handling of the above exception, another exception occurred:

Traceback (most recent call last):
  File "C:\Users\jaehy\anaconda3\Lib\site-packages\py4j\clientserver.py", line 503, in send_command
    self.socket.sendall(command.encode("utf-8"))
ConnectionResetError: [WinError 10054] 현재 연결은 원격 호스트에 의해 강제로 끊겼습니다

During handling of the above exception, another exception occurred:

Traceback (most recent call last):
  File "C:\Users\jaehy\anaconda3\Lib\site-packages\py4j\clientserver.py", line 503, in send_command
    self.socket.sendall(command.encode("utf-8"))
ConnectionResetError: [WinError 10054] 현재 연결은 원격 호스트에 의해 강제로 끊겼습니다

During handling of the above exception, another exception occurred:

Traceback (most recent call last):
  File "C:\Users\jaehy\anaconda3\Lib\site-packages\py4j\clientserver.py", line 503, in send_command
    self.socket.sendall(command.encode("utf-8"))
ConnectionResetError: [WinError 10054] 현재 연결은 원격 호스트에 의해 강제로 끊겼습니다

During handling of the above exception, another exception occurred:

Traceback (most recent call last):
  File "C:\Users\jaehy\anaconda3\Lib\site-packages\py4j\clientserver.py", line 503, in send_command
    self.socket.sendall(command.encode("utf-8"))
ConnectionResetError: [WinError 10054] 현재 연결은 원격 호스트에 의해 강제로 끊겼습니다

During handling of the above exception, another exception occurred:

Traceback (most recent call last):
  File "C:\Users\jaehy\anaconda3\Lib\site-packages\py4j\clientserver.py", line 503, in send_command
    self.socket.sendall(command.encode("utf-8"))
ConnectionResetError: [WinError 10054] 현재 연결은 원격 호스트에 의해 강제로 끊겼습니다

During handling of the above exception, another exception occurred:

Traceback (most recent call last):
  File "C:\Users\jaehy\anaconda3\Lib\site-packages\py4j\clientserver.py", line 503, in send_command
    self.socket.sendall(command.encode("utf-8"))
ConnectionResetError: [WinError 10054] 현재 연결은 원격 호스트에 의해 강제로 끊겼습니다

During handling of the above exception, another exception occurred:

Traceback (most recent call last):
  File "C:\Users\jaehy\anaconda3\Lib\site-packages\py4j\clientserver.py", line 503, in send_command
    self.socket.sendall(command.encode("utf-8"))
ConnectionResetError: [WinError 10054] 현재 연결은 원격 호스트에 의해 강제로 끊겼습니다

During handling of the above exception, another exception occurred:

Traceback (most recent call last):
  File "C:\Users\jaehy\anaconda3\Lib\site-packages\py4j\clientserver.py", line 503, in send_command
    self.socket.sendall(command.encode("utf-8"))
ConnectionResetError: [WinError 10054] 현재 연결은 원격 호스트에 의해 강제로 끊겼습니다

During handling of the above exception, another exception occurred:

Traceback (most recent call last):
  File "C:\Users\jaehy\anaconda3\Lib\site-packages\py4j\clientserver.py", line 503, in send_command
    self.socket.sendall(command.encode("utf-8"))
ConnectionResetError: [WinError 10054] 현재 연결은 원격 호스트에 의해 강제로 끊겼습니다

During handling of the above exception, another exception occurred:

Traceback (most recent call last):
  File "C:\Users\jaehy\anaconda3\Lib\site-packages\py4j\clientserver.py", line 503, in send_command
    self.socket.sendall(command.encode("utf-8"))
ConnectionResetError: [WinError 10054] 현재 연결은 원격 호스트에 의해 강제로 끊겼습니다

During handling of the above exception, another exception occurred:

Traceback (most recent call last):
  File "C:\Users\jaehy\anaconda3\Lib\site-packages\py4j\clientserver.py", line 503, in send_command
    self.socket.sendall(command.encode("utf-8"))
ConnectionResetError: [WinError 10054] 현재 연결은 원격 호스트에 의해 강제로 끊겼습니다

During handling of the above exception, another exception occurred:

Traceback (most recent call last):
  File "C:\Users\jaehy\anaconda3\Lib\site-packages\py4j\clientserver.py", line 503, in send_command
    self.socket.sendall(command.encode("utf-8"))
ConnectionResetError: [WinError 10054] 현재 연결은 원격 호스트에 의해 강제로 끊겼습니다

During handling of the above exception, another exception occurred:

Traceback (most recent call last):
  File "C:\Users\jaehy\anaconda3\Lib\site-packages\py4j\clientserver.py", line 503, in send_command
    self.socket.sendall(command.encode("utf-8"))
ConnectionResetError: [WinError 10054] 현재 연결은 원격 호스트에 의해 강제로 끊겼습니다

During handling of the above exception, another exception occurred:

Traceback (most recent call last):
  File "C:\Users\jaehy\anaconda3\Lib\site-packages\py4j\clientserver.py", line 503, in send_command
    self.socket.sendall(command.encode("utf-8"))
ConnectionResetError: [WinError 10054] 현재 연결은 원격 호스트에 의해 강제로 끊겼습니다

During handling of the above exception, another exception occurred:

Traceback (most recent call last):
  File "C:\Users\jaehy\anaconda3\Lib\site-packages\py4j\clientserver.py", line 503, in send_command
    self.socket.sendall(command.encode("utf-8"))
ConnectionResetError: [WinError 10054] 현재 연결은 원격 호스트에 의해 강제로 끊겼습니다

During handling of the above exception, another exception occurred:

Traceback (most recent call last):
  File "C:\Users\jaehy\anaconda3\Lib\site-packages\py4j\clientserver.py", line 503, in send_command
    self.socket.sendall(command.encode("utf-8"))
ConnectionResetError: [WinError 10054] 현재 연결은 원격 호스트에 의해 강제로 끊겼습니다

During handling of the above exception, another exception occurred:

Traceback (most recent call last):
  File "C:\Users\jaehy\anaconda3\Lib\site-packages\py4j\clientserver.py", line 503, in send_command
    self.socket.sendall(command.encode("utf-8"))
ConnectionResetError: [WinError 10054] 현재 연결은 원격 호스트에 의해 강제로 끊겼습니다

During handling of the above exception, another exception occurred:

Traceback (most recent call last):
  File "C:\Users\jaehy\anaconda3\Lib\site-packages\py4j\clientserver.py", line 503, in send_command
    self.socket.sendall(command.encode("utf-8"))
ConnectionResetError: [WinError 10054] 현재 연결은 원격 호스트에 의해 강제로 끊겼습니다

During handling of the above exception, another exception occurred:

Traceback (most recent call last):
  File "C:\Users\jaehy\anaconda3\Lib\site-packages\py4j\clientserver.py", line 503, in send_command
    self.socket.sendall(command.encode("utf-8"))
ConnectionResetError: [WinError 10054] 현재 연결은 원격 호스트에 의해 강제로 끊겼습니다

During handling of the above exception, another exception occurred:

Traceback (most recent call last):
  File "C:\Users\jaehy\anaconda3\Lib\site-packages\py4j\clientserver.py", line 503, in send_command
    self.socket.sendall(command.encode("utf-8"))
ConnectionResetError: [WinError 10054] 현재 연결은 원격 호스트에 의해 강제로 끊겼습니다

During handling of the above exception, another exception occurred:

Traceback (most recent call last):
  File "C:\Users\jaehy\anaconda3\Lib\site-packages\py4j\clientserver.py", line 503, in send_command
    self.socket.sendall(command.encode("utf-8"))
ConnectionResetError: [WinError 10054] 현재 연결은 원격 호스트에 의해 강제로 끊겼습니다

During handling of the above exception, another exception occurred:

Traceback (most recent call last):
  File "C:\Users\jaehy\anaconda3\Lib\site-packages\py4j\clientserver.py", line 503, in send_command
    self.socket.sendall(command.encode("utf-8"))
ConnectionResetError: [WinError 10054] 현재 연결은 원격 호스트에 의해 강제로 끊겼습니다

During handling of the above exception, another exception occurred:

Traceback (most recent call last):
  File "C:\Users\jaehy\anaconda3\Lib\site-packages\py4j\clientserver.py", line 503, in send_command
    self.socket.sendall(command.encode("utf-8"))
ConnectionResetError: [WinError 10054] 현재 연결은 원격 호스트에 의해 강제로 끊겼습니다

During handling of the above exception, another exception occurred:

Traceback (most recent call last):
  File "C:\Users\jaehy\anaconda3\Lib\site-packages\py4j\clientserver.py", line 503, in send_command
    self.socket.sendall(command.encode("utf-8"))
ConnectionResetError: [WinError 10054] 현재 연결은 원격 호스트에 의해 강제로 끊겼습니다

During handling of the above exception, another exception occurred:

Traceback (most recent call last):
  File "C:\Users\jaehy\anaconda3\Lib\site-packages\py4j\clientserver.py", line 503, in send_command
    self.socket.sendall(command.encode("utf-8"))
ConnectionResetError: [WinError 10054] 현재 연결은 원격 호스트에 의해 강제로 끊겼습니다

During handling of the above exception, another exception occurred:

Traceback (most recent call last):
  File "C:\Users\jaehy\anaconda3\Lib\site-packages\py4j\clientserver.py", line 503, in send_command
    self.socket.sendall(command.encode("utf-8"))
ConnectionResetError: [WinError 10054] 현재 연결은 원격 호스트에 의해 강제로 끊겼습니다

During handling of the above exception, another exception occurred:

Traceback (most recent call last):
  File "C:\Users\jaehy\anaconda3\Lib\site-packages\py4j\clientserver.py", line 503, in send_command
    self.socket.sendall(command.encode("utf-8"))
ConnectionResetError: [WinError 10054] 현재 연결은 원격 호스트에 의해 강제로 끊겼습니다

During handling of the above exception, another exception occurred:

Traceback (most recent call last):
  File "C:\Users\jaehy\anaconda3\Lib\site-packages\py4j\java_gateway.py", line 1038, in send_command
    response = connection.send_command(command)
               ^^^^^^^^^^^^^^^^^^^^^^^^^^^^^^^^
  File "C:\Users\jaehy\anaconda3\Lib\site-packages\py4j\clientserver.py", line 506, in send_command
    raise Py4JNetworkError(
py4j.protocol.Py4JNetworkError: Error while sending
2025-06-19 21:10:16,093 [INFO] [31m[1mWARNING: This is a development server. Do not use it in a production deployment. Use a production WSGI server instead.[0m
 * Running on all addresses (0.0.0.0)
 * Running on http://127.0.0.1:5000
 * Running on http://192.168.0.7:5000
2025-06-19 21:10:16,093 [INFO] [33mPress CTRL+C to quit[0m
2025-06-19 21:10:18,110 [INFO] [요청] IP: 127.0.0.1, POST /realtime_search
2025-06-19 21:10:18,414 [ERROR] Exception on /realtime_search [POST]
Traceback (most recent call last):
  File "C:\Users\jaehy\anaconda3\Lib\site-packages\flask\app.py", line 2529, in wsgi_app
    response = self.full_dispatch_request()
               ^^^^^^^^^^^^^^^^^^^^^^^^^^^^
  File "C:\Users\jaehy\anaconda3\Lib\site-packages\flask\app.py", line 1825, in full_dispatch_request
    rv = self.handle_user_exception(e)
         ^^^^^^^^^^^^^^^^^^^^^^^^^^^^^
  File "C:\Users\jaehy\anaconda3\Lib\site-packages\flask_cors\extension.py", line 176, in wrapped_function
    return cors_after_request(app.make_response(f(*args, **kwargs)))
                                                ^^^^^^^^^^^^^^^^^^
  File "C:\Users\jaehy\anaconda3\Lib\site-packages\flask\app.py", line 1823, in full_dispatch_request
    rv = self.dispatch_request()
         ^^^^^^^^^^^^^^^^^^^^^^^
  File "C:\Users\jaehy\anaconda3\Lib\site-packages\flask\app.py", line 1799, in dispatch_request
    return self.ensure_sync(self.view_functions[rule.endpoint])(**view_args)
           ^^^^^^^^^^^^^^^^^^^^^^^^^^^^^^^^^^^^^^^^^^^^^^^^^^^^^^^^^^^^^^^^^
  File "c:\JaeHyeok\TickerNow\TickerNow-backend\main.py", line 343, in run_realtime_search
    re = spark.sql(query)
         ^^^^^^^^^^^^^^^^
  File "C:\Users\jaehy\anaconda3\Lib\site-packages\pyspark\sql\session.py", line 1631, in sql
    return DataFrame(self._jsparkSession.sql(sqlQuery, litArgs), self)
                     ^^^^^^^^^^^^^^^^^^^^^^^^^^^^^^^^^^^^^^^^^^
  File "C:\Users\jaehy\anaconda3\Lib\site-packages\py4j\java_gateway.py", line 1322, in __call__
    return_value = get_return_value(
                   ^^^^^^^^^^^^^^^^^
  File "C:\Users\jaehy\anaconda3\Lib\site-packages\pyspark\errors\exceptions\captured.py", line 185, in deco
    raise converted from None
pyspark.errors.exceptions.captured.ParseException: 
[PARSE_SYNTAX_ERROR] Syntax error at or near 'LIKE'.(line 4, pos 15)

== SQL ==

    select name
    from daum_financial_stock_table
    where name LIKE 삼성%
---------------^^^
    

2025-06-19 21:10:18,425 [INFO] 127.0.0.1 - - [19/Jun/2025 21:10:18] "[35m[1mPOST /realtime_search HTTP/1.1[0m" 500 -
2025-06-19 21:10:18,425 [INFO] Closing down clientserver connection
2025-06-19 21:10:57,620 [INFO] Error while sending or receiving.
Traceback (most recent call last):
  File "C:\Users\jaehy\anaconda3\Lib\site-packages\pyspark\errors\exceptions\captured.py", line 179, in deco
    return f(*a, **kw)
           ^^^^^^^^^^^
  File "C:\Users\jaehy\anaconda3\Lib\site-packages\py4j\protocol.py", line 326, in get_return_value
    raise Py4JJavaError(
py4j.protocol.Py4JJavaError: <exception str() failed>

During handling of the above exception, another exception occurred:

Traceback (most recent call last):
  File "C:\Users\jaehy\anaconda3\Lib\site-packages\py4j\clientserver.py", line 511, in send_command
    answer = smart_decode(self.stream.readline()[:-1])
                          ^^^^^^^^^^^^^^^^^^^^^^
  File "C:\Users\jaehy\anaconda3\Lib\socket.py", line 706, in readinto
    return self._sock.recv_into(b)
           ^^^^^^^^^^^^^^^^^^^^^^^
ConnectionResetError: [WinError 10054] 현재 연결은 원격 호스트에 의해 강제로 끊겼습니다

During handling of the above exception, another exception occurred:

Traceback (most recent call last):
  File "C:\Users\jaehy\anaconda3\Lib\site-packages\py4j\clientserver.py", line 503, in send_command
    self.socket.sendall(command.encode("utf-8"))
ConnectionResetError: [WinError 10054] 현재 연결은 원격 호스트에 의해 강제로 끊겼습니다

During handling of the above exception, another exception occurred:

Traceback (most recent call last):
  File "C:\Users\jaehy\anaconda3\Lib\site-packages\py4j\clientserver.py", line 503, in send_command
    self.socket.sendall(command.encode("utf-8"))
ConnectionResetError: [WinError 10054] 현재 연결은 원격 호스트에 의해 강제로 끊겼습니다

During handling of the above exception, another exception occurred:

Traceback (most recent call last):
  File "C:\Users\jaehy\anaconda3\Lib\site-packages\py4j\clientserver.py", line 503, in send_command
    self.socket.sendall(command.encode("utf-8"))
ConnectionResetError: [WinError 10054] 현재 연결은 원격 호스트에 의해 강제로 끊겼습니다

During handling of the above exception, another exception occurred:

Traceback (most recent call last):
  File "C:\Users\jaehy\anaconda3\Lib\site-packages\py4j\clientserver.py", line 503, in send_command
    self.socket.sendall(command.encode("utf-8"))
ConnectionResetError: [WinError 10054] 현재 연결은 원격 호스트에 의해 강제로 끊겼습니다

During handling of the above exception, another exception occurred:

Traceback (most recent call last):
  File "C:\Users\jaehy\anaconda3\Lib\site-packages\py4j\clientserver.py", line 503, in send_command
    self.socket.sendall(command.encode("utf-8"))
ConnectionResetError: [WinError 10054] 현재 연결은 원격 호스트에 의해 강제로 끊겼습니다

During handling of the above exception, another exception occurred:

Traceback (most recent call last):
  File "C:\Users\jaehy\anaconda3\Lib\site-packages\py4j\clientserver.py", line 503, in send_command
    self.socket.sendall(command.encode("utf-8"))
ConnectionResetError: [WinError 10054] 현재 연결은 원격 호스트에 의해 강제로 끊겼습니다

During handling of the above exception, another exception occurred:

Traceback (most recent call last):
  File "C:\Users\jaehy\anaconda3\Lib\site-packages\py4j\clientserver.py", line 503, in send_command
    self.socket.sendall(command.encode("utf-8"))
ConnectionResetError: [WinError 10054] 현재 연결은 원격 호스트에 의해 강제로 끊겼습니다

During handling of the above exception, another exception occurred:

Traceback (most recent call last):
  File "C:\Users\jaehy\anaconda3\Lib\site-packages\py4j\clientserver.py", line 503, in send_command
    self.socket.sendall(command.encode("utf-8"))
ConnectionResetError: [WinError 10054] 현재 연결은 원격 호스트에 의해 강제로 끊겼습니다

During handling of the above exception, another exception occurred:

Traceback (most recent call last):
  File "C:\Users\jaehy\anaconda3\Lib\site-packages\py4j\clientserver.py", line 503, in send_command
    self.socket.sendall(command.encode("utf-8"))
ConnectionResetError: [WinError 10054] 현재 연결은 원격 호스트에 의해 강제로 끊겼습니다

During handling of the above exception, another exception occurred:

Traceback (most recent call last):
  File "C:\Users\jaehy\anaconda3\Lib\site-packages\py4j\clientserver.py", line 503, in send_command
    self.socket.sendall(command.encode("utf-8"))
ConnectionResetError: [WinError 10054] 현재 연결은 원격 호스트에 의해 강제로 끊겼습니다

During handling of the above exception, another exception occurred:

Traceback (most recent call last):
  File "C:\Users\jaehy\anaconda3\Lib\site-packages\py4j\clientserver.py", line 503, in send_command
    self.socket.sendall(command.encode("utf-8"))
ConnectionResetError: [WinError 10054] 현재 연결은 원격 호스트에 의해 강제로 끊겼습니다

During handling of the above exception, another exception occurred:

Traceback (most recent call last):
  File "C:\Users\jaehy\anaconda3\Lib\site-packages\py4j\clientserver.py", line 503, in send_command
    self.socket.sendall(command.encode("utf-8"))
ConnectionResetError: [WinError 10054] 현재 연결은 원격 호스트에 의해 강제로 끊겼습니다

During handling of the above exception, another exception occurred:

Traceback (most recent call last):
  File "C:\Users\jaehy\anaconda3\Lib\site-packages\py4j\clientserver.py", line 503, in send_command
    self.socket.sendall(command.encode("utf-8"))
ConnectionResetError: [WinError 10054] 현재 연결은 원격 호스트에 의해 강제로 끊겼습니다

During handling of the above exception, another exception occurred:

Traceback (most recent call last):
  File "C:\Users\jaehy\anaconda3\Lib\site-packages\py4j\clientserver.py", line 503, in send_command
    self.socket.sendall(command.encode("utf-8"))
ConnectionResetError: [WinError 10054] 현재 연결은 원격 호스트에 의해 강제로 끊겼습니다

During handling of the above exception, another exception occurred:

Traceback (most recent call last):
  File "C:\Users\jaehy\anaconda3\Lib\site-packages\py4j\clientserver.py", line 503, in send_command
    self.socket.sendall(command.encode("utf-8"))
ConnectionResetError: [WinError 10054] 현재 연결은 원격 호스트에 의해 강제로 끊겼습니다

During handling of the above exception, another exception occurred:

Traceback (most recent call last):
  File "C:\Users\jaehy\anaconda3\Lib\site-packages\py4j\clientserver.py", line 503, in send_command
    self.socket.sendall(command.encode("utf-8"))
ConnectionResetError: [WinError 10054] 현재 연결은 원격 호스트에 의해 강제로 끊겼습니다

During handling of the above exception, another exception occurred:

Traceback (most recent call last):
  File "C:\Users\jaehy\anaconda3\Lib\site-packages\py4j\clientserver.py", line 503, in send_command
    self.socket.sendall(command.encode("utf-8"))
ConnectionResetError: [WinError 10054] 현재 연결은 원격 호스트에 의해 강제로 끊겼습니다

During handling of the above exception, another exception occurred:

Traceback (most recent call last):
  File "C:\Users\jaehy\anaconda3\Lib\site-packages\py4j\clientserver.py", line 503, in send_command
    self.socket.sendall(command.encode("utf-8"))
ConnectionResetError: [WinError 10054] 현재 연결은 원격 호스트에 의해 강제로 끊겼습니다

During handling of the above exception, another exception occurred:

Traceback (most recent call last):
  File "C:\Users\jaehy\anaconda3\Lib\site-packages\py4j\clientserver.py", line 503, in send_command
    self.socket.sendall(command.encode("utf-8"))
ConnectionResetError: [WinError 10054] 현재 연결은 원격 호스트에 의해 강제로 끊겼습니다

During handling of the above exception, another exception occurred:

Traceback (most recent call last):
  File "C:\Users\jaehy\anaconda3\Lib\site-packages\py4j\clientserver.py", line 503, in send_command
    self.socket.sendall(command.encode("utf-8"))
ConnectionResetError: [WinError 10054] 현재 연결은 원격 호스트에 의해 강제로 끊겼습니다

During handling of the above exception, another exception occurred:

Traceback (most recent call last):
  File "C:\Users\jaehy\anaconda3\Lib\site-packages\py4j\clientserver.py", line 503, in send_command
    self.socket.sendall(command.encode("utf-8"))
ConnectionResetError: [WinError 10054] 현재 연결은 원격 호스트에 의해 강제로 끊겼습니다

During handling of the above exception, another exception occurred:

Traceback (most recent call last):
  File "C:\Users\jaehy\anaconda3\Lib\site-packages\py4j\clientserver.py", line 503, in send_command
    self.socket.sendall(command.encode("utf-8"))
ConnectionResetError: [WinError 10054] 현재 연결은 원격 호스트에 의해 강제로 끊겼습니다

During handling of the above exception, another exception occurred:

Traceback (most recent call last):
  File "C:\Users\jaehy\anaconda3\Lib\site-packages\py4j\clientserver.py", line 503, in send_command
    self.socket.sendall(command.encode("utf-8"))
ConnectionResetError: [WinError 10054] 현재 연결은 원격 호스트에 의해 강제로 끊겼습니다

During handling of the above exception, another exception occurred:

Traceback (most recent call last):
  File "C:\Users\jaehy\anaconda3\Lib\site-packages\py4j\clientserver.py", line 503, in send_command
    self.socket.sendall(command.encode("utf-8"))
ConnectionResetError: [WinError 10054] 현재 연결은 원격 호스트에 의해 강제로 끊겼습니다

During handling of the above exception, another exception occurred:

Traceback (most recent call last):
  File "C:\Users\jaehy\anaconda3\Lib\site-packages\py4j\clientserver.py", line 503, in send_command
    self.socket.sendall(command.encode("utf-8"))
ConnectionResetError: [WinError 10054] 현재 연결은 원격 호스트에 의해 강제로 끊겼습니다

During handling of the above exception, another exception occurred:

Traceback (most recent call last):
  File "C:\Users\jaehy\anaconda3\Lib\site-packages\py4j\clientserver.py", line 503, in send_command
    self.socket.sendall(command.encode("utf-8"))
ConnectionResetError: [WinError 10054] 현재 연결은 원격 호스트에 의해 강제로 끊겼습니다

During handling of the above exception, another exception occurred:

Traceback (most recent call last):
  File "C:\Users\jaehy\anaconda3\Lib\site-packages\py4j\clientserver.py", line 503, in send_command
    self.socket.sendall(command.encode("utf-8"))
ConnectionResetError: [WinError 10054] 현재 연결은 원격 호스트에 의해 강제로 끊겼습니다

During handling of the above exception, another exception occurred:

Traceback (most recent call last):
  File "C:\Users\jaehy\anaconda3\Lib\site-packages\py4j\clientserver.py", line 503, in send_command
    self.socket.sendall(command.encode("utf-8"))
ConnectionResetError: [WinError 10054] 현재 연결은 원격 호스트에 의해 강제로 끊겼습니다

During handling of the above exception, another exception occurred:

Traceback (most recent call last):
  File "C:\Users\jaehy\anaconda3\Lib\site-packages\py4j\clientserver.py", line 503, in send_command
    self.socket.sendall(command.encode("utf-8"))
ConnectionResetError: [WinError 10054] 현재 연결은 원격 호스트에 의해 강제로 끊겼습니다

During handling of the above exception, another exception occurred:

Traceback (most recent call last):
  File "C:\Users\jaehy\anaconda3\Lib\site-packages\py4j\clientserver.py", line 503, in send_command
    self.socket.sendall(command.encode("utf-8"))
ConnectionResetError: [WinError 10054] 현재 연결은 원격 호스트에 의해 강제로 끊겼습니다

During handling of the above exception, another exception occurred:

Traceback (most recent call last):
  File "C:\Users\jaehy\anaconda3\Lib\site-packages\py4j\clientserver.py", line 503, in send_command
    self.socket.sendall(command.encode("utf-8"))
ConnectionResetError: [WinError 10054] 현재 연결은 원격 호스트에 의해 강제로 끊겼습니다

During handling of the above exception, another exception occurred:

Traceback (most recent call last):
  File "C:\Users\jaehy\anaconda3\Lib\site-packages\py4j\clientserver.py", line 503, in send_command
    self.socket.sendall(command.encode("utf-8"))
ConnectionResetError: [WinError 10054] 현재 연결은 원격 호스트에 의해 강제로 끊겼습니다

During handling of the above exception, another exception occurred:

Traceback (most recent call last):
  File "C:\Users\jaehy\anaconda3\Lib\site-packages\py4j\clientserver.py", line 503, in send_command
    self.socket.sendall(command.encode("utf-8"))
ConnectionResetError: [WinError 10054] 현재 연결은 원격 호스트에 의해 강제로 끊겼습니다

During handling of the above exception, another exception occurred:

Traceback (most recent call last):
  File "C:\Users\jaehy\anaconda3\Lib\site-packages\py4j\clientserver.py", line 503, in send_command
    self.socket.sendall(command.encode("utf-8"))
ConnectionResetError: [WinError 10054] 현재 연결은 원격 호스트에 의해 강제로 끊겼습니다

During handling of the above exception, another exception occurred:

Traceback (most recent call last):
  File "C:\Users\jaehy\anaconda3\Lib\site-packages\py4j\clientserver.py", line 503, in send_command
    self.socket.sendall(command.encode("utf-8"))
ConnectionResetError: [WinError 10054] 현재 연결은 원격 호스트에 의해 강제로 끊겼습니다

During handling of the above exception, another exception occurred:

Traceback (most recent call last):
  File "C:\Users\jaehy\anaconda3\Lib\site-packages\py4j\clientserver.py", line 503, in send_command
    self.socket.sendall(command.encode("utf-8"))
ConnectionResetError: [WinError 10054] 현재 연결은 원격 호스트에 의해 강제로 끊겼습니다

During handling of the above exception, another exception occurred:

Traceback (most recent call last):
  File "C:\Users\jaehy\anaconda3\Lib\site-packages\py4j\clientserver.py", line 503, in send_command
    self.socket.sendall(command.encode("utf-8"))
ConnectionResetError: [WinError 10054] 현재 연결은 원격 호스트에 의해 강제로 끊겼습니다

During handling of the above exception, another exception occurred:

Traceback (most recent call last):
  File "C:\Users\jaehy\anaconda3\Lib\site-packages\py4j\clientserver.py", line 503, in send_command
    self.socket.sendall(command.encode("utf-8"))
ConnectionResetError: [WinError 10054] 현재 연결은 원격 호스트에 의해 강제로 끊겼습니다

During handling of the above exception, another exception occurred:

Traceback (most recent call last):
  File "C:\Users\jaehy\anaconda3\Lib\site-packages\py4j\clientserver.py", line 503, in send_command
    self.socket.sendall(command.encode("utf-8"))
ConnectionResetError: [WinError 10054] 현재 연결은 원격 호스트에 의해 강제로 끊겼습니다

During handling of the above exception, another exception occurred:

Traceback (most recent call last):
  File "C:\Users\jaehy\anaconda3\Lib\site-packages\py4j\clientserver.py", line 503, in send_command
    self.socket.sendall(command.encode("utf-8"))
ConnectionResetError: [WinError 10054] 현재 연결은 원격 호스트에 의해 강제로 끊겼습니다

During handling of the above exception, another exception occurred:

Traceback (most recent call last):
  File "C:\Users\jaehy\anaconda3\Lib\site-packages\py4j\clientserver.py", line 503, in send_command
    self.socket.sendall(command.encode("utf-8"))
ConnectionResetError: [WinError 10054] 현재 연결은 원격 호스트에 의해 강제로 끊겼습니다

During handling of the above exception, another exception occurred:

Traceback (most recent call last):
  File "C:\Users\jaehy\anaconda3\Lib\site-packages\py4j\clientserver.py", line 503, in send_command
    self.socket.sendall(command.encode("utf-8"))
ConnectionResetError: [WinError 10054] 현재 연결은 원격 호스트에 의해 강제로 끊겼습니다

During handling of the above exception, another exception occurred:

Traceback (most recent call last):
  File "C:\Users\jaehy\anaconda3\Lib\site-packages\py4j\clientserver.py", line 503, in send_command
    self.socket.sendall(command.encode("utf-8"))
ConnectionResetError: [WinError 10054] 현재 연결은 원격 호스트에 의해 강제로 끊겼습니다

During handling of the above exception, another exception occurred:

Traceback (most recent call last):
  File "C:\Users\jaehy\anaconda3\Lib\site-packages\py4j\clientserver.py", line 503, in send_command
    self.socket.sendall(command.encode("utf-8"))
ConnectionResetError: [WinError 10054] 현재 연결은 원격 호스트에 의해 강제로 끊겼습니다

During handling of the above exception, another exception occurred:

Traceback (most recent call last):
  File "C:\Users\jaehy\anaconda3\Lib\site-packages\py4j\clientserver.py", line 503, in send_command
    self.socket.sendall(command.encode("utf-8"))
ConnectionResetError: [WinError 10054] 현재 연결은 원격 호스트에 의해 강제로 끊겼습니다

During handling of the above exception, another exception occurred:

Traceback (most recent call last):
  File "C:\Users\jaehy\anaconda3\Lib\site-packages\py4j\clientserver.py", line 503, in send_command
    self.socket.sendall(command.encode("utf-8"))
ConnectionResetError: [WinError 10054] 현재 연결은 원격 호스트에 의해 강제로 끊겼습니다

During handling of the above exception, another exception occurred:

Traceback (most recent call last):
  File "C:\Users\jaehy\anaconda3\Lib\site-packages\py4j\clientserver.py", line 503, in send_command
    self.socket.sendall(command.encode("utf-8"))
ConnectionResetError: [WinError 10054] 현재 연결은 원격 호스트에 의해 강제로 끊겼습니다

During handling of the above exception, another exception occurred:

Traceback (most recent call last):
  File "C:\Users\jaehy\anaconda3\Lib\site-packages\py4j\clientserver.py", line 503, in send_command
    self.socket.sendall(command.encode("utf-8"))
ConnectionResetError: [WinError 10054] 현재 연결은 원격 호스트에 의해 강제로 끊겼습니다
2025-06-19 21:10:57,627 [INFO] Closing down clientserver connection
2025-06-19 21:10:57,627 [INFO] Exception while sending command.
Traceback (most recent call last):
  File "C:\Users\jaehy\anaconda3\Lib\site-packages\pyspark\errors\exceptions\captured.py", line 179, in deco
    return f(*a, **kw)
           ^^^^^^^^^^^
  File "C:\Users\jaehy\anaconda3\Lib\site-packages\py4j\protocol.py", line 326, in get_return_value
    raise Py4JJavaError(
py4j.protocol.Py4JJavaError: <exception str() failed>

During handling of the above exception, another exception occurred:

Traceback (most recent call last):
  File "C:\Users\jaehy\anaconda3\Lib\site-packages\py4j\clientserver.py", line 511, in send_command
    answer = smart_decode(self.stream.readline()[:-1])
                          ^^^^^^^^^^^^^^^^^^^^^^
  File "C:\Users\jaehy\anaconda3\Lib\socket.py", line 706, in readinto
    return self._sock.recv_into(b)
           ^^^^^^^^^^^^^^^^^^^^^^^
ConnectionResetError: [WinError 10054] 현재 연결은 원격 호스트에 의해 강제로 끊겼습니다

During handling of the above exception, another exception occurred:

Traceback (most recent call last):
  File "C:\Users\jaehy\anaconda3\Lib\site-packages\py4j\clientserver.py", line 503, in send_command
    self.socket.sendall(command.encode("utf-8"))
ConnectionResetError: [WinError 10054] 현재 연결은 원격 호스트에 의해 강제로 끊겼습니다

During handling of the above exception, another exception occurred:

Traceback (most recent call last):
  File "C:\Users\jaehy\anaconda3\Lib\site-packages\py4j\clientserver.py", line 503, in send_command
    self.socket.sendall(command.encode("utf-8"))
ConnectionResetError: [WinError 10054] 현재 연결은 원격 호스트에 의해 강제로 끊겼습니다

During handling of the above exception, another exception occurred:

Traceback (most recent call last):
  File "C:\Users\jaehy\anaconda3\Lib\site-packages\py4j\clientserver.py", line 503, in send_command
    self.socket.sendall(command.encode("utf-8"))
ConnectionResetError: [WinError 10054] 현재 연결은 원격 호스트에 의해 강제로 끊겼습니다

During handling of the above exception, another exception occurred:

Traceback (most recent call last):
  File "C:\Users\jaehy\anaconda3\Lib\site-packages\py4j\clientserver.py", line 503, in send_command
    self.socket.sendall(command.encode("utf-8"))
ConnectionResetError: [WinError 10054] 현재 연결은 원격 호스트에 의해 강제로 끊겼습니다

During handling of the above exception, another exception occurred:

Traceback (most recent call last):
  File "C:\Users\jaehy\anaconda3\Lib\site-packages\py4j\clientserver.py", line 503, in send_command
    self.socket.sendall(command.encode("utf-8"))
ConnectionResetError: [WinError 10054] 현재 연결은 원격 호스트에 의해 강제로 끊겼습니다

During handling of the above exception, another exception occurred:

Traceback (most recent call last):
  File "C:\Users\jaehy\anaconda3\Lib\site-packages\py4j\clientserver.py", line 503, in send_command
    self.socket.sendall(command.encode("utf-8"))
ConnectionResetError: [WinError 10054] 현재 연결은 원격 호스트에 의해 강제로 끊겼습니다

During handling of the above exception, another exception occurred:

Traceback (most recent call last):
  File "C:\Users\jaehy\anaconda3\Lib\site-packages\py4j\clientserver.py", line 503, in send_command
    self.socket.sendall(command.encode("utf-8"))
ConnectionResetError: [WinError 10054] 현재 연결은 원격 호스트에 의해 강제로 끊겼습니다

During handling of the above exception, another exception occurred:

Traceback (most recent call last):
  File "C:\Users\jaehy\anaconda3\Lib\site-packages\py4j\clientserver.py", line 503, in send_command
    self.socket.sendall(command.encode("utf-8"))
ConnectionResetError: [WinError 10054] 현재 연결은 원격 호스트에 의해 강제로 끊겼습니다

During handling of the above exception, another exception occurred:

Traceback (most recent call last):
  File "C:\Users\jaehy\anaconda3\Lib\site-packages\py4j\clientserver.py", line 503, in send_command
    self.socket.sendall(command.encode("utf-8"))
ConnectionResetError: [WinError 10054] 현재 연결은 원격 호스트에 의해 강제로 끊겼습니다

During handling of the above exception, another exception occurred:

Traceback (most recent call last):
  File "C:\Users\jaehy\anaconda3\Lib\site-packages\py4j\clientserver.py", line 503, in send_command
    self.socket.sendall(command.encode("utf-8"))
ConnectionResetError: [WinError 10054] 현재 연결은 원격 호스트에 의해 강제로 끊겼습니다

During handling of the above exception, another exception occurred:

Traceback (most recent call last):
  File "C:\Users\jaehy\anaconda3\Lib\site-packages\py4j\clientserver.py", line 503, in send_command
    self.socket.sendall(command.encode("utf-8"))
ConnectionResetError: [WinError 10054] 현재 연결은 원격 호스트에 의해 강제로 끊겼습니다

During handling of the above exception, another exception occurred:

Traceback (most recent call last):
  File "C:\Users\jaehy\anaconda3\Lib\site-packages\py4j\clientserver.py", line 503, in send_command
    self.socket.sendall(command.encode("utf-8"))
ConnectionResetError: [WinError 10054] 현재 연결은 원격 호스트에 의해 강제로 끊겼습니다

During handling of the above exception, another exception occurred:

Traceback (most recent call last):
  File "C:\Users\jaehy\anaconda3\Lib\site-packages\py4j\clientserver.py", line 503, in send_command
    self.socket.sendall(command.encode("utf-8"))
ConnectionResetError: [WinError 10054] 현재 연결은 원격 호스트에 의해 강제로 끊겼습니다

During handling of the above exception, another exception occurred:

Traceback (most recent call last):
  File "C:\Users\jaehy\anaconda3\Lib\site-packages\py4j\clientserver.py", line 503, in send_command
    self.socket.sendall(command.encode("utf-8"))
ConnectionResetError: [WinError 10054] 현재 연결은 원격 호스트에 의해 강제로 끊겼습니다

During handling of the above exception, another exception occurred:

Traceback (most recent call last):
  File "C:\Users\jaehy\anaconda3\Lib\site-packages\py4j\clientserver.py", line 503, in send_command
    self.socket.sendall(command.encode("utf-8"))
ConnectionResetError: [WinError 10054] 현재 연결은 원격 호스트에 의해 강제로 끊겼습니다

During handling of the above exception, another exception occurred:

Traceback (most recent call last):
  File "C:\Users\jaehy\anaconda3\Lib\site-packages\py4j\clientserver.py", line 503, in send_command
    self.socket.sendall(command.encode("utf-8"))
ConnectionResetError: [WinError 10054] 현재 연결은 원격 호스트에 의해 강제로 끊겼습니다

During handling of the above exception, another exception occurred:

Traceback (most recent call last):
  File "C:\Users\jaehy\anaconda3\Lib\site-packages\py4j\clientserver.py", line 503, in send_command
    self.socket.sendall(command.encode("utf-8"))
ConnectionResetError: [WinError 10054] 현재 연결은 원격 호스트에 의해 강제로 끊겼습니다

During handling of the above exception, another exception occurred:

Traceback (most recent call last):
  File "C:\Users\jaehy\anaconda3\Lib\site-packages\py4j\clientserver.py", line 503, in send_command
    self.socket.sendall(command.encode("utf-8"))
ConnectionResetError: [WinError 10054] 현재 연결은 원격 호스트에 의해 강제로 끊겼습니다

During handling of the above exception, another exception occurred:

Traceback (most recent call last):
  File "C:\Users\jaehy\anaconda3\Lib\site-packages\py4j\clientserver.py", line 503, in send_command
    self.socket.sendall(command.encode("utf-8"))
ConnectionResetError: [WinError 10054] 현재 연결은 원격 호스트에 의해 강제로 끊겼습니다

During handling of the above exception, another exception occurred:

Traceback (most recent call last):
  File "C:\Users\jaehy\anaconda3\Lib\site-packages\py4j\clientserver.py", line 503, in send_command
    self.socket.sendall(command.encode("utf-8"))
ConnectionResetError: [WinError 10054] 현재 연결은 원격 호스트에 의해 강제로 끊겼습니다

During handling of the above exception, another exception occurred:

Traceback (most recent call last):
  File "C:\Users\jaehy\anaconda3\Lib\site-packages\py4j\clientserver.py", line 503, in send_command
    self.socket.sendall(command.encode("utf-8"))
ConnectionResetError: [WinError 10054] 현재 연결은 원격 호스트에 의해 강제로 끊겼습니다

During handling of the above exception, another exception occurred:

Traceback (most recent call last):
  File "C:\Users\jaehy\anaconda3\Lib\site-packages\py4j\clientserver.py", line 503, in send_command
    self.socket.sendall(command.encode("utf-8"))
ConnectionResetError: [WinError 10054] 현재 연결은 원격 호스트에 의해 강제로 끊겼습니다

During handling of the above exception, another exception occurred:

Traceback (most recent call last):
  File "C:\Users\jaehy\anaconda3\Lib\site-packages\py4j\clientserver.py", line 503, in send_command
    self.socket.sendall(command.encode("utf-8"))
ConnectionResetError: [WinError 10054] 현재 연결은 원격 호스트에 의해 강제로 끊겼습니다

During handling of the above exception, another exception occurred:

Traceback (most recent call last):
  File "C:\Users\jaehy\anaconda3\Lib\site-packages\py4j\clientserver.py", line 503, in send_command
    self.socket.sendall(command.encode("utf-8"))
ConnectionResetError: [WinError 10054] 현재 연결은 원격 호스트에 의해 강제로 끊겼습니다

During handling of the above exception, another exception occurred:

Traceback (most recent call last):
  File "C:\Users\jaehy\anaconda3\Lib\site-packages\py4j\clientserver.py", line 503, in send_command
    self.socket.sendall(command.encode("utf-8"))
ConnectionResetError: [WinError 10054] 현재 연결은 원격 호스트에 의해 강제로 끊겼습니다

During handling of the above exception, another exception occurred:

Traceback (most recent call last):
  File "C:\Users\jaehy\anaconda3\Lib\site-packages\py4j\clientserver.py", line 503, in send_command
    self.socket.sendall(command.encode("utf-8"))
ConnectionResetError: [WinError 10054] 현재 연결은 원격 호스트에 의해 강제로 끊겼습니다

During handling of the above exception, another exception occurred:

Traceback (most recent call last):
  File "C:\Users\jaehy\anaconda3\Lib\site-packages\py4j\clientserver.py", line 503, in send_command
    self.socket.sendall(command.encode("utf-8"))
ConnectionResetError: [WinError 10054] 현재 연결은 원격 호스트에 의해 강제로 끊겼습니다

During handling of the above exception, another exception occurred:

Traceback (most recent call last):
  File "C:\Users\jaehy\anaconda3\Lib\site-packages\py4j\clientserver.py", line 503, in send_command
    self.socket.sendall(command.encode("utf-8"))
ConnectionResetError: [WinError 10054] 현재 연결은 원격 호스트에 의해 강제로 끊겼습니다

During handling of the above exception, another exception occurred:

Traceback (most recent call last):
  File "C:\Users\jaehy\anaconda3\Lib\site-packages\py4j\clientserver.py", line 503, in send_command
    self.socket.sendall(command.encode("utf-8"))
ConnectionResetError: [WinError 10054] 현재 연결은 원격 호스트에 의해 강제로 끊겼습니다

During handling of the above exception, another exception occurred:

Traceback (most recent call last):
  File "C:\Users\jaehy\anaconda3\Lib\site-packages\py4j\clientserver.py", line 503, in send_command
    self.socket.sendall(command.encode("utf-8"))
ConnectionResetError: [WinError 10054] 현재 연결은 원격 호스트에 의해 강제로 끊겼습니다

During handling of the above exception, another exception occurred:

Traceback (most recent call last):
  File "C:\Users\jaehy\anaconda3\Lib\site-packages\py4j\clientserver.py", line 503, in send_command
    self.socket.sendall(command.encode("utf-8"))
ConnectionResetError: [WinError 10054] 현재 연결은 원격 호스트에 의해 강제로 끊겼습니다

During handling of the above exception, another exception occurred:

Traceback (most recent call last):
  File "C:\Users\jaehy\anaconda3\Lib\site-packages\py4j\clientserver.py", line 503, in send_command
    self.socket.sendall(command.encode("utf-8"))
ConnectionResetError: [WinError 10054] 현재 연결은 원격 호스트에 의해 강제로 끊겼습니다

During handling of the above exception, another exception occurred:

Traceback (most recent call last):
  File "C:\Users\jaehy\anaconda3\Lib\site-packages\py4j\clientserver.py", line 503, in send_command
    self.socket.sendall(command.encode("utf-8"))
ConnectionResetError: [WinError 10054] 현재 연결은 원격 호스트에 의해 강제로 끊겼습니다

During handling of the above exception, another exception occurred:

Traceback (most recent call last):
  File "C:\Users\jaehy\anaconda3\Lib\site-packages\py4j\clientserver.py", line 503, in send_command
    self.socket.sendall(command.encode("utf-8"))
ConnectionResetError: [WinError 10054] 현재 연결은 원격 호스트에 의해 강제로 끊겼습니다

During handling of the above exception, another exception occurred:

Traceback (most recent call last):
  File "C:\Users\jaehy\anaconda3\Lib\site-packages\py4j\clientserver.py", line 503, in send_command
    self.socket.sendall(command.encode("utf-8"))
ConnectionResetError: [WinError 10054] 현재 연결은 원격 호스트에 의해 강제로 끊겼습니다

During handling of the above exception, another exception occurred:

Traceback (most recent call last):
  File "C:\Users\jaehy\anaconda3\Lib\site-packages\py4j\clientserver.py", line 503, in send_command
    self.socket.sendall(command.encode("utf-8"))
ConnectionResetError: [WinError 10054] 현재 연결은 원격 호스트에 의해 강제로 끊겼습니다

During handling of the above exception, another exception occurred:

Traceback (most recent call last):
  File "C:\Users\jaehy\anaconda3\Lib\site-packages\py4j\clientserver.py", line 503, in send_command
    self.socket.sendall(command.encode("utf-8"))
ConnectionResetError: [WinError 10054] 현재 연결은 원격 호스트에 의해 강제로 끊겼습니다

During handling of the above exception, another exception occurred:

Traceback (most recent call last):
  File "C:\Users\jaehy\anaconda3\Lib\site-packages\py4j\clientserver.py", line 503, in send_command
    self.socket.sendall(command.encode("utf-8"))
ConnectionResetError: [WinError 10054] 현재 연결은 원격 호스트에 의해 강제로 끊겼습니다

During handling of the above exception, another exception occurred:

Traceback (most recent call last):
  File "C:\Users\jaehy\anaconda3\Lib\site-packages\py4j\clientserver.py", line 503, in send_command
    self.socket.sendall(command.encode("utf-8"))
ConnectionResetError: [WinError 10054] 현재 연결은 원격 호스트에 의해 강제로 끊겼습니다

During handling of the above exception, another exception occurred:

Traceback (most recent call last):
  File "C:\Users\jaehy\anaconda3\Lib\site-packages\py4j\clientserver.py", line 503, in send_command
    self.socket.sendall(command.encode("utf-8"))
ConnectionResetError: [WinError 10054] 현재 연결은 원격 호스트에 의해 강제로 끊겼습니다

During handling of the above exception, another exception occurred:

Traceback (most recent call last):
  File "C:\Users\jaehy\anaconda3\Lib\site-packages\py4j\clientserver.py", line 503, in send_command
    self.socket.sendall(command.encode("utf-8"))
ConnectionResetError: [WinError 10054] 현재 연결은 원격 호스트에 의해 강제로 끊겼습니다

During handling of the above exception, another exception occurred:

Traceback (most recent call last):
  File "C:\Users\jaehy\anaconda3\Lib\site-packages\py4j\clientserver.py", line 503, in send_command
    self.socket.sendall(command.encode("utf-8"))
ConnectionResetError: [WinError 10054] 현재 연결은 원격 호스트에 의해 강제로 끊겼습니다

During handling of the above exception, another exception occurred:

Traceback (most recent call last):
  File "C:\Users\jaehy\anaconda3\Lib\site-packages\py4j\clientserver.py", line 503, in send_command
    self.socket.sendall(command.encode("utf-8"))
ConnectionResetError: [WinError 10054] 현재 연결은 원격 호스트에 의해 강제로 끊겼습니다

During handling of the above exception, another exception occurred:

Traceback (most recent call last):
  File "C:\Users\jaehy\anaconda3\Lib\site-packages\py4j\clientserver.py", line 503, in send_command
    self.socket.sendall(command.encode("utf-8"))
ConnectionResetError: [WinError 10054] 현재 연결은 원격 호스트에 의해 강제로 끊겼습니다

During handling of the above exception, another exception occurred:

Traceback (most recent call last):
  File "C:\Users\jaehy\anaconda3\Lib\site-packages\py4j\clientserver.py", line 503, in send_command
    self.socket.sendall(command.encode("utf-8"))
ConnectionResetError: [WinError 10054] 현재 연결은 원격 호스트에 의해 강제로 끊겼습니다

During handling of the above exception, another exception occurred:

Traceback (most recent call last):
  File "C:\Users\jaehy\anaconda3\Lib\site-packages\py4j\clientserver.py", line 503, in send_command
    self.socket.sendall(command.encode("utf-8"))
ConnectionResetError: [WinError 10054] 현재 연결은 원격 호스트에 의해 강제로 끊겼습니다

During handling of the above exception, another exception occurred:

Traceback (most recent call last):
  File "C:\Users\jaehy\anaconda3\Lib\site-packages\py4j\clientserver.py", line 503, in send_command
    self.socket.sendall(command.encode("utf-8"))
ConnectionResetError: [WinError 10054] 현재 연결은 원격 호스트에 의해 강제로 끊겼습니다

During handling of the above exception, another exception occurred:

Traceback (most recent call last):
  File "C:\Users\jaehy\anaconda3\Lib\site-packages\py4j\clientserver.py", line 503, in send_command
    self.socket.sendall(command.encode("utf-8"))
ConnectionResetError: [WinError 10054] 현재 연결은 원격 호스트에 의해 강제로 끊겼습니다

During handling of the above exception, another exception occurred:

Traceback (most recent call last):
  File "C:\Users\jaehy\anaconda3\Lib\site-packages\py4j\java_gateway.py", line 1038, in send_command
    response = connection.send_command(command)
               ^^^^^^^^^^^^^^^^^^^^^^^^^^^^^^^^
  File "C:\Users\jaehy\anaconda3\Lib\site-packages\py4j\clientserver.py", line 506, in send_command
    raise Py4JNetworkError(
py4j.protocol.Py4JNetworkError: Error while sending
2025-06-19 21:10:59,668 [INFO] Closing down clientserver connection
2025-06-19 21:10:59,668 [INFO] Closing down clientserver connection
2025-06-19 21:10:57,617 [INFO] Error while sending or receiving.
Traceback (most recent call last):
  File "C:\Users\jaehy\anaconda3\Lib\site-packages\pyspark\errors\exceptions\captured.py", line 179, in deco
    return f(*a, **kw)
           ^^^^^^^^^^^
  File "C:\Users\jaehy\anaconda3\Lib\site-packages\py4j\protocol.py", line 326, in get_return_value
    raise Py4JJavaError(
py4j.protocol.Py4JJavaError: <exception str() failed>

During handling of the above exception, another exception occurred:

Traceback (most recent call last):
  File "C:\Users\jaehy\anaconda3\Lib\site-packages\py4j\clientserver.py", line 511, in send_command
    answer = smart_decode(self.stream.readline()[:-1])
                          ^^^^^^^^^^^^^^^^^^^^^^
  File "C:\Users\jaehy\anaconda3\Lib\socket.py", line 706, in readinto
    return self._sock.recv_into(b)
           ^^^^^^^^^^^^^^^^^^^^^^^
ConnectionResetError: [WinError 10054] 현재 연결은 원격 호스트에 의해 강제로 끊겼습니다

During handling of the above exception, another exception occurred:

Traceback (most recent call last):
  File "C:\Users\jaehy\anaconda3\Lib\site-packages\py4j\clientserver.py", line 503, in send_command
    self.socket.sendall(command.encode("utf-8"))
ConnectionResetError: [WinError 10054] 현재 연결은 원격 호스트에 의해 강제로 끊겼습니다

During handling of the above exception, another exception occurred:

Traceback (most recent call last):
  File "C:\Users\jaehy\anaconda3\Lib\site-packages\py4j\clientserver.py", line 503, in send_command
    self.socket.sendall(command.encode("utf-8"))
ConnectionResetError: [WinError 10054] 현재 연결은 원격 호스트에 의해 강제로 끊겼습니다

During handling of the above exception, another exception occurred:

Traceback (most recent call last):
  File "C:\Users\jaehy\anaconda3\Lib\site-packages\py4j\clientserver.py", line 503, in send_command
    self.socket.sendall(command.encode("utf-8"))
ConnectionResetError: [WinError 10054] 현재 연결은 원격 호스트에 의해 강제로 끊겼습니다

During handling of the above exception, another exception occurred:

Traceback (most recent call last):
  File "C:\Users\jaehy\anaconda3\Lib\site-packages\py4j\clientserver.py", line 503, in send_command
    self.socket.sendall(command.encode("utf-8"))
ConnectionResetError: [WinError 10054] 현재 연결은 원격 호스트에 의해 강제로 끊겼습니다

During handling of the above exception, another exception occurred:

Traceback (most recent call last):
  File "C:\Users\jaehy\anaconda3\Lib\site-packages\py4j\clientserver.py", line 503, in send_command
    self.socket.sendall(command.encode("utf-8"))
ConnectionResetError: [WinError 10054] 현재 연결은 원격 호스트에 의해 강제로 끊겼습니다

During handling of the above exception, another exception occurred:

Traceback (most recent call last):
  File "C:\Users\jaehy\anaconda3\Lib\site-packages\py4j\clientserver.py", line 503, in send_command
    self.socket.sendall(command.encode("utf-8"))
ConnectionResetError: [WinError 10054] 현재 연결은 원격 호스트에 의해 강제로 끊겼습니다

During handling of the above exception, another exception occurred:

Traceback (most recent call last):
  File "C:\Users\jaehy\anaconda3\Lib\site-packages\py4j\clientserver.py", line 503, in send_command
    self.socket.sendall(command.encode("utf-8"))
ConnectionResetError: [WinError 10054] 현재 연결은 원격 호스트에 의해 강제로 끊겼습니다

During handling of the above exception, another exception occurred:

Traceback (most recent call last):
  File "C:\Users\jaehy\anaconda3\Lib\site-packages\py4j\clientserver.py", line 503, in send_command
    self.socket.sendall(command.encode("utf-8"))
ConnectionResetError: [WinError 10054] 현재 연결은 원격 호스트에 의해 강제로 끊겼습니다

During handling of the above exception, another exception occurred:

Traceback (most recent call last):
  File "C:\Users\jaehy\anaconda3\Lib\site-packages\py4j\clientserver.py", line 503, in send_command
    self.socket.sendall(command.encode("utf-8"))
ConnectionResetError: [WinError 10054] 현재 연결은 원격 호스트에 의해 강제로 끊겼습니다

During handling of the above exception, another exception occurred:

Traceback (most recent call last):
  File "C:\Users\jaehy\anaconda3\Lib\site-packages\py4j\clientserver.py", line 503, in send_command
    self.socket.sendall(command.encode("utf-8"))
ConnectionResetError: [WinError 10054] 현재 연결은 원격 호스트에 의해 강제로 끊겼습니다

During handling of the above exception, another exception occurred:

Traceback (most recent call last):
  File "C:\Users\jaehy\anaconda3\Lib\site-packages\py4j\clientserver.py", line 503, in send_command
    self.socket.sendall(command.encode("utf-8"))
ConnectionResetError: [WinError 10054] 현재 연결은 원격 호스트에 의해 강제로 끊겼습니다

During handling of the above exception, another exception occurred:

Traceback (most recent call last):
  File "C:\Users\jaehy\anaconda3\Lib\site-packages\py4j\clientserver.py", line 503, in send_command
    self.socket.sendall(command.encode("utf-8"))
ConnectionResetError: [WinError 10054] 현재 연결은 원격 호스트에 의해 강제로 끊겼습니다

During handling of the above exception, another exception occurred:

Traceback (most recent call last):
  File "C:\Users\jaehy\anaconda3\Lib\site-packages\py4j\clientserver.py", line 503, in send_command
    self.socket.sendall(command.encode("utf-8"))
ConnectionResetError: [WinError 10054] 현재 연결은 원격 호스트에 의해 강제로 끊겼습니다

During handling of the above exception, another exception occurred:

Traceback (most recent call last):
  File "C:\Users\jaehy\anaconda3\Lib\site-packages\py4j\clientserver.py", line 503, in send_command
    self.socket.sendall(command.encode("utf-8"))
ConnectionResetError: [WinError 10054] 현재 연결은 원격 호스트에 의해 강제로 끊겼습니다

During handling of the above exception, another exception occurred:

Traceback (most recent call last):
  File "C:\Users\jaehy\anaconda3\Lib\site-packages\py4j\clientserver.py", line 503, in send_command
    self.socket.sendall(command.encode("utf-8"))
ConnectionResetError: [WinError 10054] 현재 연결은 원격 호스트에 의해 강제로 끊겼습니다

During handling of the above exception, another exception occurred:

Traceback (most recent call last):
  File "C:\Users\jaehy\anaconda3\Lib\site-packages\py4j\clientserver.py", line 503, in send_command
    self.socket.sendall(command.encode("utf-8"))
ConnectionResetError: [WinError 10054] 현재 연결은 원격 호스트에 의해 강제로 끊겼습니다

During handling of the above exception, another exception occurred:

Traceback (most recent call last):
  File "C:\Users\jaehy\anaconda3\Lib\site-packages\py4j\clientserver.py", line 503, in send_command
    self.socket.sendall(command.encode("utf-8"))
ConnectionResetError: [WinError 10054] 현재 연결은 원격 호스트에 의해 강제로 끊겼습니다

During handling of the above exception, another exception occurred:

Traceback (most recent call last):
  File "C:\Users\jaehy\anaconda3\Lib\site-packages\py4j\clientserver.py", line 503, in send_command
    self.socket.sendall(command.encode("utf-8"))
ConnectionResetError: [WinError 10054] 현재 연결은 원격 호스트에 의해 강제로 끊겼습니다

During handling of the above exception, another exception occurred:

Traceback (most recent call last):
  File "C:\Users\jaehy\anaconda3\Lib\site-packages\py4j\clientserver.py", line 503, in send_command
    self.socket.sendall(command.encode("utf-8"))
ConnectionResetError: [WinError 10054] 현재 연결은 원격 호스트에 의해 강제로 끊겼습니다

During handling of the above exception, another exception occurred:

Traceback (most recent call last):
  File "C:\Users\jaehy\anaconda3\Lib\site-packages\py4j\clientserver.py", line 503, in send_command
    self.socket.sendall(command.encode("utf-8"))
ConnectionResetError: [WinError 10054] 현재 연결은 원격 호스트에 의해 강제로 끊겼습니다

During handling of the above exception, another exception occurred:

Traceback (most recent call last):
  File "C:\Users\jaehy\anaconda3\Lib\site-packages\py4j\clientserver.py", line 503, in send_command
    self.socket.sendall(command.encode("utf-8"))
ConnectionResetError: [WinError 10054] 현재 연결은 원격 호스트에 의해 강제로 끊겼습니다

During handling of the above exception, another exception occurred:

Traceback (most recent call last):
  File "C:\Users\jaehy\anaconda3\Lib\site-packages\py4j\clientserver.py", line 503, in send_command
    self.socket.sendall(command.encode("utf-8"))
ConnectionResetError: [WinError 10054] 현재 연결은 원격 호스트에 의해 강제로 끊겼습니다

During handling of the above exception, another exception occurred:

Traceback (most recent call last):
  File "C:\Users\jaehy\anaconda3\Lib\site-packages\py4j\clientserver.py", line 503, in send_command
    self.socket.sendall(command.encode("utf-8"))
ConnectionResetError: [WinError 10054] 현재 연결은 원격 호스트에 의해 강제로 끊겼습니다

During handling of the above exception, another exception occurred:

Traceback (most recent call last):
  File "C:\Users\jaehy\anaconda3\Lib\site-packages\py4j\clientserver.py", line 503, in send_command
    self.socket.sendall(command.encode("utf-8"))
ConnectionResetError: [WinError 10054] 현재 연결은 원격 호스트에 의해 강제로 끊겼습니다

During handling of the above exception, another exception occurred:

Traceback (most recent call last):
  File "C:\Users\jaehy\anaconda3\Lib\site-packages\py4j\clientserver.py", line 503, in send_command
    self.socket.sendall(command.encode("utf-8"))
ConnectionResetError: [WinError 10054] 현재 연결은 원격 호스트에 의해 강제로 끊겼습니다

During handling of the above exception, another exception occurred:

Traceback (most recent call last):
  File "C:\Users\jaehy\anaconda3\Lib\site-packages\py4j\clientserver.py", line 503, in send_command
    self.socket.sendall(command.encode("utf-8"))
ConnectionResetError: [WinError 10054] 현재 연결은 원격 호스트에 의해 강제로 끊겼습니다

During handling of the above exception, another exception occurred:

Traceback (most recent call last):
  File "C:\Users\jaehy\anaconda3\Lib\site-packages\py4j\clientserver.py", line 503, in send_command
    self.socket.sendall(command.encode("utf-8"))
ConnectionResetError: [WinError 10054] 현재 연결은 원격 호스트에 의해 강제로 끊겼습니다

During handling of the above exception, another exception occurred:

Traceback (most recent call last):
  File "C:\Users\jaehy\anaconda3\Lib\site-packages\py4j\clientserver.py", line 503, in send_command
    self.socket.sendall(command.encode("utf-8"))
ConnectionResetError: [WinError 10054] 현재 연결은 원격 호스트에 의해 강제로 끊겼습니다

During handling of the above exception, another exception occurred:

Traceback (most recent call last):
  File "C:\Users\jaehy\anaconda3\Lib\site-packages\py4j\clientserver.py", line 503, in send_command
    self.socket.sendall(command.encode("utf-8"))
ConnectionResetError: [WinError 10054] 현재 연결은 원격 호스트에 의해 강제로 끊겼습니다

During handling of the above exception, another exception occurred:

Traceback (most recent call last):
  File "C:\Users\jaehy\anaconda3\Lib\site-packages\py4j\clientserver.py", line 503, in send_command
    self.socket.sendall(command.encode("utf-8"))
ConnectionResetError: [WinError 10054] 현재 연결은 원격 호스트에 의해 강제로 끊겼습니다

During handling of the above exception, another exception occurred:

Traceback (most recent call last):
  File "C:\Users\jaehy\anaconda3\Lib\site-packages\py4j\clientserver.py", line 503, in send_command
    self.socket.sendall(command.encode("utf-8"))
ConnectionResetError: [WinError 10054] 현재 연결은 원격 호스트에 의해 강제로 끊겼습니다

During handling of the above exception, another exception occurred:

Traceback (most recent call last):
  File "C:\Users\jaehy\anaconda3\Lib\site-packages\py4j\clientserver.py", line 503, in send_command
    self.socket.sendall(command.encode("utf-8"))
ConnectionResetError: [WinError 10054] 현재 연결은 원격 호스트에 의해 강제로 끊겼습니다

During handling of the above exception, another exception occurred:

Traceback (most recent call last):
  File "C:\Users\jaehy\anaconda3\Lib\site-packages\py4j\clientserver.py", line 503, in send_command
    self.socket.sendall(command.encode("utf-8"))
ConnectionResetError: [WinError 10054] 현재 연결은 원격 호스트에 의해 강제로 끊겼습니다

During handling of the above exception, another exception occurred:

Traceback (most recent call last):
  File "C:\Users\jaehy\anaconda3\Lib\site-packages\py4j\clientserver.py", line 503, in send_command
    self.socket.sendall(command.encode("utf-8"))
ConnectionResetError: [WinError 10054] 현재 연결은 원격 호스트에 의해 강제로 끊겼습니다

During handling of the above exception, another exception occurred:

Traceback (most recent call last):
  File "C:\Users\jaehy\anaconda3\Lib\site-packages\py4j\clientserver.py", line 503, in send_command
    self.socket.sendall(command.encode("utf-8"))
ConnectionResetError: [WinError 10054] 현재 연결은 원격 호스트에 의해 강제로 끊겼습니다

During handling of the above exception, another exception occurred:

Traceback (most recent call last):
  File "C:\Users\jaehy\anaconda3\Lib\site-packages\py4j\clientserver.py", line 503, in send_command
    self.socket.sendall(command.encode("utf-8"))
ConnectionResetError: [WinError 10054] 현재 연결은 원격 호스트에 의해 강제로 끊겼습니다

During handling of the above exception, another exception occurred:

Traceback (most recent call last):
  File "C:\Users\jaehy\anaconda3\Lib\site-packages\py4j\clientserver.py", line 503, in send_command
    self.socket.sendall(command.encode("utf-8"))
ConnectionResetError: [WinError 10054] 현재 연결은 원격 호스트에 의해 강제로 끊겼습니다

During handling of the above exception, another exception occurred:

Traceback (most recent call last):
  File "C:\Users\jaehy\anaconda3\Lib\site-packages\py4j\clientserver.py", line 503, in send_command
    self.socket.sendall(command.encode("utf-8"))
ConnectionResetError: [WinError 10054] 현재 연결은 원격 호스트에 의해 강제로 끊겼습니다

During handling of the above exception, another exception occurred:

Traceback (most recent call last):
  File "C:\Users\jaehy\anaconda3\Lib\site-packages\py4j\clientserver.py", line 503, in send_command
    self.socket.sendall(command.encode("utf-8"))
ConnectionResetError: [WinError 10054] 현재 연결은 원격 호스트에 의해 강제로 끊겼습니다

During handling of the above exception, another exception occurred:

Traceback (most recent call last):
  File "C:\Users\jaehy\anaconda3\Lib\site-packages\py4j\clientserver.py", line 503, in send_command
    self.socket.sendall(command.encode("utf-8"))
ConnectionResetError: [WinError 10054] 현재 연결은 원격 호스트에 의해 강제로 끊겼습니다

During handling of the above exception, another exception occurred:

Traceback (most recent call last):
  File "C:\Users\jaehy\anaconda3\Lib\site-packages\py4j\clientserver.py", line 503, in send_command
    self.socket.sendall(command.encode("utf-8"))
ConnectionResetError: [WinError 10054] 현재 연결은 원격 호스트에 의해 강제로 끊겼습니다

During handling of the above exception, another exception occurred:

Traceback (most recent call last):
  File "C:\Users\jaehy\anaconda3\Lib\site-packages\py4j\clientserver.py", line 503, in send_command
    self.socket.sendall(command.encode("utf-8"))
ConnectionResetError: [WinError 10054] 현재 연결은 원격 호스트에 의해 강제로 끊겼습니다

During handling of the above exception, another exception occurred:

Traceback (most recent call last):
  File "C:\Users\jaehy\anaconda3\Lib\site-packages\py4j\clientserver.py", line 503, in send_command
    self.socket.sendall(command.encode("utf-8"))
ConnectionResetError: [WinError 10054] 현재 연결은 원격 호스트에 의해 강제로 끊겼습니다

During handling of the above exception, another exception occurred:

Traceback (most recent call last):
  File "C:\Users\jaehy\anaconda3\Lib\site-packages\py4j\clientserver.py", line 503, in send_command
    self.socket.sendall(command.encode("utf-8"))
ConnectionResetError: [WinError 10054] 현재 연결은 원격 호스트에 의해 강제로 끊겼습니다

During handling of the above exception, another exception occurred:

Traceback (most recent call last):
  File "C:\Users\jaehy\anaconda3\Lib\site-packages\py4j\clientserver.py", line 503, in send_command
    self.socket.sendall(command.encode("utf-8"))
ConnectionResetError: [WinError 10054] 현재 연결은 원격 호스트에 의해 강제로 끊겼습니다

During handling of the above exception, another exception occurred:

Traceback (most recent call last):
  File "C:\Users\jaehy\anaconda3\Lib\site-packages\py4j\clientserver.py", line 503, in send_command
    self.socket.sendall(command.encode("utf-8"))
ConnectionResetError: [WinError 10054] 현재 연결은 원격 호스트에 의해 강제로 끊겼습니다

During handling of the above exception, another exception occurred:

Traceback (most recent call last):
  File "C:\Users\jaehy\anaconda3\Lib\site-packages\py4j\clientserver.py", line 503, in send_command
    self.socket.sendall(command.encode("utf-8"))
ConnectionResetError: [WinError 10054] 현재 연결은 원격 호스트에 의해 강제로 끊겼습니다
2025-06-19 21:10:59,672 [INFO] Closing down clientserver connection
2025-06-19 21:11:01,708 [INFO] Closing down clientserver connection
2025-06-19 21:11:01,708 [INFO] Closing down clientserver connection
2025-06-19 21:10:59,672 [INFO] Exception while sending command.
Traceback (most recent call last):
  File "C:\Users\jaehy\anaconda3\Lib\site-packages\pyspark\errors\exceptions\captured.py", line 179, in deco
    return f(*a, **kw)
           ^^^^^^^^^^^
  File "C:\Users\jaehy\anaconda3\Lib\site-packages\py4j\protocol.py", line 326, in get_return_value
    raise Py4JJavaError(
py4j.protocol.Py4JJavaError: <exception str() failed>

During handling of the above exception, another exception occurred:

Traceback (most recent call last):
  File "C:\Users\jaehy\anaconda3\Lib\site-packages\py4j\clientserver.py", line 511, in send_command
    answer = smart_decode(self.stream.readline()[:-1])
                          ^^^^^^^^^^^^^^^^^^^^^^
  File "C:\Users\jaehy\anaconda3\Lib\socket.py", line 706, in readinto
    return self._sock.recv_into(b)
           ^^^^^^^^^^^^^^^^^^^^^^^
ConnectionResetError: [WinError 10054] 현재 연결은 원격 호스트에 의해 강제로 끊겼습니다

During handling of the above exception, another exception occurred:

Traceback (most recent call last):
  File "C:\Users\jaehy\anaconda3\Lib\site-packages\py4j\clientserver.py", line 503, in send_command
    self.socket.sendall(command.encode("utf-8"))
ConnectionResetError: [WinError 10054] 현재 연결은 원격 호스트에 의해 강제로 끊겼습니다

During handling of the above exception, another exception occurred:

Traceback (most recent call last):
  File "C:\Users\jaehy\anaconda3\Lib\site-packages\py4j\clientserver.py", line 503, in send_command
    self.socket.sendall(command.encode("utf-8"))
ConnectionResetError: [WinError 10054] 현재 연결은 원격 호스트에 의해 강제로 끊겼습니다

During handling of the above exception, another exception occurred:

Traceback (most recent call last):
  File "C:\Users\jaehy\anaconda3\Lib\site-packages\py4j\clientserver.py", line 503, in send_command
    self.socket.sendall(command.encode("utf-8"))
ConnectionResetError: [WinError 10054] 현재 연결은 원격 호스트에 의해 강제로 끊겼습니다

During handling of the above exception, another exception occurred:

Traceback (most recent call last):
  File "C:\Users\jaehy\anaconda3\Lib\site-packages\py4j\clientserver.py", line 503, in send_command
    self.socket.sendall(command.encode("utf-8"))
ConnectionResetError: [WinError 10054] 현재 연결은 원격 호스트에 의해 강제로 끊겼습니다

During handling of the above exception, another exception occurred:

Traceback (most recent call last):
  File "C:\Users\jaehy\anaconda3\Lib\site-packages\py4j\clientserver.py", line 503, in send_command
    self.socket.sendall(command.encode("utf-8"))
ConnectionResetError: [WinError 10054] 현재 연결은 원격 호스트에 의해 강제로 끊겼습니다

During handling of the above exception, another exception occurred:

Traceback (most recent call last):
  File "C:\Users\jaehy\anaconda3\Lib\site-packages\py4j\clientserver.py", line 503, in send_command
    self.socket.sendall(command.encode("utf-8"))
ConnectionResetError: [WinError 10054] 현재 연결은 원격 호스트에 의해 강제로 끊겼습니다

During handling of the above exception, another exception occurred:

Traceback (most recent call last):
  File "C:\Users\jaehy\anaconda3\Lib\site-packages\py4j\clientserver.py", line 503, in send_command
    self.socket.sendall(command.encode("utf-8"))
ConnectionResetError: [WinError 10054] 현재 연결은 원격 호스트에 의해 강제로 끊겼습니다

During handling of the above exception, another exception occurred:

Traceback (most recent call last):
  File "C:\Users\jaehy\anaconda3\Lib\site-packages\py4j\clientserver.py", line 503, in send_command
    self.socket.sendall(command.encode("utf-8"))
ConnectionResetError: [WinError 10054] 현재 연결은 원격 호스트에 의해 강제로 끊겼습니다

During handling of the above exception, another exception occurred:

Traceback (most recent call last):
  File "C:\Users\jaehy\anaconda3\Lib\site-packages\py4j\clientserver.py", line 503, in send_command
    self.socket.sendall(command.encode("utf-8"))
ConnectionResetError: [WinError 10054] 현재 연결은 원격 호스트에 의해 강제로 끊겼습니다

During handling of the above exception, another exception occurred:

Traceback (most recent call last):
  File "C:\Users\jaehy\anaconda3\Lib\site-packages\py4j\clientserver.py", line 503, in send_command
    self.socket.sendall(command.encode("utf-8"))
ConnectionResetError: [WinError 10054] 현재 연결은 원격 호스트에 의해 강제로 끊겼습니다

During handling of the above exception, another exception occurred:

Traceback (most recent call last):
  File "C:\Users\jaehy\anaconda3\Lib\site-packages\py4j\clientserver.py", line 503, in send_command
    self.socket.sendall(command.encode("utf-8"))
ConnectionResetError: [WinError 10054] 현재 연결은 원격 호스트에 의해 강제로 끊겼습니다

During handling of the above exception, another exception occurred:

Traceback (most recent call last):
  File "C:\Users\jaehy\anaconda3\Lib\site-packages\py4j\clientserver.py", line 503, in send_command
    self.socket.sendall(command.encode("utf-8"))
ConnectionResetError: [WinError 10054] 현재 연결은 원격 호스트에 의해 강제로 끊겼습니다

During handling of the above exception, another exception occurred:

Traceback (most recent call last):
  File "C:\Users\jaehy\anaconda3\Lib\site-packages\py4j\clientserver.py", line 503, in send_command
    self.socket.sendall(command.encode("utf-8"))
ConnectionResetError: [WinError 10054] 현재 연결은 원격 호스트에 의해 강제로 끊겼습니다

During handling of the above exception, another exception occurred:

Traceback (most recent call last):
  File "C:\Users\jaehy\anaconda3\Lib\site-packages\py4j\clientserver.py", line 503, in send_command
    self.socket.sendall(command.encode("utf-8"))
ConnectionResetError: [WinError 10054] 현재 연결은 원격 호스트에 의해 강제로 끊겼습니다

During handling of the above exception, another exception occurred:

Traceback (most recent call last):
  File "C:\Users\jaehy\anaconda3\Lib\site-packages\py4j\clientserver.py", line 503, in send_command
    self.socket.sendall(command.encode("utf-8"))
ConnectionResetError: [WinError 10054] 현재 연결은 원격 호스트에 의해 강제로 끊겼습니다

During handling of the above exception, another exception occurred:

Traceback (most recent call last):
  File "C:\Users\jaehy\anaconda3\Lib\site-packages\py4j\clientserver.py", line 503, in send_command
    self.socket.sendall(command.encode("utf-8"))
ConnectionResetError: [WinError 10054] 현재 연결은 원격 호스트에 의해 강제로 끊겼습니다

During handling of the above exception, another exception occurred:

Traceback (most recent call last):
  File "C:\Users\jaehy\anaconda3\Lib\site-packages\py4j\clientserver.py", line 503, in send_command
    self.socket.sendall(command.encode("utf-8"))
ConnectionResetError: [WinError 10054] 현재 연결은 원격 호스트에 의해 강제로 끊겼습니다

During handling of the above exception, another exception occurred:

Traceback (most recent call last):
  File "C:\Users\jaehy\anaconda3\Lib\site-packages\py4j\clientserver.py", line 503, in send_command
    self.socket.sendall(command.encode("utf-8"))
ConnectionResetError: [WinError 10054] 현재 연결은 원격 호스트에 의해 강제로 끊겼습니다

During handling of the above exception, another exception occurred:

Traceback (most recent call last):
  File "C:\Users\jaehy\anaconda3\Lib\site-packages\py4j\clientserver.py", line 503, in send_command
    self.socket.sendall(command.encode("utf-8"))
ConnectionResetError: [WinError 10054] 현재 연결은 원격 호스트에 의해 강제로 끊겼습니다

During handling of the above exception, another exception occurred:

Traceback (most recent call last):
  File "C:\Users\jaehy\anaconda3\Lib\site-packages\py4j\clientserver.py", line 503, in send_command
    self.socket.sendall(command.encode("utf-8"))
ConnectionResetError: [WinError 10054] 현재 연결은 원격 호스트에 의해 강제로 끊겼습니다

During handling of the above exception, another exception occurred:

Traceback (most recent call last):
  File "C:\Users\jaehy\anaconda3\Lib\site-packages\py4j\clientserver.py", line 503, in send_command
    self.socket.sendall(command.encode("utf-8"))
ConnectionResetError: [WinError 10054] 현재 연결은 원격 호스트에 의해 강제로 끊겼습니다

During handling of the above exception, another exception occurred:

Traceback (most recent call last):
  File "C:\Users\jaehy\anaconda3\Lib\site-packages\py4j\clientserver.py", line 503, in send_command
    self.socket.sendall(command.encode("utf-8"))
ConnectionResetError: [WinError 10054] 현재 연결은 원격 호스트에 의해 강제로 끊겼습니다

During handling of the above exception, another exception occurred:

Traceback (most recent call last):
  File "C:\Users\jaehy\anaconda3\Lib\site-packages\py4j\clientserver.py", line 503, in send_command
    self.socket.sendall(command.encode("utf-8"))
ConnectionResetError: [WinError 10054] 현재 연결은 원격 호스트에 의해 강제로 끊겼습니다

During handling of the above exception, another exception occurred:

Traceback (most recent call last):
  File "C:\Users\jaehy\anaconda3\Lib\site-packages\py4j\clientserver.py", line 503, in send_command
    self.socket.sendall(command.encode("utf-8"))
ConnectionResetError: [WinError 10054] 현재 연결은 원격 호스트에 의해 강제로 끊겼습니다

During handling of the above exception, another exception occurred:

Traceback (most recent call last):
  File "C:\Users\jaehy\anaconda3\Lib\site-packages\py4j\clientserver.py", line 503, in send_command
    self.socket.sendall(command.encode("utf-8"))
ConnectionResetError: [WinError 10054] 현재 연결은 원격 호스트에 의해 강제로 끊겼습니다

During handling of the above exception, another exception occurred:

Traceback (most recent call last):
  File "C:\Users\jaehy\anaconda3\Lib\site-packages\py4j\clientserver.py", line 503, in send_command
    self.socket.sendall(command.encode("utf-8"))
ConnectionResetError: [WinError 10054] 현재 연결은 원격 호스트에 의해 강제로 끊겼습니다

During handling of the above exception, another exception occurred:

Traceback (most recent call last):
  File "C:\Users\jaehy\anaconda3\Lib\site-packages\py4j\clientserver.py", line 503, in send_command
    self.socket.sendall(command.encode("utf-8"))
ConnectionResetError: [WinError 10054] 현재 연결은 원격 호스트에 의해 강제로 끊겼습니다

During handling of the above exception, another exception occurred:

Traceback (most recent call last):
  File "C:\Users\jaehy\anaconda3\Lib\site-packages\py4j\clientserver.py", line 503, in send_command
    self.socket.sendall(command.encode("utf-8"))
ConnectionResetError: [WinError 10054] 현재 연결은 원격 호스트에 의해 강제로 끊겼습니다

During handling of the above exception, another exception occurred:

Traceback (most recent call last):
  File "C:\Users\jaehy\anaconda3\Lib\site-packages\py4j\clientserver.py", line 503, in send_command
    self.socket.sendall(command.encode("utf-8"))
ConnectionResetError: [WinError 10054] 현재 연결은 원격 호스트에 의해 강제로 끊겼습니다

During handling of the above exception, another exception occurred:

Traceback (most recent call last):
  File "C:\Users\jaehy\anaconda3\Lib\site-packages\py4j\clientserver.py", line 503, in send_command
    self.socket.sendall(command.encode("utf-8"))
ConnectionResetError: [WinError 10054] 현재 연결은 원격 호스트에 의해 강제로 끊겼습니다

During handling of the above exception, another exception occurred:

Traceback (most recent call last):
  File "C:\Users\jaehy\anaconda3\Lib\site-packages\py4j\clientserver.py", line 503, in send_command
    self.socket.sendall(command.encode("utf-8"))
ConnectionResetError: [WinError 10054] 현재 연결은 원격 호스트에 의해 강제로 끊겼습니다

During handling of the above exception, another exception occurred:

Traceback (most recent call last):
  File "C:\Users\jaehy\anaconda3\Lib\site-packages\py4j\clientserver.py", line 503, in send_command
    self.socket.sendall(command.encode("utf-8"))
ConnectionResetError: [WinError 10054] 현재 연결은 원격 호스트에 의해 강제로 끊겼습니다

During handling of the above exception, another exception occurred:

Traceback (most recent call last):
  File "C:\Users\jaehy\anaconda3\Lib\site-packages\py4j\clientserver.py", line 503, in send_command
    self.socket.sendall(command.encode("utf-8"))
ConnectionResetError: [WinError 10054] 현재 연결은 원격 호스트에 의해 강제로 끊겼습니다

During handling of the above exception, another exception occurred:

Traceback (most recent call last):
  File "C:\Users\jaehy\anaconda3\Lib\site-packages\py4j\clientserver.py", line 503, in send_command
    self.socket.sendall(command.encode("utf-8"))
ConnectionResetError: [WinError 10054] 현재 연결은 원격 호스트에 의해 강제로 끊겼습니다

During handling of the above exception, another exception occurred:

Traceback (most recent call last):
  File "C:\Users\jaehy\anaconda3\Lib\site-packages\py4j\clientserver.py", line 503, in send_command
    self.socket.sendall(command.encode("utf-8"))
ConnectionResetError: [WinError 10054] 현재 연결은 원격 호스트에 의해 강제로 끊겼습니다

During handling of the above exception, another exception occurred:

Traceback (most recent call last):
  File "C:\Users\jaehy\anaconda3\Lib\site-packages\py4j\clientserver.py", line 503, in send_command
    self.socket.sendall(command.encode("utf-8"))
ConnectionResetError: [WinError 10054] 현재 연결은 원격 호스트에 의해 강제로 끊겼습니다

During handling of the above exception, another exception occurred:

Traceback (most recent call last):
  File "C:\Users\jaehy\anaconda3\Lib\site-packages\py4j\clientserver.py", line 503, in send_command
    self.socket.sendall(command.encode("utf-8"))
ConnectionResetError: [WinError 10054] 현재 연결은 원격 호스트에 의해 강제로 끊겼습니다

During handling of the above exception, another exception occurred:

Traceback (most recent call last):
  File "C:\Users\jaehy\anaconda3\Lib\site-packages\py4j\clientserver.py", line 503, in send_command
    self.socket.sendall(command.encode("utf-8"))
ConnectionResetError: [WinError 10054] 현재 연결은 원격 호스트에 의해 강제로 끊겼습니다

During handling of the above exception, another exception occurred:

Traceback (most recent call last):
  File "C:\Users\jaehy\anaconda3\Lib\site-packages\py4j\clientserver.py", line 503, in send_command
    self.socket.sendall(command.encode("utf-8"))
ConnectionResetError: [WinError 10054] 현재 연결은 원격 호스트에 의해 강제로 끊겼습니다

During handling of the above exception, another exception occurred:

Traceback (most recent call last):
  File "C:\Users\jaehy\anaconda3\Lib\site-packages\py4j\clientserver.py", line 503, in send_command
    self.socket.sendall(command.encode("utf-8"))
ConnectionResetError: [WinError 10054] 현재 연결은 원격 호스트에 의해 강제로 끊겼습니다

During handling of the above exception, another exception occurred:

Traceback (most recent call last):
  File "C:\Users\jaehy\anaconda3\Lib\site-packages\py4j\clientserver.py", line 503, in send_command
    self.socket.sendall(command.encode("utf-8"))
ConnectionResetError: [WinError 10054] 현재 연결은 원격 호스트에 의해 강제로 끊겼습니다

During handling of the above exception, another exception occurred:

Traceback (most recent call last):
  File "C:\Users\jaehy\anaconda3\Lib\site-packages\py4j\clientserver.py", line 503, in send_command
    self.socket.sendall(command.encode("utf-8"))
ConnectionResetError: [WinError 10054] 현재 연결은 원격 호스트에 의해 강제로 끊겼습니다

During handling of the above exception, another exception occurred:

Traceback (most recent call last):
  File "C:\Users\jaehy\anaconda3\Lib\site-packages\py4j\clientserver.py", line 503, in send_command
    self.socket.sendall(command.encode("utf-8"))
ConnectionResetError: [WinError 10054] 현재 연결은 원격 호스트에 의해 강제로 끊겼습니다

During handling of the above exception, another exception occurred:

Traceback (most recent call last):
  File "C:\Users\jaehy\anaconda3\Lib\site-packages\py4j\clientserver.py", line 503, in send_command
    self.socket.sendall(command.encode("utf-8"))
ConnectionResetError: [WinError 10054] 현재 연결은 원격 호스트에 의해 강제로 끊겼습니다

During handling of the above exception, another exception occurred:

Traceback (most recent call last):
  File "C:\Users\jaehy\anaconda3\Lib\site-packages\py4j\clientserver.py", line 503, in send_command
    self.socket.sendall(command.encode("utf-8"))
ConnectionResetError: [WinError 10054] 현재 연결은 원격 호스트에 의해 강제로 끊겼습니다

During handling of the above exception, another exception occurred:

Traceback (most recent call last):
  File "C:\Users\jaehy\anaconda3\Lib\site-packages\py4j\clientserver.py", line 503, in send_command
    self.socket.sendall(command.encode("utf-8"))
ConnectionResetError: [WinError 10054] 현재 연결은 원격 호스트에 의해 강제로 끊겼습니다

During handling of the above exception, another exception occurred:

Traceback (most recent call last):
  File "C:\Users\jaehy\anaconda3\Lib\site-packages\py4j\clientserver.py", line 503, in send_command
    self.socket.sendall(command.encode("utf-8"))
ConnectionResetError: [WinError 10054] 현재 연결은 원격 호스트에 의해 강제로 끊겼습니다

During handling of the above exception, another exception occurred:

Traceback (most recent call last):
  File "C:\Users\jaehy\anaconda3\Lib\site-packages\py4j\java_gateway.py", line 1038, in send_command
    response = connection.send_command(command)
               ^^^^^^^^^^^^^^^^^^^^^^^^^^^^^^^^
  File "C:\Users\jaehy\anaconda3\Lib\site-packages\py4j\clientserver.py", line 506, in send_command
    raise Py4JNetworkError(
py4j.protocol.Py4JNetworkError: Error while sending
2025-06-19 21:11:13,541 [INFO] [31m[1mWARNING: This is a development server. Do not use it in a production deployment. Use a production WSGI server instead.[0m
 * Running on all addresses (0.0.0.0)
 * Running on http://127.0.0.1:5000
 * Running on http://192.168.0.7:5000
2025-06-19 21:11:13,542 [INFO] [33mPress CTRL+C to quit[0m
2025-06-19 21:11:15,074 [INFO] [요청] IP: 127.0.0.1, POST /realtime_search
2025-06-19 21:11:15,145 [ERROR] Exception on /realtime_search [POST]
Traceback (most recent call last):
  File "C:\Users\jaehy\anaconda3\Lib\site-packages\flask\app.py", line 2529, in wsgi_app
    response = self.full_dispatch_request()
               ^^^^^^^^^^^^^^^^^^^^^^^^^^^^
  File "C:\Users\jaehy\anaconda3\Lib\site-packages\flask\app.py", line 1825, in full_dispatch_request
    rv = self.handle_user_exception(e)
         ^^^^^^^^^^^^^^^^^^^^^^^^^^^^^
  File "C:\Users\jaehy\anaconda3\Lib\site-packages\flask_cors\extension.py", line 176, in wrapped_function
    return cors_after_request(app.make_response(f(*args, **kwargs)))
                                                ^^^^^^^^^^^^^^^^^^
  File "C:\Users\jaehy\anaconda3\Lib\site-packages\flask\app.py", line 1823, in full_dispatch_request
    rv = self.dispatch_request()
         ^^^^^^^^^^^^^^^^^^^^^^^
  File "C:\Users\jaehy\anaconda3\Lib\site-packages\flask\app.py", line 1799, in dispatch_request
    return self.ensure_sync(self.view_functions[rule.endpoint])(**view_args)
           ^^^^^^^^^^^^^^^^^^^^^^^^^^^^^^^^^^^^^^^^^^^^^^^^^^^^^^^^^^^^^^^^^
  File "c:\JaeHyeok\TickerNow\TickerNow-backend\main.py", line 344, in run_realtime_search
    return jsonify({re}), 200
           ^^^^^^^^^^^^^
  File "C:\Users\jaehy\anaconda3\Lib\site-packages\flask\json\__init__.py", line 342, in jsonify
    return current_app.json.response(*args, **kwargs)
           ^^^^^^^^^^^^^^^^^^^^^^^^^^^^^^^^^^^^^^^^^^
  File "C:\Users\jaehy\anaconda3\Lib\site-packages\flask\json\provider.py", line 309, in response
    f"{self.dumps(obj, **dump_args)}\n", mimetype=mimetype
       ^^^^^^^^^^^^^^^^^^^^^^^^^^^^
  File "C:\Users\jaehy\anaconda3\Lib\site-packages\flask\json\provider.py", line 230, in dumps
    return json.dumps(obj, **kwargs)
           ^^^^^^^^^^^^^^^^^^^^^^^^^
  File "C:\Users\jaehy\anaconda3\Lib\json\__init__.py", line 238, in dumps
    **kw).encode(obj)
          ^^^^^^^^^^^
  File "C:\Users\jaehy\anaconda3\Lib\json\encoder.py", line 200, in encode
    chunks = self.iterencode(o, _one_shot=True)
             ^^^^^^^^^^^^^^^^^^^^^^^^^^^^^^^^^^
  File "C:\Users\jaehy\anaconda3\Lib\json\encoder.py", line 258, in iterencode
    return _iterencode(o, 0)
           ^^^^^^^^^^^^^^^^^
  File "C:\Users\jaehy\anaconda3\Lib\site-packages\flask\json\provider.py", line 122, in _default
    raise TypeError(f"Object of type {type(o).__name__} is not JSON serializable")
TypeError: Object of type set is not JSON serializable
2025-06-19 21:11:15,151 [INFO] 127.0.0.1 - - [19/Jun/2025 21:11:15] "[35m[1mPOST /realtime_search HTTP/1.1[0m" 500 -
2025-06-19 21:11:15,152 [INFO] Closing down clientserver connection
2025-06-19 21:12:37,200 [INFO] Error while receiving.
Traceback (most recent call last):
  File "C:\Users\jaehy\anaconda3\Lib\site-packages\py4j\clientserver.py", line 511, in send_command
    answer = smart_decode(self.stream.readline()[:-1])
                          ^^^^^^^^^^^^^^^^^^^^^^
  File "C:\Users\jaehy\anaconda3\Lib\socket.py", line 706, in readinto
    return self._sock.recv_into(b)
           ^^^^^^^^^^^^^^^^^^^^^^^
ConnectionResetError: [WinError 10054] 현재 연결은 원격 호스트에 의해 강제로 끊겼습니다
2025-06-19 21:12:37,202 [INFO] Closing down clientserver connection
2025-06-19 21:12:37,202 [ERROR] Exception while sending command.
Traceback (most recent call last):
  File "C:\Users\jaehy\anaconda3\Lib\site-packages\py4j\clientserver.py", line 511, in send_command
    answer = smart_decode(self.stream.readline()[:-1])
                          ^^^^^^^^^^^^^^^^^^^^^^
  File "C:\Users\jaehy\anaconda3\Lib\socket.py", line 706, in readinto
    return self._sock.recv_into(b)
           ^^^^^^^^^^^^^^^^^^^^^^^
ConnectionResetError: [WinError 10054] 현재 연결은 원격 호스트에 의해 강제로 끊겼습니다

During handling of the above exception, another exception occurred:

Traceback (most recent call last):
  File "C:\Users\jaehy\anaconda3\Lib\site-packages\py4j\java_gateway.py", line 1038, in send_command
    response = connection.send_command(command)
               ^^^^^^^^^^^^^^^^^^^^^^^^^^^^^^^^
  File "C:\Users\jaehy\anaconda3\Lib\site-packages\py4j\clientserver.py", line 539, in send_command
    raise Py4JNetworkError(
py4j.protocol.Py4JNetworkError: Error while sending or receiving
2025-06-19 21:12:37,204 [INFO] Closing down clientserver connection
2025-06-19 21:12:37,244 [INFO] Closing down clientserver connection
2025-06-19 21:12:50,695 [INFO] [31m[1mWARNING: This is a development server. Do not use it in a production deployment. Use a production WSGI server instead.[0m
 * Running on all addresses (0.0.0.0)
 * Running on http://127.0.0.1:5000
 * Running on http://192.168.0.7:5000
2025-06-19 21:12:50,695 [INFO] [33mPress CTRL+C to quit[0m
2025-06-19 21:12:51,955 [INFO] [요청] IP: 127.0.0.1, POST /realtime_search
2025-06-19 21:12:53,179 [INFO] 127.0.0.1 - - [19/Jun/2025 21:12:53] "POST /realtime_search HTTP/1.1" 200 -
2025-06-19 21:12:53,180 [INFO] Closing down clientserver connection
2025-06-19 21:12:58,003 [INFO] [요청] IP: 127.0.0.1, POST /realtime_search
2025-06-19 21:12:58,066 [INFO] 127.0.0.1 - - [19/Jun/2025 21:12:58] "POST /realtime_search HTTP/1.1" 200 -
2025-06-19 21:12:58,066 [INFO] Closing down clientserver connection
2025-06-19 21:14:33,103 [INFO] [31m[1mWARNING: This is a development server. Do not use it in a production deployment. Use a production WSGI server instead.[0m
 * Running on all addresses (0.0.0.0)
 * Running on http://127.0.0.1:5000
 * Running on http://192.168.0.7:5000
2025-06-19 21:14:33,104 [INFO] [33mPress CTRL+C to quit[0m
2025-06-19 21:14:34,206 [INFO] [요청] IP: 127.0.0.1, POST /realtime_search
2025-06-19 21:14:35,370 [INFO] 127.0.0.1 - - [19/Jun/2025 21:14:35] "POST /realtime_search HTTP/1.1" 200 -
2025-06-19 21:14:35,370 [INFO] Closing down clientserver connection
2025-06-19 21:15:49,759 [INFO] [31m[1mWARNING: This is a development server. Do not use it in a production deployment. Use a production WSGI server instead.[0m
 * Running on all addresses (0.0.0.0)
 * Running on http://127.0.0.1:5000
 * Running on http://192.168.0.7:5000
2025-06-19 21:15:49,759 [INFO] [33mPress CTRL+C to quit[0m
2025-06-19 21:15:50,599 [INFO] [요청] IP: 127.0.0.1, POST /realtime_search
2025-06-19 21:15:51,791 [INFO] 127.0.0.1 - - [19/Jun/2025 21:15:51] "POST /realtime_search HTTP/1.1" 200 -
2025-06-19 21:15:51,792 [INFO] Closing down clientserver connection
2025-06-19 21:16:10,535 [INFO] Error while receiving.
Traceback (most recent call last):
  File "C:\Users\jaehy\anaconda3\Lib\site-packages\py4j\clientserver.py", line 511, in send_command
    answer = smart_decode(self.stream.readline()[:-1])
                          ^^^^^^^^^^^^^^^^^^^^^^
  File "C:\Users\jaehy\anaconda3\Lib\socket.py", line 706, in readinto
    return self._sock.recv_into(b)
           ^^^^^^^^^^^^^^^^^^^^^^^
ConnectionResetError: [WinError 10054] 현재 연결은 원격 호스트에 의해 강제로 끊겼습니다
2025-06-19 21:16:10,538 [INFO] Closing down clientserver connection
2025-06-19 21:16:10,539 [ERROR] Exception while sending command.
Traceback (most recent call last):
  File "C:\Users\jaehy\anaconda3\Lib\site-packages\py4j\clientserver.py", line 511, in send_command
    answer = smart_decode(self.stream.readline()[:-1])
                          ^^^^^^^^^^^^^^^^^^^^^^
  File "C:\Users\jaehy\anaconda3\Lib\socket.py", line 706, in readinto
    return self._sock.recv_into(b)
           ^^^^^^^^^^^^^^^^^^^^^^^
ConnectionResetError: [WinError 10054] 현재 연결은 원격 호스트에 의해 강제로 끊겼습니다

During handling of the above exception, another exception occurred:

Traceback (most recent call last):
  File "C:\Users\jaehy\anaconda3\Lib\site-packages\py4j\java_gateway.py", line 1038, in send_command
    response = connection.send_command(command)
               ^^^^^^^^^^^^^^^^^^^^^^^^^^^^^^^^
  File "C:\Users\jaehy\anaconda3\Lib\site-packages\py4j\clientserver.py", line 539, in send_command
    raise Py4JNetworkError(
py4j.protocol.Py4JNetworkError: Error while sending or receiving
2025-06-19 21:16:10,540 [INFO] Closing down clientserver connection
2025-06-19 21:16:10,578 [INFO] Closing down clientserver connection
2025-06-19 21:16:25,778 [INFO] [31m[1mWARNING: This is a development server. Do not use it in a production deployment. Use a production WSGI server instead.[0m
 * Running on all addresses (0.0.0.0)
 * Running on http://127.0.0.1:5000
 * Running on http://192.168.0.7:5000
2025-06-19 21:16:25,778 [INFO] [33mPress CTRL+C to quit[0m
2025-06-19 21:16:27,257 [INFO] [요청] IP: 127.0.0.1, POST /realtime_search
2025-06-19 21:16:28,926 [INFO] 127.0.0.1 - - [19/Jun/2025 21:16:28] "POST /realtime_search HTTP/1.1" 200 -
2025-06-19 21:16:28,927 [INFO] Closing down clientserver connection
2025-06-19 21:16:38,343 [INFO] [요청] IP: 127.0.0.1, POST /realtime_search
2025-06-19 21:16:38,475 [INFO] 127.0.0.1 - - [19/Jun/2025 21:16:38] "POST /realtime_search HTTP/1.1" 200 -
2025-06-19 21:16:38,476 [INFO] Closing down clientserver connection
2025-06-19 21:16:44,108 [INFO] [요청] IP: 127.0.0.1, POST /realtime_search
2025-06-19 21:16:44,182 [INFO] 127.0.0.1 - - [19/Jun/2025 21:16:44] "POST /realtime_search HTTP/1.1" 200 -
2025-06-19 21:16:44,183 [INFO] Closing down clientserver connection
2025-06-19 21:16:49,179 [INFO] [요청] IP: 127.0.0.1, POST /realtime_search
2025-06-19 21:16:49,322 [INFO] 127.0.0.1 - - [19/Jun/2025 21:16:49] "POST /realtime_search HTTP/1.1" 200 -
2025-06-19 21:16:49,323 [INFO] Closing down clientserver connection
2025-06-19 21:16:59,730 [INFO] [요청] IP: 127.0.0.1, POST /realtime_search
2025-06-19 21:16:59,847 [INFO] 127.0.0.1 - - [19/Jun/2025 21:16:59] "POST /realtime_search HTTP/1.1" 200 -
2025-06-19 21:16:59,848 [INFO] Closing down clientserver connection
2025-06-19 21:18:38,959 [INFO] Error while receiving.
Traceback (most recent call last):
  File "C:\Users\jaehy\anaconda3\Lib\site-packages\py4j\clientserver.py", line 511, in send_command
    answer = smart_decode(self.stream.readline()[:-1])
                          ^^^^^^^^^^^^^^^^^^^^^^
  File "C:\Users\jaehy\anaconda3\Lib\socket.py", line 706, in readinto
    return self._sock.recv_into(b)
           ^^^^^^^^^^^^^^^^^^^^^^^
ConnectionResetError: [WinError 10054] 현재 연결은 원격 호스트에 의해 강제로 끊겼습니다
2025-06-19 21:18:38,961 [INFO] Closing down clientserver connection
2025-06-19 21:18:38,961 [ERROR] Exception while sending command.
Traceback (most recent call last):
  File "C:\Users\jaehy\anaconda3\Lib\site-packages\py4j\clientserver.py", line 511, in send_command
    answer = smart_decode(self.stream.readline()[:-1])
                          ^^^^^^^^^^^^^^^^^^^^^^
  File "C:\Users\jaehy\anaconda3\Lib\socket.py", line 706, in readinto
    return self._sock.recv_into(b)
           ^^^^^^^^^^^^^^^^^^^^^^^
ConnectionResetError: [WinError 10054] 현재 연결은 원격 호스트에 의해 강제로 끊겼습니다

During handling of the above exception, another exception occurred:

Traceback (most recent call last):
  File "C:\Users\jaehy\anaconda3\Lib\site-packages\py4j\java_gateway.py", line 1038, in send_command
    response = connection.send_command(command)
               ^^^^^^^^^^^^^^^^^^^^^^^^^^^^^^^^
  File "C:\Users\jaehy\anaconda3\Lib\site-packages\py4j\clientserver.py", line 539, in send_command
    raise Py4JNetworkError(
py4j.protocol.Py4JNetworkError: Error while sending or receiving
2025-06-19 21:18:38,962 [INFO] Closing down clientserver connection
2025-06-19 21:18:38,998 [INFO] Closing down clientserver connection
2025-06-19 21:18:50,787 [INFO] [31m[1mWARNING: This is a development server. Do not use it in a production deployment. Use a production WSGI server instead.[0m
 * Running on all addresses (0.0.0.0)
 * Running on http://127.0.0.1:5000
 * Running on http://192.168.0.7:5000
2025-06-19 21:18:50,787 [INFO] [33mPress CTRL+C to quit[0m
2025-06-19 21:18:54,325 [INFO] [요청] IP: 127.0.0.1, POST /realtime_search
2025-06-19 21:18:56,012 [INFO] 127.0.0.1 - - [19/Jun/2025 21:18:56] "POST /realtime_search HTTP/1.1" 200 -
2025-06-19 21:18:56,013 [INFO] Closing down clientserver connection
2025-06-19 21:22:38,154 [INFO] [요청] IP: 127.0.0.1, POST /realtime_search
2025-06-19 21:22:38,298 [INFO] 127.0.0.1 - - [19/Jun/2025 21:22:38] "POST /realtime_search HTTP/1.1" 200 -
2025-06-19 21:22:38,299 [INFO] Closing down clientserver connection
2025-06-19 21:22:41,158 [INFO] [요청] IP: 127.0.0.1, POST /realtime_search
2025-06-19 21:22:41,275 [INFO] 127.0.0.1 - - [19/Jun/2025 21:22:41] "POST /realtime_search HTTP/1.1" 200 -
2025-06-19 21:22:41,275 [INFO] Closing down clientserver connection
2025-06-19 21:22:45,855 [INFO] Error while receiving.
Traceback (most recent call last):
  File "C:\Users\jaehy\anaconda3\Lib\site-packages\py4j\clientserver.py", line 511, in send_command
    answer = smart_decode(self.stream.readline()[:-1])
                          ^^^^^^^^^^^^^^^^^^^^^^
  File "C:\Users\jaehy\anaconda3\Lib\socket.py", line 706, in readinto
    return self._sock.recv_into(b)
           ^^^^^^^^^^^^^^^^^^^^^^^
ConnectionResetError: [WinError 10054] 현재 연결은 원격 호스트에 의해 강제로 끊겼습니다
2025-06-19 21:22:45,858 [INFO] Closing down clientserver connection
2025-06-19 21:22:45,859 [ERROR] Exception while sending command.
Traceback (most recent call last):
  File "C:\Users\jaehy\anaconda3\Lib\site-packages\py4j\clientserver.py", line 511, in send_command
    answer = smart_decode(self.stream.readline()[:-1])
                          ^^^^^^^^^^^^^^^^^^^^^^
  File "C:\Users\jaehy\anaconda3\Lib\socket.py", line 706, in readinto
    return self._sock.recv_into(b)
           ^^^^^^^^^^^^^^^^^^^^^^^
ConnectionResetError: [WinError 10054] 현재 연결은 원격 호스트에 의해 강제로 끊겼습니다

During handling of the above exception, another exception occurred:

Traceback (most recent call last):
  File "C:\Users\jaehy\anaconda3\Lib\site-packages\py4j\java_gateway.py", line 1038, in send_command
    response = connection.send_command(command)
               ^^^^^^^^^^^^^^^^^^^^^^^^^^^^^^^^
  File "C:\Users\jaehy\anaconda3\Lib\site-packages\py4j\clientserver.py", line 539, in send_command
    raise Py4JNetworkError(
py4j.protocol.Py4JNetworkError: Error while sending or receiving
2025-06-19 21:22:45,860 [INFO] Closing down clientserver connection
2025-06-19 21:22:45,899 [INFO] Closing down clientserver connection
2025-06-19 21:22:57,878 [INFO] [31m[1mWARNING: This is a development server. Do not use it in a production deployment. Use a production WSGI server instead.[0m
 * Running on all addresses (0.0.0.0)
 * Running on http://127.0.0.1:5000
 * Running on http://192.168.0.7:5000
2025-06-19 21:22:57,878 [INFO] [33mPress CTRL+C to quit[0m
2025-06-19 21:23:02,694 [INFO] [요청] IP: 127.0.0.1, POST /realtime_search
2025-06-19 21:23:04,380 [INFO] 127.0.0.1 - - [19/Jun/2025 21:23:04] "POST /realtime_search HTTP/1.1" 200 -
2025-06-19 21:23:04,381 [INFO] Closing down clientserver connection
